Workbook

Sheet Org Chart
C3: Role (Title) | D3: Reporting Head
B4: 1 | C4: Board | D4: Shareholders
B5: 2 | C5: CEO | D5: Board
B6: 3 | C6: CFO | D6: CEO
B7: 4 | C7: COO | D7: CEO
B8: 5 | C8: Head Marketing | D8: CEO
B9: 6 | C9: Marketing Manager | D9: =C8 -> Head Marketing
B10: 7 | C10: Social Media Assistant | D10: =C9 -> Marketing Manager
B11: 8 | C11: Copy Writer | D11: =C10 -> Social Media Assistant
B12: 9 | C12: Events Co-ordinator | D12: =C11 -> Copy Writer
B13: 10 | C13: Head HR | D13: COO
B14: 11 | C14: Trainer | D14: =C13 -> Head HR
B15: 12 | C15: Health & Safety Officer | D15: Head HR
B16: 13 | C16: Head Sales | D16: CEO
B17: 14 | C17: Sales Manager | D17: =C16 -> Head Sales
B18: 15 | C18: Salesperson | D18: =C17 -> Sales Manager
B19: 16 | C19: Accountant | D19: CFO
B20: 17 | C20: Bookkeeper | D20: =C19 -> Accountant
B21: 18 | C21: Factory Foreman | D21: COO
B22: 19 | C22: Head of Purchasing | D22: COO
B23: 20 | C23: Head of Inventory | D23: COO
B24: 21 | C24: Snr Tech | D24: =C21 -> Factory Foreman
B25: 22 | C25: Tech | D25: Factory Foreman
B26: 23 | C26: Jnr Tech | D26: Factory Foreman
B27: 24 | C27: Personal Assistant | D27: =C22 -> Head of Purchasing
B28: 25
B29: 26
B30: 27
B31: 28
B32: 29
B33: 30
C36: Enter your data in the section above. You can choose to enter the Role or if you prefer, the name of the people. | G36: Once your Org Chart is completed simply copy and paste it into the document. Remember, if you want the chart to auto update then click 'paste link'.

Sheet Roles & Responsibilities
D4: ='Org Chart'!D3 -> Reporting Head | F4: {=transpose('Org Chart'!$D$4:$D$33)} -> Shareholders | G4: Board | H4: CEO | I4: CEO | J4: CEO | K4: Head Marketing | L4: Marketing Manager | M4: Social Media Assistant | N4: Copy Writer | O4: COO | P4: Head HR | Q4: Head HR | R4: CEO | S4: Head Sales | T4: Sales Manager | U4: CFO | V4: Accountant | W4: COO | X4: COO | Y4: COO | Z4: Factory Foreman | AA4: Factory Foreman | AB4: Factory Foreman | AC4: Head of Purchasing
F5: 1 | G5: 2 | H5: 3 | I5: 4 | J5: 5 | K5: 6 | L5: 7 | M5: 8 | N5: 9 | O5: 10 | P5: 11 | Q5: 12 | R5: 13 | S5: 14 | T5: 15 | U5: 16 | V5: 17 | W5: 18 | X5: 19 | Y5: 20 | Z5: 21 | AA5: 22 | AB5: 23 | AC5: 24 | AD5: 25 | AE5: 26 | AF5: 27 | AG5: 28 | AH5: 29 | AI5: 30
D6: ='Org Chart'!C3 -> Role (Title) | F6: {=transpose('Org Chart'!$C$4:$C$33)} -> Board | G6: CEO | H6: CFO | I6: COO | J6: Head Marketing | K6: Marketing Manager | L6: Social Media Assistant | M6: Copy Writer | N6: Events Co-ordinator | O6: Head HR | P6: Trainer | Q6: Health & Safety Officer | R6: Head Sales | S6: Sales Manager | T6: Salesperson | U6: Accountant | V6: Bookkeeper | W6: Factory Foreman | X6: Head of Purchasing | Y6: Head of Inventory | Z6: Snr Tech | AA6: Tech | AB6: Jnr Tech | AC6: Personal Assistant
D8: Critical Function 1 | F8: Define Strategy | G8: Report Accurate Position to the Board | H8: Report Accurate Position to the CEO | I8: Report Accurate Position to the CEO | J8: Develop Sales Leads
D9: Critical Function 2 | F9: Build Governance Culture | G9: Implement Board Directives (Operational Objectives) | H9: Maintain Solvency | I9: Oversee the Achievement of Production Targets | J9: Build Brand Recognition
D10: Critical Function 3 | F10: Financial & Risk Management | G10: Build Governance Culture | H10: Meet Financial Compliance Regulations | I10: Support Governance Culture | J10: Maintain Competitive Awareness
D11: Critical Function 4 | F11: Hold to Account | H11: Support Governance Culture
D12: Critical Function 5
D15: Measurable Outputs 1 | F15: Return on Assets | G15: Net Profit | H15: Quick Position | I15: Gross Margin | J15: Unprompted Awareness Tests with Target Market Groups
D16: Measurable Outputs 2
D17: Measurable Outputs 3
D18: Measurable Outputs 4
D19: Measurable Outputs 5
D22: Duties 1
D23: Duties 2
D24: Duties 3
D25: Duties 4
D26: Duties 5
D27: Duties 6
D28: Duties 7
D29: Duties 8
... D51: Expense Account Limit

Sheet Key Sheet
A3: {{Org.chrt.1}} | B3: =F3 -> #REF! | F3: ='Data Input'!C3 -> #REF! | G3: ='Data Input'!D3 -> #REF! | H3: ='Data Input'!E3 -> #REF! | I3: ='Data Input'!F3 -> #REF! | J3: ='Data Input'!G3 -> #REF! | K3: ='Data Input'!H3 -> #REF! | L3: ='Data Input'!I3 -> #REF! | M3: ='Data Input'!J3 -> #REF! | N3: ='Data Input'!K3 -> #REF!
A4: {{Org.chrt.2}} | B4: =F4 -> #REF! | F4: ='Data Input'!C4 -> #REF! | G4: ='Data Input'!D4 -> #REF! | H4: ='Data Input'!E4 -> #REF! | I4: ='Data Input'!F4 -> #REF! | J4: ='Data Input'!G4 -> #REF! | K4: ='Data Input'!H4 -> #REF! | L4: ='Data Input'!I4 -> #REF! | M4: ='Data Input'!J4 -> #REF! | N4: ='Data Input'!K4 -> #REF!
A5: {{Org.chrt.3}} | B5: =F5 -> #REF! | F5: ='Data Input'!C5 -> #REF! | G5: ='Data Input'!D5 -> #REF! | H5: ='Data Input'!E5 -> #REF! | I5: ='Data Input'!F5 -> #REF! | J5: ='Data Input'!G5 -> #REF! | K5: ='Data Input'!H5 -> #REF! | L5: ='Data Input'!I5 -> #REF! | M5: ='Data Input'!J5 -> #REF! | N5: ='Data Input'!K5 -> #REF!
A6: {{Org.chrt.4}} | B6: =F6 -> #REF! | F6: ='Data Input'!C6 -> #REF! | G6: ='Data Input'!D6 -> #REF! | H6: ='Data Input'!E6 -> #REF! | I6: ='Data Input'!F6 -> #REF! | J6: ='Data Input'!G6 -> #REF! | K6: ='Data Input'!H6 -> #REF! | L6: ='Data Input'!I6 -> #REF! | M6: ='Data Input'!J6 -> #REF! | N6: ='Data Input'!K6 -> #REF!
A7: {{Org.chrt.5}} | B7: =F7 -> #REF! | F7: ='Data Input'!C7 -> #REF! | G7: ='Data Input'!D7 -> #REF! | H7: ='Data Input'!E7 -> #REF! | I7: ='Data Input'!F7 -> #REF! | J7: ='Data Input'!G7 -> #REF! | K7: ='Data Input'!H7 -> #REF! | L7: ='Data Input'!I7 -> #REF! | M7: ='Data Input'!J7 -> #REF! | N7: ='Data Input'!K7 -> #REF!
A8: {{Org.chrt.6}} | B8: =F8 -> #REF! | F8: ='Data Input'!C8 -> #REF! | G8: ='Data Input'!D8 -> #REF! | H8: ='Data Input'!E8 -> #REF! | I8: ='Data Input'!F8 -> #REF! | J8: ='Data Input'!G8 -> #REF! | K8: ='Data Input'!H8 -> #REF! | L8: ='Data Input'!I8 -> #REF! | M8: ='Data Input'!J8 -> #REF! | N8: ='Data Input'!K8 -> #REF!
A9: {{Org.chrt.7}} | B9: =F9 -> #REF! | F9: ='Data Input'!C9 -> #REF! | G9: ='Data Input'!D9 -> #REF! | H9: ='Data Input'!E9 -> #REF! | I9: ='Data Input'!F9 -> #REF! | J9: ='Data Input'!G9 -> #REF! | K9: ='Data Input'!H9 -> #REF! | L9: ='Data Input'!I9 -> #REF! | M9: ='Data Input'!J9 -> #REF! | N9: ='Data Input'!K9 -> #REF!
A10: {{Org.chrt.8}} | B10: =G3 -> #REF! | F10: ='Data Input'!C10 -> #REF!
A11: {{Org.chrt.9}} | B11: =G4 -> #REF! | F11: ='Data Input'!C11 -> #REF!
A12: {{Org.chrt.10}} | B12: =G5 -> #REF! | F12: ='Data Input'!C12 -> #REF!
A13: {{Org.chrt.11}} | B13: =G6 -> #REF! | F13: ='Data Input'!C13 -> #REF!
A14: {{Org.chrt.12}} | B14: =G7 -> #REF! | F14: ='Data Input'!C14 -> #REF!
A15: {{Org.chrt.13}} | B15: =G8 -> #REF!
A16: {{Org.chrt.14}} | B16: =G9 -> #REF!
A17: {{Org.chrt.15}} | B17: =H3 -> #REF!
A18: {{Org.chrt.16}} | B18: =H4 -> #REF!
A19: {{Org.chrt.17}} | B19: =H5 -> #REF!
A20: {{Org.chrt.18}} | B20: =H6 -> #REF!
A21: {{Org.chrt.19}} | B21: =H7 -> #REF! | F21: =A3 -> {{Org.chrt.1}} | G21: =A10 -> {{Org.chrt.8}} | H21: =A17 -> {{Org.chrt.15}} | I21: =A24 -> {{Org.chrt.22}} | J21: =A31 -> {{Org.chrt.29}} | K21: =A38 -> {{Org.chrt.36}} | L21: =A45 -> {{Org.chrt.43}} | M21: =A52 -> {{Org.chrt.50}} | N21: =A59 -> {{Org.chrt.57}}
A22: {{Org.chrt.20}} | B22: =H8 -> #REF! | F22: =A4 -> {{Org.chrt.2}} | G22: =A11 -> {{Org.chrt.9}} | H22: =A18 -> {{Org.chrt.16}} | I22: =A25 -> {{Org.chrt.23}} | J22: =A32 -> {{Org.chrt.30}} | K22: =A39 -> {{Org.chrt.37}} | L22: =A46 -> {{Org.chrt.44}} | M22: =A53 -> {{Org.chrt.51}} | N22: =A60 -> {{Org.chrt.58}}
A23: {{Org.chrt.21}} | B23: =H9 -> #REF! | F23: =A5 -> {{Org.chrt.3}} | G23: =A12 -> {{Org.chrt.10}} | H23: =A19 -> {{Org.chrt.17}} | I23: =A26 -> {{Org.chrt.24}} | J23: =A33 -> {{Org.chrt.31}} | K23: =A40 -> {{Org.chrt.38}} | L23: =A47 -> {{Org.chrt.45}} | M23: =A54 -> {{Org.chrt.52}} | N23: =A61 -> {{Org.chrt.59}}
A24: {{Org.chrt.22}} | B24: =I3 -> #REF! | F24: =A6 -> {{Org.chrt.4}} | G24: =A13 -> {{Org.chrt.11}} | H24: =A20 -> {{Org.chrt.18}} | I24: =A27 -> {{Org.chrt.25}} | J24: =A34 -> {{Org.chrt.32}} | K24: =A41 -> {{Org.chrt.39}} | L24: =A48 -> {{Org.chrt.46}} | M24: =A55 -> {{Org.chrt.53}} | N24: =A62 -> {{Org.chrt.60}}
A25: {{Org.chrt.23}} | B25: =I4 -> #REF! | F25: =A7 -> {{Org.chrt.5}} | G25: =A14 -> {{Org.chrt.12}} | H25: =A21 -> {{Org.chrt.19}} | I25: =A28 -> {{Org.chrt.26}} | J25: =A35 -> {{Org.chrt.33}} | K25: =A42 -> {{Org.chrt.40}} | L25: =A49 -> {{Org.chrt.47}} | M25: =A56 -> {{Org.chrt.54}} | N25: =A63 -> {{Org.chrt.61}}
A26: {{Org.chrt.24}} | B26: =I5 -> #REF! | F26: =A8 -> {{Org.chrt.6}} | G26: =A15 -> {{Org.chrt.13}} | H26: =A22 -> {{Org.chrt.20}} | I26: =A29 -> {{Org.chrt.27}} | J26: =A36 -> {{Org.chrt.34}} | K26: =A43 -> {{Org.chrt.41}} | L26: =A50 -> {{Org.chrt.48}} | M26: =A57 -> {{Org.chrt.55}} | N26: =A64 -> {{Org.chrt.62}}
A27: {{Org.chrt.25}} | B27: =I6 -> #REF! | F27: =A9 -> {{Org.chrt.7}} | G27: =A16 -> {{Org.chrt.14}} | H27: =A23 -> {{Org.chrt.21}} | I27: =A30 -> {{Org.chrt.28}} | J27: =A37 -> {{Org.chrt.35}} | K27: =A44 -> {{Org.chrt.42}} | L27: =A51 -> {{Org.chrt.49}} | M27: =A58 -> {{Org.chrt.56}} | N27: =A65 -> {{Org.chrt.63}}
A28: {{Org.chrt.26}} | B28: =I7 -> #REF!
A29: {{Org.chrt.27}} | B29: =I8 -> #REF!
A30: {{Org.chrt.28}} | B30: =I9 -> #REF!
A31: {{Org.chrt.29}} | B31: =J3 -> #REF!
A32: {{Org.chrt.30}} | B32: =J4 -> #REF!
A33: {{Org.chrt.31}} | B33: =J5 -> #REF!
A34: {{Org.chrt.32}} | B34: =J6 -> #REF!
A35: {{Org.chrt.33}} | B35: =J7 -> #REF!
A36: {{Org.chrt.34}} | B36: =J8 -> #REF!
A37: {{Org.chrt.35}} | B37: =J9 -> #REF!
A38: {{Org.chrt.36}} | B38: =K3 -> #REF!
A39: {{Org.chrt.37}} | B39: =K4 -> #REF!
A40: {{Org.chrt.38}} | B40: =K5 -> #REF!
A41: {{Org.chrt.39}} | B41: =K6 -> #REF!
A42: {{Org.chrt.40}} | B42: =K7 -> #REF!
...
