Workbook

Sheet Process
B2: Step 1. Review Past Sales Reports/ Collate Into Matrix | O2: Please Note: IN some cases you may find that stock items are more singular by nature (Imported exotic items as an example) in which case, you may choose to ignore the 'Volume' weighting and place more emphasis on the 'Days on Hand' figures. On the other hand, in cases where you stock large quantities of individual stock items, you may choose to ignore the 'Days on Hand' weighting and place more emphasis on the 'Volume' sold within a set period or, Sales of Units as a % of Stock Units Purchased, combined with 'Margin' and 'Unit Cost Risk)
C3: Review PAST SALES to determine which units have made great Margin, Which units have sold in higher quantities (popularity), which units sold relatively quickly and which units require less 'per unit exposure'. Each assessment 'category' has been allocated a 'weighting'; the total points are combined to provide your highest ranking 'Weighted Average' products.
B7: Step 2. Stock Check
C8: Now compare the 'weighted average' results against your current stock holdings; which do you have plenty of already? (Including incoming units in transit) and assess your 'average daily unit-sold' against the time taken to arrive from the supplier. (If you sell 3 per day on average and it takes 5 days to arrive you need to set your re-order minimum at 15) | O8: Note: The locked sheets do not have a password
B13: Step 3. Financial Check
C14: Review your financial position to determine your Quick Ratio (Liquidity) and assess your total financial exposure to stock against the operational needs of the business. If you have a Capital Expenditure forecast combined with your Sales & Expenses forecast (seasonally adjusted) then now's a good time to look at it BEFORE you get your cheque book out!
B20: Step 4. Order Stock

Sheet Product Categories
B2: Margin Achieved | G2: (Gross Sales Profit)
B4: Points | D4: Rating | F4: Range Min & Max %
B5: 1 | D5: Minor | F5: 0 | G5: 0.25
B6: 2 | D6: Moderate | F6: =G5+1% -> 0.26 | G6: 0.4
B7: 3 | D7: Major | F7: =G6+1% -> 0.41 | G7: 0.8
B8: 4 | D8: Fruitful | F8: =G7+1% -> 0.81 | G8: 1
B9: 5 | D9: Awesome! | F9: =G8+1% -> 1.01 | I9: (Greater Than)
B11: Sales by Volume (per days) | G11: (Popularity of Product) | I11: 60 | K11: % of Stock Units | O11: =G11 -> (Popularity of Product)
I12: DAYS
B13: Points | D13: Rating | F13: Range Min & Max Units | K13: =B13 -> Points | L13: =D13 -> Rating | N13: =F13 -> Range Min & Max Units
B14: 1 | D14: Rare | F14: 1 | G14: 5 | K14: =B14 -> 1 | L14: Drip | N14: 0.01 | O14: 0.05
B15: 2 | D15: Occassional | F15: =G14+1 -> 6 | G15: 10 | K15: =B15 -> 2 | L15: Trickle | N15: =O14+1% -> 0.06 | O15: 0.125
B16: 3 | D16: Regular | F16: =G15+1 -> 11 | G16: 15 | K16: =B16 -> 3 | L16: Flowing | N16: =O15+1% -> 0.135 | O16: 0.33
B17: 4 | D17: Frequent | F17: =G16+1 -> 16 | G17: 25 | K17: =B17 -> 4 | L17: Flood | N17: =O16+1% -> 0.34 | O17: 0.58
B18: 5 | D18: Often | F18: =G17+1 -> 26 | I18: (Greater Than) | K18: =B18 -> 5 | L18: Torrent | N18: =O17+1% -> 0.59 | O18: 1
B20: Days on Hand | G20: (Time Taken)
B22: Points | D22: Rating | F22: Range Min & Max Days
B23: 1 | D23: Dead Wood | F23: 75 | I23: (Greater Than)
B24: 2 | D24: Sleepy | F24: 45 | G24: =F23-1 -> 74
B25: 3 | D25: Come n Go | F25: 28 | G25: =F24-1 -> 44
B26: 4 | D26: Quick Shifter | F26: 14 | G26: =F25-1 -> 27
B27: 5 | D27: Hot Cakes! | F27: 1 | G27: =F26-1 -> 13
B29: Unit Cost Risk | G29: (Unit Cost Exposure)
B31: Points | D31: Rating | F31: Range Min & Max $ Risk
B32: 5 | D32: Minor | F32: 1 | G32: 25
B33: 4 | D33: Low | F33: =G32+1 -> 26 | G33: 40
B34: 3 | D34: Acceptable | F34: =G33+1 -> 41 | G34: 75
B35: 2 | D35: Stressful | F35: =G34+1 -> 76 | G35: 175
B36: 1 | D36: Waking Nites | F36: =G35+1 -> 176 | I36: (Greater Than)

Sheet Sales Report
W2: Total Weighted Average Points
E3: =SUM(E7:E2402) -> 776359.6 | G3: =SUM(G7:G2402) -> 298725.82 | R3: Weighted Points as per Tables
E4: Grand Total | G4: Grand Total | I4: Stock | J4: Stock | M4: Avg Unit Sale | N4: Days on Hand | O4: Avg Unit Cost | P4: % of Stock Units | R4: Margin % | S4: Sales by Vol | T4: Unit Cost Risk | U4: Days on Hand | V4: % of Stock Units
B5: Product Group | C5: Product Code | D5: Quantity | E5: Sales | F5: Cost | G5: Gross Profit | H5: Margin % | I5: Entry Date | J5: Sale Date
C7: Widget 1 | D7: 1 | E7: 60 | F7: =E7-(E7*11%) -> 53.4 | G7: =E7-F7 -> 6.6 | H7: =G7/E7 -> 0.11 | I7: 44355 | J7: 44391 | M7: =if(E7=0,0,E7/D7) -> 60 | N7: =datedif(I7,J7,"D") -> 36 | O7: =if(F7=0,0,F7/D7) -> 53.4 | P7: 0.03 | R7: =IF(AND(H7<='Product Ratings'!$E$5,H7>='Product Ratings'!$D$5),'Product Ratings'!$C$5,IF(AND(H7<='Product Ratings'!$E$6,H7>='Product Ratings'!$D$6),'Product Ratings'!$C$6,IF(AND(H7<='Product Ratings'!$E$7,H7>='Product Ratings'!$D$7),'Product Ratings'!$C$7,IF(AND(H7<='Product Ratings'!$E$8,H7>='Product Ratings'!$D$8),'Product Ratings'!$C$8,IF(H7>='Product Ratings'!$D$9,'Product Ratings'!$C$9))))) -> 1 | S7: =IF(AND(D7<='Product Ratings'!$I$5,D7>='Product Ratings'!$H$5),'Product Ratings'!$F$5,IF(AND(D7<='Product Ratings'!$I$6,D7>='Product Ratings'!$H$6),'Product Ratings'!$F$6,IF(AND(D7<='Product Ratings'!$I$7,I7>='Product Ratings'!$H$7),'Product Ratings'!$F$7,IF(AND(D7<='Product Ratings'!$I$8,D7>='Product Ratings'!$H$8),'Product Ratings'!$F$8,IF(D7>='Product Ratings'!$H$9,'Product Ratings'!$F$9))))) -> 1 | T7: =IF(AND(O7<='Product Ratings'!$M$5,O7>='Product Ratings'!$L$5),'Product Ratings'!$J$5,IF(AND(O7<='Product Ratings'!$M$6,O7>='Product Ratings'!$L$6),'Product Ratings'!$J$6,IF(AND(O7<='Product Ratings'!$M$7,O7>='Product Ratings'!$L$7),'Product Ratings'!$J$7,IF(AND(O7<='Product Ratings'!$M$8,O7>='Product Ratings'!$L$8),'Product Ratings'!$J$8,IF(O7>='Product Ratings'!$L$9,'Product Ratings'!$J$9))))) -> 3 | U7: =IF(AND(N7<='Product Ratings'!$R$5,N7>='Product Ratings'!$Q$5),'Product Ratings'!$O$5,IF(AND(N7<='Product Ratings'!$R$6,N7>='Product Ratings'!$Q$6),'Product Ratings'!$O$6,IF(AND(N7<='Product Ratings'!$R$7,N7>='Product Ratings'!$Q$7),'Product Ratings'!$O$7,IF(AND(N7<='Product Ratings'!$R$8,N7>='Product Ratings'!$Q$8),'Product Ratings'!$O$8,IF(N7>='Product Ratings'!$Q$9,'Product Ratings'!$O$9))))) -> 3 | V7: =IF(AND(P7<='Product Ratings'!$V$5,P7>='Product Ratings'!$U$5),'Product Ratings'!$S$5,IF(AND(P7<='Product Ratings'!$V$6,P7>='Product Ratings'!$U$6),'Product Ratings'!$S$6,IF(AND(P7<='Product Ratings'!$V$7,P7>='Product Ratings'!$U$7),'Product Ratings'!$S$7,IF(AND(P7<='Product Ratings'!$V$8,P7>='Product Ratings'!$U$8),'Product Ratings'!$S$8,IF(P7>='Product Ratings'!$U$9,'Product Ratings'!$S$9))))) -> 1 | W7: =SUM(R7:V7) -> 9
C8: Widget 2 | D8: 2 | E8: 998.17 | F8: =E8-(E8*12%) -> 878.3896 | G8: =E8-F8 -> 119.7804 | H8: =G8/E8 -> 0.12 | I8: 44356 | J8: 44392 | M8: =if(E8=0,0,E8/D8) -> 499.085 | N8: =datedif(I8,J8,"D") -> 36 | O8: =if(F8=0,0,F8/D8) -> 439.1948 | P8: 0.04 | R8: =IF(AND(H8<='Product Ratings'!$E$5,H8>='Product Ratings'!$D$5),'Product Ratings'!$C$5,IF(AND(H8<='Product Ratings'!$E$6,H8>='Product Ratings'!$D$6),'Product Ratings'!$C$6,IF(AND(H8<='Product Ratings'!$E$7,H8>='Product Ratings'!$D$7),'Product Ratings'!$C$7,IF(AND(H8<='Product Ratings'!$E$8,H8>='Product Ratings'!$D$8),'Product Ratings'!$C$8,IF(H8>='Product Ratings'!$D$9,'Product Ratings'!$C$9))))) -> 1 | S8: =IF(AND(D8<='Product Ratings'!$I$5,D8>='Product Ratings'!$H$5),'Product Ratings'!$F$5,IF(AND(D8<='Product Ratings'!$I$6,D8>='Product Ratings'!$H$6),'Product Ratings'!$F$6,IF(AND(D8<='Product Ratings'!$I$7,I8>='Product Ratings'!$H$7),'Product Ratings'!$F$7,IF(AND(D8<='Product Ratings'!$I$8,D8>='Product Ratings'!$H$8),'Product Ratings'!$F$8,IF(D8>='Product Ratings'!$H$9,'Product Ratings'!$F$9))))) -> 1 | T8: =IF(AND(O8<='Product Ratings'!$M$5,O8>='Product Ratings'!$L$5),'Product Ratings'!$J$5,IF(AND(O8<='Product Ratings'!$M$6,O8>='Product Ratings'!$L$6),'Product Ratings'!$J$6,IF(AND(O8<='Product Ratings'!$M$7,O8>='Product Ratings'!$L$7),'Product Ratings'!$J$7,IF(AND(O8<='Product Ratings'!$M$8,O8>='Product Ratings'!$L$8),'Product Ratings'!$J$8,IF(O8>='Product Ratings'!$L$9,'Product Ratings'!$J$9))))) -> 1 | U8: =IF(AND(N8<='Product Ratings'!$R$5,N8>='Product Ratings'!$Q$5),'Product Ratings'!$O$5,IF(AND(N8<='Product Ratings'!$R$6,N8>='Product Ratings'!$Q$6),'Product Ratings'!$O$6,IF(AND(N8<='Product Ratings'!$R$7,N8>='Product Ratings'!$Q$7),'Product Ratings'!$O$7,IF(AND(N8<='Product Ratings'!$R$8,N8>='Product Ratings'!$Q$8),'Product Ratings'!$O$8,IF(N8>='Product Ratings'!$Q$9,'Product Ratings'!$O$9))))) -> 3 | V8: =IF(AND(P8<='Product Ratings'!$V$5,P8>='Product Ratings'!$U$5),'Product Ratings'!$S$5,IF(AND(P8<='Product Ratings'!$V$6,P8>='Product Ratings'!$U$6),'Product Ratings'!$S$6,IF(AND(P8<='Product Ratings'!$V$7,P8>='Product Ratings'!$U$7),'Product Ratings'!$S$7,IF(AND(P8<='Product Ratings'!$V$8,P8>='Product Ratings'!$U$8),'Product Ratings'!$S$8,IF(P8>='Product Ratings'!$U$9,'Product Ratings'!$S$9))))) -> 1 | W8: =SUM(R8:V8) -> 7
C9: Widget 3 | D9: 3 | E9: 86.96 | F9: =E9-(E9*13%) -> 75.6552 | G9: =E9-F9 -> 11.3048 | H9: =G9/E9 -> 0.13 | I9: 44357 | J9: 44393 | M9: =if(E9=0,0,E9/D9) -> 28.986667 | N9: =datedif(I9,J9,"D") -> 36 | O9: =if(F9=0,0,F9/D9) -> 25.2184 | P9: 0.05 | R9: =IF(AND(H9<='Product Ratings'!$E$5,H9>='Product Ratings'!$D$5),'Product Ratings'!$C$5,IF(AND(H9<='Product Ratings'!$E$6,H9>='Product Ratings'!$D$6),'Product Ratings'!$C$6,IF(AND(H9<='Product Ratings'!$E$7,H9>='Product Ratings'!$D$7),'Product Ratings'!$C$7,IF(AND(H9<='Product Ratings'!$E$8,H9>='Product Ratings'!$D$8),'Product Ratings'!$C$8,IF(H9>='Product Ratings'!$D$9,'Product Ratings'!$C$9))))) -> 1 | S9: =IF(AND(D9<='Product Ratings'!$I$5,D9>='Product Ratings'!$H$5),'Product Ratings'!$F$5,IF(AND(D9<='Product Ratings'!$I$6,D9>='Product Ratings'!$H$6),'Product Ratings'!$F$6,IF(AND(D9<='Product Ratings'!$I$7,I9>='Product Ratings'!$H$7),'Product Ratings'!$F$7,IF(AND(D9<='Product Ratings'!$I$8,D9>='Product Ratings'!$H$8),'Product Ratings'!$F$8,IF(D9>='Product Ratings'!$H$9,'Product Ratings'!$F$9))))) -> 1 | T9: =IF(AND(O9<='Product Ratings'!$M$5,O9>='Product Ratings'!$L$5),'Product Ratings'!$J$5,IF(AND(O9<='Product Ratings'!$M$6,O9>='Product Ratings'!$L$6),'Product Ratings'!$J$6,IF(AND(O9<='Product Ratings'!$M$7,O9>='Product Ratings'!$L$7),'Product Ratings'!$J$7,IF(AND(O9<='Product Ratings'!$M$8,O9>='Product Ratings'!$L$8),'Product Ratings'!$J$8,IF(O9>='Product Ratings'!$L$9,'Product Ratings'!$J$9))))) -> FALSE | U9: =IF(AND(N9<='Product Ratings'!$R$5,N9>='Product Ratings'!$Q$5),'Product Ratings'!$O$5,IF(AND(N9<='Product Ratings'!$R$6,N9>='Product Ratings'!$Q$6),'Product Ratings'!$O$6,IF(AND(N9<='Product Ratings'!$R$7,N9>='Product Ratings'!$Q$7),'Product Ratings'!$O$7,IF(AND(N9<='Product Ratings'!$R$8,N9>='Product Ratings'!$Q$8),'Product Ratings'!$O$8,IF(N9>='Product Ratings'!$Q$9,'Product Ratings'!$O$9))))) -> 3 | V9: =IF(AND(P9<='Product Ratings'!$V$5,P9>='Product Ratings'!$U$5),'Product Ratings'!$S$5,IF(AND(P9<='Product Ratings'!$V$6,P9>='Product Ratings'!$U$6),'Product Ratings'!$S$6,IF(AND(P9<='Product Ratings'!$V$7,P9>='Product Ratings'!$U$7),'Product Ratings'!$S$7,IF(AND(P9<='Product Ratings'!$V$8,P9>='Product Ratings'!$U$8),'Product Ratings'!$S$8,IF(P9>='Product Ratings'!$U$9,'Product Ratings'!$S$9))))) -> 1 | W9: =SUM(R9:V9) -> 6
C10: Widget 4 | D10: 4 | E10: 82.17 | F10: =E10-(E10*11%) -> 73.1313 | G10: =E10-F10 -> 9.0387 | H10: =G10/E10 -> 0.11 | I10: 44358 | J10: 44394 | M10: =if(E10=0,0,E10/D10) -> 20.5425 | N10: =datedif(I10,J10,"D") -> 36 | O10: =if(F10=0,0,F10/D10) -> 18.282825 | P10: 0.06 | R10: =IF(AND(H10<='Product Ratings'!$E$5,H10>='Product Ratings'!$D$5),'Product Ratings'!$C$5,IF(AND(H10<='Product Ratings'!$E$6,H10>='Product Ratings'!$D$6),'Product Ratings'!$C$6,IF(AND(H10<='Product Ratings'!$E$7,H10>='Product Ratings'!$D$7),'Product Ratings'!$C$7,IF(AND(H10<='Product Ratings'!$E$8,H10>='Product Ratings'!$D$8),'Product Ratings'!$C$8,IF(H10>='Product Ratings'!$D$9,'Product Ratings'!$C$9))))) -> 1 | S10: =IF(AND(D10<='Product Ratings'!$I$5,D10>='Product Ratings'!$H$5),'Product Ratings'!$F$5,IF(AND(D10<='Product Ratings'!$I$6,D10>='Product Ratings'!$H$6),'Product Ratings'!$F$6,IF(AND(D10<='Product Ratings'!$I$7,I10>='Product Ratings'!$H$7),'Product Ratings'!$F$7,IF(AND(D10<='Product Ratings'!$I$8,D10>='Product Ratings'!$H$8),'Product Ratings'!$F$8,IF(D10>='Product Ratings'!$H$9,'Product Ratings'!$F$9))))) -> 1 | T10: =IF(AND(O10<='Product Ratings'!$M$5,O10>='Product Ratings'!$L$5),'Product Ratings'!$J$5,IF(AND(O10<='Product Ratings'!$M$6,O10>='Product Ratings'!$L$6),'Product Ratings'!$J$6,IF(AND(O10<='Product Ratings'!$M$7,O10>='Product Ratings'!$L$7),'Product Ratings'!$J$7,IF(AND(O10<='Product Ratings'!$M$8,O10>='Product Ratings'!$L$8),'Product Ratings'!$J$8,IF(O10>='Product Ratings'!$L$9,'Product Ratings'!$J$9))))) -> 5 | U10: =IF(AND(N10<='Product Ratings'!$R$5,N10>='Product Ratings'!$Q$5),'Product Ratings'!$O$5,IF(AND(N10<='Product Ratings'!$R$6,N10>='Product Ratings'!$Q$6),'Product Ratings'!$O$6,IF(AND(N10<='Product Ratings'!$R$7,N10>='Product Ratings'!$Q$7),'Product Ratings'!$O$7,IF(AND(N10<='Product Ratings'!$R$8,N10>='Product Ratings'!$Q$8),'Product Ratings'!$O$8,IF(N10>='Product Ratings'!$Q$9,'Product Ratings'!$O$9))))) -> 3 | V10: =IF(AND(P10<='Product Ratings'!$V$5,P10>='Product Ratings'!$U$5),'Product Ratings'!$S$5,IF(AND(P10<='Product Ratings'!$V$6,P10>='Product Ratings'!$U$6),'Product Ratings'!$S$6,IF(AND(P10<='Product Ratings'!$V$7,P10>='Product Ratings'!$U$7),'Product Ratings'!$S$7,IF(AND(P10<='Product Ratings'!$V$8,P10>='Product Ratings'!$U$8),'Product Ratings'!$S$8,IF(P10>='Product Ratings'!$U$9,'Product Ratings'!$S$9))))) -> 2 | W10: =SUM(R10:V10) -> 12
C11: Widget 5 | D11: 5 | E11: 809.89 | F11: =E11-(E11*12%) -> 712.7032 | G11: =E11-F11 -> 97.1868 | H11: =G11/E11 -> 0.12 | I11: 44359 | J11: 44395 | M11: =if(E11=0,0,E11/D11) -> 161.978 | N11: =datedif(I11,J11,"D") -> 36 | O11: =if(F11=0,0,F11/D11) -> 142.54064 | P11: 0.07 | R11: =IF(AND(H11<='Product Ratings'!$E$5,H11>='Product Ratings'!$D$5),'Product Ratings'!$C$5,IF(AND(H11<='Product Ratings'!$E$6,H11>='Product Ratings'!$D$6),'Product Ratings'!$C$6,IF(AND(H11<='Product Ratings'!$E$7,H11>='Product Ratings'!$D$7),'Product Ratings'!$C$7,IF(AND(H11<='Product Ratings'!$E$8,H11>='Product Ratings'!$D$8),'Product Ratings'!$C$8,IF(H11>='Product Ratings'!$D$9,'Product Ratings'!$C$9))))) -> 1 | S11: =IF(AND(D11<='Product Ratings'!$I$5,D11>='Product Ratings'!$H$5),'Product Ratings'!$F$5,IF(AND(D11<='Product Ratings'!$I$6,D11>='Product Ratings'!$H$6),'Product Ratings'!$F$6,IF(AND(D11<='Product Ratings'!$I$7,I11>='Product Ratings'!$H$7),'Product Ratings'!$F$7,IF(AND(D11<='Product Ratings'!$I$8,D11>='Product Ratings'!$H$8),'Product Ratings'!$F$8,IF(D11>='Product Ratings'!$H$9,'Product Ratings'!$F$9))))) -> 1 | T11: =IF(AND(O11<='Product Ratings'!$M$5,O11>='Product Ratings'!$L$5),'Product Ratings'!$J$5,IF(AND(O11<='Product Ratings'!$M$6,O11>='Product Ratings'!$L$6),'Product Ratings'!$J$6,IF(AND(O11<='Product Ratings'!$M$7,O11>='Product Ratings'!$L$7),'Product Ratings'!$J$7,IF(AND(O11<='Product Ratings'!$M$8,O11>='Product Ratings'!$L$8),'Product Ratings'!$J$8,IF(O11>='Product Ratings'!$L$9,'Product Ratings'!$J$9))))) -> 2 | U11: =IF(AND(N11<='Product Ratings'!$R$5,N11>='Product Ratings'!$Q$5),'Product Ratings'!$O$5,IF(AND(N11<='Product Ratings'!$R$6,N11>='Product Ratings'!$Q$6),'Product Ratings'!$O$6,IF(AND(N11<='Product Ratings'!$R$7,N11>='Product Ratings'!$Q$7),'Product Ratings'!$O$7,IF(AND(N11<='Product Ratings'!$R$8,N11>='Product Ratings'!$Q$8),'Product Ratings'!$O$8,IF(N11>='Product Ratings'!$Q$9,'Product Ratings'!$O$9))))) -> 3 | V11: =IF(AND(P11<='Product Ratings'!$V$5,P11>='Product Ratings'!$U$5),'Product Ratings'!$S$5,IF(AND(P11<='Product Ratings'!$V$6,P11>='Product Ratings'!$U$6),'Product Ratings'!$S$6,IF(AND(P11<='Product Ratings'!$V$7,P11>='Product Ratings'!$U$7),'Product Ratings'!$S$7,IF(AND(P11<='Product Ratings'!$V$8,P11>='Product Ratings'!$U$8),'Product Ratings'!$S$8,IF(P11>='Product Ratings'!$U$9,'Product Ratings'!$S$9))))) -> 2 | W11: =SUM(R11:V11) -> 9
C12: Widget 6 | D12: 6 | E12: 695.65 | F12: =E12-(E12*13%) -> 605.2155 | G12: =E12-F12 -> 90.4345 | H12: =G12/E12 -> 0.13 | I12: 44360 | J12: 44396 | M12: =if(E12=0,0,E12/D12) -> 115.94167 | N12: =datedif(I12,J12,"D") -> 36 | O12: =if(F12=0,0,F12/D12) -> 100.86925 | P12: 0.08 | R12: =IF(AND(H12<='Product Ratings'!$E$5,H12>='Product Ratings'!$D$5),'Product Ratings'!$C$5,IF(AND(H12<='Product Ratings'!$E$6,H12>='Product Ratings'!$D$6),'Product Ratings'!$C$6,IF(AND(H12<='Product Ratings'!$E$7,H12>='Product Ratings'!$D$7),'Product Ratings'!$C$7,IF(AND(H12<='Product Ratings'!$E$8,H12>='Product Ratings'!$D$8),'Product Ratings'!$C$8,IF(H12>='Product Ratings'!$D$9,'Product Ratings'!$C$9))))) -> 1 | S12: =IF(AND(D12<='Product Ratings'!$I$5,D12>='Product Ratings'!$H$5),'Product Ratings'!$F$5,IF(AND(D12<='Product Ratings'!$I$6,D12>='Product Ratings'!$H$6),'Product Ratings'!$F$6,IF(AND(D12<='Product Ratings'!$I$7,I12>='Product Ratings'!$H$7),'Product Ratings'!$F$7,IF(AND(D12<='Product Ratings'!$I$8,D12>='Product Ratings'!$H$8),'Product Ratings'!$F$8,IF(D12>='Product Ratings'!$H$9,'Product Ratings'!$F$9))))) -> 2 | T12: =IF(AND(O12<='Product Ratings'!$M$5,O12>='Product Ratings'!$L$5),'Product Ratings'!$J$5,IF(AND(O12<='Product Ratings'!$M$6,O12>='Product Ratings'!$L$6),'Product Ratings'!$J$6,IF(AND(O12<='Product Ratings'!$M$7,O12>='Product Ratings'!$L$7),'Product Ratings'!$J$7,IF(AND(O12<='Product Ratings'!$M$8,O12>='Product Ratings'!$L$8),'Product Ratings'!$J$8,IF(O12>='Product Ratings'!$L$9,'Product Ratings'!$J$9))))) -> 2 | U12: =IF(AND(N12<='Product Ratings'!$R$5,N12>='Product Ratings'!$Q$5),'Product Ratings'!$O$5,IF(AND(N12<='Product Ratings'!$R$6,N12>='Product Ratings'!$Q$6),'Product Ratings'!$O$6,IF(AND(N12<='Product Ratings'!$R$7,N12>='Product Ratings'!$Q$7),'Product Ratings'!$O$7,IF(AND(N12<='Product Ratings'!$R$8,N12>='Product Ratings'!$Q$8),'Product Ratings'!$O$8,IF(N12>='Product Ratings'!$Q$9,'Product Ratings'!$O$9))))) -> 3 | V12: =IF(AND(P12<='Product Ratings'!$V$5,P12>='Product Ratings'!$U$5),'Product Ratings'!$S$5,IF(AND(P12<='Product Ratings'!$V$6,P12>='Product Ratings'!$U$6),'Product Ratings'!$S$6,IF(AND(P12<='Product Ratings'!$V$7,P12>='Product Ratings'!$U$7),'Product Ratings'!$S$7,IF(AND(P12<='Product Ratings'!$V$8,P12>='Product Ratings'!$U$8),'Product Ratings'!$S$8,IF(P12>='Product Ratings'!$U$9,'Product Ratings'!$S$9))))) -> 2 | W12: =SUM(R12:V12) -> 10
C13: Widget 7 | D13: 1 | E13: 69.57 | F13: =E13-(E13*11%) -> 61.9173 | G13: =E13-F13 -> 7.6527 | H13: =G13/E13 -> 0.11 | I13: 44361 | J13: 44397 | M13: =if(E13=0,0,E13/D13) -> 69.57 | N13: =datedif(I13,J13,"D") -> 36 | O13: =if(F13=0,0,F13/D13) -> 61.9173 | P13: 0.09 | R13: =IF(AND(H13<='Product Ratings'!$E$5,H13>='Product Ratings'!$D$5),'Product Ratings'!$C$5,IF(AND(H13<='Product Ratings'!$E$6,H13>='Product Ratings'!$D$6),'Product Ratings'!$C$6,IF(AND(H13<='Product Ratings'!$E$7,H13>='Product Ratings'!$D$7),'Product Ratings'!$C$7,IF(AND(H13<='Product Ratings'!$E$8,H13>='Product Ratings'!$D$8),'Product Ratings'!$C$8,IF(H13>='Product Ratings'!$D$9,'Product Ratings'!$C$9))))) -> 1 | S13: =IF(AND(D13<='Product Ratings'!$I$5,D13>='Product Ratings'!$H$5),'Product Ratings'!$F$5,IF(AND(D13<='Product Ratings'!$I$6,D13>='Product Ratings'!$H$6),'Product Ratings'!$F$6,IF(AND(D13<='Product Ratings'!$I$7,I13>='Product Ratings'!$H$7),'Product Ratings'!$F$7,IF(AND(D13<='Product Ratings'!$I$8,D13>='Product Ratings'!$H$8),'Product Ratings'!$F$8,IF(D13>='Product Ratings'!$H$9,'Product Ratings'!$F$9))))) -> 1 | T13: =IF(AND(O13<='Product Ratings'!$M$5,O13>='Product Ratings'!$L$5),'Product Ratings'!$J$5,IF(AND(O13<='Product Ratings'!$M$6,O13>='Product Ratings'!$L$6),'Product Ratings'!$J$6,IF(AND(O13<='Product Ratings'!$M$7,O13>='Product Ratings'!$L$7),'Product Ratings'!$J$7,IF(AND(O13<='Product Ratings'!$M$8,O13>='Product Ratings'!$L$8),'Product Ratings'!$J$8,IF(O13>='Product Ratings'!$L$9,'Product Ratings'!$J$9))))) -> 3 | U13: =IF(AND(N13<='Product Ratings'!$R$5,N13>='Product Ratings'!$Q$5),'Product Ratings'!$O$5,IF(AND(N13<='Product Ratings'!$R$6,N13>='Product Ratings'!$Q$6),'Product Ratings'!$O$6,IF(AND(N13<='Product Ratings'!$R$7,N13>='Product Ratings'!$Q$7),'Product Ratings'!$O$7,IF(AND(N13<='Product Ratings'!$R$8,N13>='Product Ratings'!$Q$8),'Product Ratings'!$O$8,IF(N13>='Product Ratings'!$Q$9,'Product Ratings'!$O$9))))) -> 3 | V13: =IF(AND(P13<='Product Ratings'!$V$5,P13>='Product Ratings'!$U$5),'Product Ratings'!$S$5,IF(AND(P13<='Product Ratings'!$V$6,P13>='Product Ratings'!$U$6),'Product Ratings'!$S$6,IF(AND(P13<='Product Ratings'!$V$7,P13>='Product Ratings'!$U$7),'Product Ratings'!$S$7,IF(AND(P13<='Product Ratings'!$V$8,P13>='Product Ratings'!$U$8),'Product Ratings'!$S$8,IF(P13>='Product Ratings'!$U$9,'Product Ratings'!$S$9))))) -> 2 | W13: =SUM(R13:V13) -> 10
C14: Widget 8 | D14: 2 | E14: 65.22 | F14: =E14-(E14*12%) -> 57.3936 | G14: =E14-F14 -> 7.8264 | H14: =G14/E14 -> 0.12 | I14: 44362 | J14: 44398 | M14: =if(E14=0,0,E14/D14) -> 32.61 | N14: =datedif(I14,J14,"D") -> 36 | O14: =if(F14=0,0,F14/D14) -> 28.6968 | P14: 0.12 | R14: =IF(AND(H14<='Product Ratings'!$E$5,H14>='Product Ratings'!$D$5),'Product Ratings'!$C$5,IF(AND(H14<='Product Ratings'!$E$6,H14>='Product Ratings'!$D$6),'Product Ratings'!$C$6,IF(AND(H14<='Product Ratings'!$E$7,H14>='Product Ratings'!$D$7),'Product Ratings'!$C$7,IF(AND(H14<='Product Ratings'!$E$8,H14>='Product Ratings'!$D$8),'Product Ratings'!$C$8,IF(H14>='Product Ratings'!$D$9,'Product Ratings'!$C$9))))) -> 1 | S14: =IF(AND(D14<='Product Ratings'!$I$5,D14>='Product Ratings'!$H$5),'Product Ratings'!$F$5,IF(AND(D14<='Product Ratings'!$I$6,D14>='Product Ratings'!$H$6),'Product Ratings'!$F$6,IF(AND(D14<='Product Ratings'!$I$7,I14>='Product Ratings'!$H$7),'Product Ratings'!$F$7,IF(AND(D14<='Product Ratings'!$I$8,D14>='Product Ratings'!$H$8),'Product Ratings'!$F$8,IF(D14>='Product Ratings'!$H$9,'Product Ratings'!$F$9))))) -> 1 | T14: =IF(AND(O14<='Product Ratings'!$M$5,O14>='Product Ratings'!$L$5),'Product Ratings'!$J$5,IF(AND(O14<='Product Ratings'!$M$6,O14>='Product Ratings'!$L$6),'Product Ratings'!$J$6,IF(AND(O14<='Product Ratings'!$M$7,O14>='Product Ratings'!$L$7),'Product Ratings'!$J$7,IF(AND(O14<='Product Ratings'!$M$8,O14>='Product Ratings'!$L$8),'Product Ratings'!$J$8,IF(O14>='Product Ratings'!$L$9,'Product Ratings'!$J$9))))) -> 4 | U14: =IF(AND(N14<='Product Ratings'!$R$5,N14>='Product Ratings'!$Q$5),'Product Ratings'!$O$5,IF(AND(N14<='Product Ratings'!$R$6,N14>='Product Ratings'!$Q$6),'Product Ratings'!$O$6,IF(AND(N14<='Product Ratings'!$R$7,N14>='Product Ratings'!$Q$7),'Product Ratings'!$O$7,IF(AND(N14<='Product Ratings'!$R$8,N14>='Product Ratings'!$Q$8),'Product Ratings'!$O$8,IF(N14>='Product Ratings'!$Q$9,'Product Ratings'!$O$9))))) -> 3 | V14: =IF(AND(P14<='Product Ratings'!$V$5,P14>='Product Ratings'!$U$5),'Product Ratings'!$S$5,IF(AND(P14<='Product Ratings'!$V$6,P14>='Product Ratings'!$U$6),'Product Ratings'!$S$6,IF(AND(P14<='Product Ratings'!$V$7,P14>='Product Ratings'!$U$7),'Product Ratings'!$S$7,IF(AND(P14<='Product Ratings'!$V$8,P14>='Product Ratings'!$U$8),'Product Ratings'!$S$8,IF(P14>='Product Ratings'!$U$9,'Product Ratings'!$S$9))))) -> 2 | W14: =SUM(R14:V14) -> 11
C15: Widget 9 | D15: 3 | E15: 608.7 | F15: =E15-(E15*13%) -> 529.569 | G15: =E15-F15 -> 79.131 | H15: =G15/E15 -> 0.13 | I15: 44363 | J15: 44399 | M15: =if(E15=0,0,E15/D15) -> 202.9 | N15: =datedif(I15,J15,"D") -> 36 | O15: =if(F15=0,0,F15/D15) -> 176.523 | P15: 0.13 | R15: =IF(AND(H15<='Product Ratings'!$E$5,H15>='Product Ratings'!$D$5),'Product Ratings'!$C$5,IF(AND(H15<='Product Ratings'!$E$6,H15>='Product Ratings'!$D$6),'Product Ratings'!$C$6,IF(AND(H15<='Product Ratings'!$E$7,H15>='Product Ratings'!$D$7),'Product Ratings'!$C$7,IF(AND(H15<='Product Ratings'!$E$8,H15>='Product Ratings'!$D$8),'Product Ratings'!$C$8,IF(H15>='Product Ratings'!$D$9,'Product Ratings'!$C$9))))) -> 1 | S15: =IF(AND(D15<='Product Ratings'!$I$5,D15>='Product Ratings'!$H$5),'Product Ratings'!$F$5,IF(AND(D15<='Product Ratings'!$I$6,D15>='Product Ratings'!$H$6),'Product Ratings'!$F$6,IF(AND(D15<='Product Ratings'!$I$7,I15>='Product Ratings'!$H$7),'Product Ratings'!$F$7,IF(AND(D15<='Product Ratings'!$I$8,D15>='Product Ratings'!$H$8),'Product Ratings'!$F$8,IF(D15>='Product Ratings'!$H$9,'Product Ratings'!$F$9))))) -> 1 | T15: =IF(AND(O15<='Product Ratings'!$M$5,O15>='Product Ratings'!$L$5),'Product Ratings'!$J$5,IF(AND(O15<='Product Ratings'!$M$6,O15>='Product Ratings'!$L$6),'Product Ratings'!$J$6,IF(AND(O15<='Product Ratings'!$M$7,O15>='Product Ratings'!$L$7),'Product Ratings'!$J$7,IF(AND(O15<='Product Ratings'!$M$8,O15>='Product Ratings'!$L$8),'Product Ratings'!$J$8,IF(O15>='Product Ratings'!$L$9,'Product Ratings'!$J$9))))) -> 1 | U15: =IF(AND(N15<='Product Ratings'!$R$5,N15>='Product Ratings'!$Q$5),'Product Ratings'!$O$5,IF(AND(N15<='Product Ratings'!$R$6,N15>='Product Ratings'!$Q$6),'Product Ratings'!$O$6,IF(AND(N15<='Product Ratings'!$R$7,N15>='Product Ratings'!$Q$7),'Product Ratings'!$O$7,IF(AND(N15<='Product Ratings'!$R$8,N15>='Product Ratings'!$Q$8),'Product Ratings'!$O$8,IF(N15>='Product Ratings'!$Q$9,'Product Ratings'!$O$9))))) -> 3 | V15: =IF(AND(P15<='Product Ratings'!$V$5,P15>='Product Ratings'!$U$5),'Product Ratings'!$S$5,IF(AND(P15<='Product Ratings'!$V$6,P15>='Product Ratings'!$U$6),'Product Ratings'!$S$6,IF(AND(P15<='Product Ratings'!$V$7,P15>='Product Ratings'!$U$7),'Product Ratings'!$S$7,IF(AND(P15<='Product Ratings'!$V$8,P15>='Product Ratings'!$U$8),'Product Ratings'!$S$8,IF(P15>='Product Ratings'!$U$9,'Product Ratings'!$S$9))))) -> FALSE | W15: =SUM(R15:V15) -> 6
C16: Widget 10 | D16: 4 | E16: 60 | F16: =E16-(E16*11%) -> 53.4 | G16: =E16-F16 -> 6.6 | H16: =G16/E16 -> 0.11 | I16: 44364 | J16: 44400 | M16: =if(E16=0,0,E16/D16) -> 15 | N16: =datedif(I16,J16,"D") -> 36 | O16: =if(F16=0,0,F16/D16) -> 13.35 | P16: 0.125 | R16: =IF(AND(H16<='Product Ratings'!$E$5,H16>='Product Ratings'!$D$5),'Product Ratings'!$C$5,IF(AND(H16<='Product Ratings'!$E$6,H16>='Product Ratings'!$D$6),'Product Ratings'!$C$6,IF(AND(H16<='Product Ratings'!$E$7,H16>='Product Ratings'!$D$7),'Product Ratings'!$C$7,IF(AND(H16<='Product Ratings'!$E$8,H16>='Product Ratings'!$D$8),'Product Ratings'!$C$8,IF(H16>='Product Ratings'!$D$9,'Product Ratings'!$C$9))))) -> 1 | S16: =IF(AND(D16<='Product Ratings'!$I$5,D16>='Product Ratings'!$H$5),'Product Ratings'!$F$5,IF(AND(D16<='Product Ratings'!$I$6,D16>='Product Ratings'!$H$6),'Product Ratings'!$F$6,IF(AND(D16<='Product Ratings'!$I$7,I16>='Product Ratings'!$H$7),'Product Ratings'!$F$7,IF(AND(D16<='Product Ratings'!$I$8,D16>='Product Ratings'!$H$8),'Product Ratings'!$F$8,IF(D16>='Product Ratings'!$H$9,'Product Ratings'!$F$9))))) -> 1 | T16: =IF(AND(O16<='Product Ratings'!$M$5,O16>='Product Ratings'!$L$5),'Product Ratings'!$J$5,IF(AND(O16<='Product Ratings'!$M$6,O16>='Product Ratings'!$L$6),'Product Ratings'!$J$6,IF(AND(O16<='Product Ratings'!$M$7,O16>='Product Ratings'!$L$7),'Product Ratings'!$J$7,IF(AND(O16<='Product Ratings'!$M$8,O16>='Product Ratings'!$L$8),'Product Ratings'!$J$8,IF(O16>='Product Ratings'!$L$9,'Product Ratings'!$J$9))))) -> 5 | U16: =IF(AND(N16<='Product Ratings'!$R$5,N16>='Product Ratings'!$Q$5),'Product Ratings'!$O$5,IF(AND(N16<='Product Ratings'!$R$6,N16>='Product Ratings'!$Q$6),'Product Ratings'!$O$6,IF(AND(N16<='Product Ratings'!$R$7,N16>='Product Ratings'!$Q$7),'Product Ratings'!$O$7,IF(AND(N16<='Product Ratings'!$R$8,N16>='Product Ratings'!$Q$8),'Product Ratings'!$O$8,IF(N16>='Product Ratings'!$Q$9,'Product Ratings'!$O$9))))) -> 3 | V16: =IF(AND(P16<='Product Ratings'!$V$5,P16>='Product Ratings'!$U$5),'Product Ratings'!$S$5,IF(AND(P16<='Product Ratings'!$V$6,P16>='Product Ratings'!$U$6),'Product Ratings'!$S$6,IF(AND(P16<='Product Ratings'!$V$7,P16>='Product Ratings'!$U$7),'Product Ratings'!$S$7,IF(AND(P16<='Product Ratings'!$V$8,P16>='Product Ratings'!$U$8),'Product Ratings'!$S$8,IF(P16>='Product Ratings'!$U$9,'Product Ratings'!$S$9))))) -> 2 | W16: =SUM(R16:V16) -> 12
C17: Widget 11 | D17: 5 | E17: 60 | F17: =E17-(E17*14%) -> 51.6 | G17: =E17-F17 -> 8.4 | H17: =G17/E17 -> 0.14 | I17: 44365 | J17: 44401 | M17: =if(E17=0,0,E17/D17) -> 12 | N17: =datedif(I17,J17,"D") -> 36 | O17: =if(F17=0,0,F17/D17) -> 10.32 | P17: 0.15 | R17: =IF(AND(H17<='Product Ratings'!$E$5,H17>='Product Ratings'!$D$5),'Product Ratings'!$C$5,IF(AND(H17<='Product Ratings'!$E$6,H17>='Product Ratings'!$D$6),'Product Ratings'!$C$6,IF(AND(H17<='Product Ratings'!$E$7,H17>='Product Ratings'!$D$7),'Product Ratings'!$C$7,IF(AND(H17<='Product Ratings'!$E$8,H17>='Product Ratings'!$D$8),'Product Ratings'!$C$8,IF(H17>='Product Ratings'!$D$9,'Product Ratings'!$C$9))))) -> 1 | S17: =IF(AND(D17<='Product Ratings'!$I$5,D17>='Product Ratings'!$H$5),'Product Ratings'!$F$5,IF(AND(D17<='Product Ratings'!$I$6,D17>='Product Ratings'!$H$6),'Product Ratings'!$F$6,IF(AND(D17<='Product Ratings'!$I$7,I17>='Product Ratings'!$H$7),'Product Ratings'!$F$7,IF(AND(D17<='Product Ratings'!$I$8,D17>='Product Ratings'!$H$8),'Product Ratings'!$F$8,IF(D17>='Product Ratings'!$H$9,'Product Ratings'!$F$9))))) -> 1 | T17: =IF(AND(O17<='Product Ratings'!$M$5,O17>='Product Ratings'!$L$5),'Product Ratings'!$J$5,IF(AND(O17<='Product Ratings'!$M$6,O17>='Product Ratings'!$L$6),'Product Ratings'!$J$6,IF(AND(O17<='Product Ratings'!$M$7,O17>='Product Ratings'!$L$7),'Product Ratings'!$J$7,IF(AND(O17<='Product Ratings'!$M$8,O17>='Product Ratings'!$L$8),'Product Ratings'!$J$8,IF(O17>='Product Ratings'!$L$9,'Product Ratings'!$J$9))))) -> 5 | U17: =IF(AND(N17<='Product Ratings'!$R$5,N17>='Product Ratings'!$Q$5),'Product Ratings'!$O$5,IF(AND(N17<='Product Ratings'!$R$6,N17>='Product Ratings'!$Q$6),'Product Ratings'!$O$6,IF(AND(N17<='Product Ratings'!$R$7,N17>='Product Ratings'!$Q$7),'Product Ratings'!$O$7,IF(AND(N17<='Product Ratings'!$R$8,N17>='Product Ratings'!$Q$8),'Product Ratings'!$O$8,IF(N17>='Product Ratings'!$Q$9,'Product Ratings'!$O$9))))) -> 3 | V17: =IF(AND(P17<='Product Ratings'!$V$5,P17>='Product Ratings'!$U$5),'Product Ratings'!$S$5,IF(AND(P17<='Product Ratings'!$V$6,P17>='Product Ratings'!$U$6),'Product Ratings'!$S$6,IF(AND(P17<='Product Ratings'!$V$7,P17>='Product Ratings'!$U$7),'Product Ratings'!$S$7,IF(AND(P17<='Product Ratings'!$V$8,P17>='Product Ratings'!$U$8),'Product Ratings'!$S$8,IF(P17>='Product Ratings'!$U$9,'Product Ratings'!$S$9))))) -> 3 | W17: =SUM(R17:V17) -> 13
C18: Widget 12 | D18: 6 | E18: 6423.91 | F18: =E18-(E18*15%) -> 5460.3235 | G18: =E18-F18 -> 963.5865 | H18: =G18/E18 -> 0.15 | I18: 44366 | J18: 44402 | M18: =if(E18=0,0,E18/D18) -> 1070.6517 | N18: =datedif(I18,J18,"D") -> 36 | O18: =if(F18=0,0,F18/D18) -> 910.05392 | P18: 0.18 | R18: =IF(AND(H18<='Product Ratings'!$E$5,H18>='Product Ratings'!$D$5),'Product Ratings'!$C$5,IF(AND(H18<='Product Ratings'!$E$6,H18>='Product Ratings'!$D$6),'Product Ratings'!$C$6,IF(AND(H18<='Product Ratings'!$E$7,H18>='Product Ratings'!$D$7),'Product Ratings'!$C$7,IF(AND(H18<='Product Ratings'!$E$8,H18>='Product Ratings'!$D$8),'Product Ratings'!$C$8,IF(H18>='Product Ratings'!$D$9,'Product Ratings'!$C$9))))) -> 1 | S18: =IF(AND(D18<='Product Ratings'!$I$5,D18>='Product Ratings'!$H$5),'Product Ratings'!$F$5,IF(AND(D18<='Product Ratings'!$I$6,D18>='Product Ratings'!$H$6),'Product Ratings'!$F$6,IF(AND(D18<='Product Ratings'!$I$7,I18>='Product Ratings'!$H$7),'Product Ratings'!$F$7,IF(AND(D18<='Product Ratings'!$I$8,D18>='Product Ratings'!$H$8),'Product Ratings'!$F$8,IF(D18>='Product Ratings'!$H$9,'Product Ratings'!$F$9))))) -> 2 | T18: =IF(AND(O18<='Product Ratings'!$M$5,O18>='Product Ratings'!$L$5),'Product Ratings'!$J$5,IF(AND(O18<='Product Ratings'!$M$6,O18>='Product Ratings'!$L$6),'Product Ratings'!$J$6,IF(AND(O18<='Product Ratings'!$M$7,O18>='Product Ratings'!$L$7),'Product Ratings'!$J$7,IF(AND(O18<='Product Ratings'!$M$8,O18>='Product Ratings'!$L$8),'Product Ratings'!$J$8,IF(O18>='Product Ratings'!$L$9,'Product Ratings'!$J$9))))) -> 1 | U18: =IF(AND(N18<='Product Ratings'!$R$5,N18>='Product Ratings'!$Q$5),'Product Ratings'!$O$5,IF(AND(N18<='Product Ratings'!$R$6,N18>='Product Ratings'!$Q$6),'Product Ratings'!$O$6,IF(AND(N18<='Product Ratings'!$R$7,N18>='Product Ratings'!$Q$7),'Product Ratings'!$O$7,IF(AND(N18<='Product Ratings'!$R$8,N18>='Product Ratings'!$Q$8),'Product Ratings'!$O$8,IF(N18>='Product Ratings'!$Q$9,'Product Ratings'!$O$9))))) -> 3 | V18: =IF(AND(P18<='Product Ratings'!$V$5,P18>='Product Ratings'!$U$5),'Product Ratings'!$S$5,IF(AND(P18<='Product Ratings'!$V$6,P18>='Product Ratings'!$U$6),'Product Ratings'!$S$6,IF(AND(P18<='Product Ratings'!$V$7,P18>='Product Ratings'!$U$7),'Product Ratings'!$S$7,IF(AND(P18<='Product Ratings'!$V$8,P18>='Product Ratings'!$U$8),'Product Ratings'!$S$8,IF(P18>='Product Ratings'!$U$9,'Product Ratings'!$S$9))))) -> 3 | W18: =SUM(R18:V18) -> 10
C19: Widget 13 | D19: 1 | E19: 55.65 | F19: =E19-(E19*11%) -> 49.5285 | G19: =E19-F19 -> 6.1215 | H19: =G19/E19 -> 0.11 | I19: 44367 | J19: 44403 | M19: =if(E19=0,0,E19/D19) -> 55.65 | N19: =datedif(I19,J19,"D") -> 36 | O19: =if(F19=0,0,F19/D19) -> 49.5285 | P19: 0.22 | R19: =IF(AND(H19<='Product Ratings'!$E$5,H19>='Product Ratings'!$D$5),'Product Ratings'!$C$5,IF(AND(H19<='Product Ratings'!$E$6,H19>='Product Ratings'!$D$6),'Product Ratings'!$C$6,IF(AND(H19<='Product Ratings'!$E$7,H19>='Product Ratings'!$D$7),'Product Ratings'!$C$7,IF(AND(H19<='Product Ratings'!$E$8,H19>='Product Ratings'!$D$8),'Product Ratings'!$C$8,IF(H19>='Product Ratings'!$D$9,'Product Ratings'!$C$9))))) -> 1 | S19: =IF(AND(D19<='Product Ratings'!$I$5,D19>='Product Ratings'!$H$5),'Product Ratings'!$F$5,IF(AND(D19<='Product Ratings'!$I$6,D19>='Product Ratings'!$H$6),'Product Ratings'!$F$6,IF(AND(D19<='Product Ratings'!$I$7,I19>='Product Ratings'!$H$7),'Product Ratings'!$F$7,IF(AND(D19<='Product Ratings'!$I$8,D19>='Product Ratings'!$H$8),'Product Ratings'!$F$8,IF(D19>='Product Ratings'!$H$9,'Product Ratings'!$F$9))))) -> 1 | T19: =IF(AND(O19<='Product Ratings'!$M$5,O19>='Product Ratings'!$L$5),'Product Ratings'!$J$5,IF(AND(O19<='Product Ratings'!$M$6,O19>='Product Ratings'!$L$6),'Product Ratings'!$J$6,IF(AND(O19<='Product Ratings'!$M$7,O19>='Product Ratings'!$L$7),'Product Ratings'!$J$7,IF(AND(O19<='Product Ratings'!$M$8,O19>='Product Ratings'!$L$8),'Product Ratings'!$J$8,IF(O19>='Product Ratings'!$L$9,'Product Ratings'!$J$9))))) -> 3 | U19: =IF(AND(N19<='Product Ratings'!$R$5,N19>='Product Ratings'!$Q$5),'Product Ratings'!$O$5,IF(AND(N19<='Product Ratings'!$R$6,N19>='Product Ratings'!$Q$6),'Product Ratings'!$O$6,IF(AND(N19<='Product Ratings'!$R$7,N19>='Product Ratings'!$Q$7),'Product Ratings'!$O$7,IF(AND(N19<='Product Ratings'!$R$8,N19>='Product Ratings'!$Q$8),'Product Ratings'!$O$8,IF(N19>='Product Ratings'!$Q$9,'Product Ratings'!$O$9))))) -> 3 | V19: =IF(AND(P19<='Product Ratings'!$V$5,P19>='Product Ratings'!$U$5),'Product Ratings'!$S$5,IF(AND(P19<='Product Ratings'!$V$6,P19>='Product Ratings'!$U$6),'Product Ratings'!$S$6,IF(AND(P19<='Product Ratings'!$V$7,P19>='Product Ratings'!$U$7),'Product Ratings'!$S$7,IF(AND(P19<='Product Ratings'!$V$8,P19>='Product Ratings'!$U$8),'Product Ratings'!$S$8,IF(P19>='Product Ratings'!$U$9,'Product Ratings'!$S$9))))) -> 3 | W19: =SUM(R19:V19) -> 11
C20: Widget 14 | D20: 2 | E20: 52.17 | F20: =E20-(E20*12%) -> 45.9096 | G20: =E20-F20 -> 6.2604 | H20: =G20/E20 -> 0.12 | I20: 44368 | J20: 44404 | M20: =if(E20=0,0,E20/D20) -> 26.085 | N20: =datedif(I20,J20,"D") -> 36 | O20: =if(F20=0,0,F20/D20) -> 22.9548 | P20: 0.26 | R20: =IF(AND(H20<='Product Ratings'!$E$5,H20>='Product Ratings'!$D$5),'Product Ratings'!$C$5,IF(AND(H20<='Product Ratings'!$E$6,H20>='Product Ratings'!$D$6),'Product Ratings'!$C$6,IF(AND(H20<='Product Ratings'!$E$7,H20>='Product Ratings'!$D$7),'Product Ratings'!$C$7,IF(AND(H20<='Product Ratings'!$E$8,H20>='Product Ratings'!$D$8),'Product Ratings'!$C$8,IF(H20>='Product Ratings'!$D$9,'Product Ratings'!$C$9))))) -> 1 | S20: =IF(AND(D20<='Product Ratings'!$I$5,D20>='Product Ratings'!$H$5),'Product Ratings'!$F$5,IF(AND(D20<='Product Ratings'!$I$6,D20>='Product Ratings'!$H$6),'Product Ratings'!$F$6,IF(AND(D20<='Product Ratings'!$I$7,I20>='Product Ratings'!$H$7),'Product Ratings'!$F$7,IF(AND(D20<='Product Ratings'!$I$8,D20>='Product Ratings'!$H$8),'Product Ratings'!$F$8,IF(D20>='Product Ratings'!$H$9,'Product Ratings'!$F$9))))) -> 1 | T20: =IF(AND(O20<='Product Ratings'!$M$5,O20>='Product Ratings'!$L$5),'Product Ratings'!$J$5,IF(AND(O20<='Product Ratings'!$M$6,O20>='Product Ratings'!$L$6),'Product Ratings'!$J$6,IF(AND(O20<='Product Ratings'!$M$7,O20>='Product Ratings'!$L$7),'Product Ratings'!$J$7,IF(AND(O20<='Product Ratings'!$M$8,O20>='Product Ratings'!$L$8),'Product Ratings'!$J$8,IF(O20>='Product Ratings'!$L$9,'Product Ratings'!$J$9))))) -> 5 | U20: =IF(AND(N20<='Product Ratings'!$R$5,N20>='Product Ratings'!$Q$5),'Product Ratings'!$O$5,IF(AND(N20<='Product Ratings'!$R$6,N20>='Product Ratings'!$Q$6),'Product Ratings'!$O$6,IF(AND(N20<='Product Ratings'!$R$7,N20>='Product Ratings'!$Q$7),'Product Ratings'!$O$7,IF(AND(N20<='Product Ratings'!$R$8,N20>='Product Ratings'!$Q$8),'Product Ratings'!$O$8,IF(N20>='Product Ratings'!$Q$9,'Product Ratings'!$O$9))))) -> 3 | V20: =IF(AND(P20<='Product Ratings'!$V$5,P20>='Product Ratings'!$U$5),'Product Ratings'!$S$5,IF(AND(P20<='Product Ratings'!$V$6,P20>='Product Ratings'!$U$6),'Product Ratings'!$S$6,IF(AND(P20<='Product Ratings'!$V$7,P20>='Product Ratings'!$U$7),'Product Ratings'!$S$7,IF(AND(P20<='Product Ratings'!$V$8,P20>='Product Ratings'!$U$8),'Product Ratings'!$S$8,IF(P20>='Product Ratings'!$U$9,'Product Ratings'!$S$9))))) -> 3 | W20: =SUM(R20:V20) -> 13
C21: Widget 15 | D21: 3 | E21: 434.78 | F21: =E21-(E21*35%) -> 282.607 | G21: =E21-F21 -> 152.173 | H21: =G21/E21 -> 0.35 | I21: 44369 | J21: 44405 | M21: =if(E21=0,0,E21/D21) -> 144.92667 | N21: =datedif(I21,J21,"D") -> 36 | O21: =if(F21=0,0,F21/D21) -> 94.202333 | P21: 0.28 | R21: =IF(AND(H21<='Product Ratings'!$E$5,H21>='Product Ratings'!$D$5),'Product Ratings'!$C$5,IF(AND(H21<='Product Ratings'!$E$6,H21>='Product Ratings'!$D$6),'Product Ratings'!$C$6,IF(AND(H21<='Product Ratings'!$E$7,H21>='Product Ratings'!$D$7),'Product Ratings'!$C$7,IF(AND(H21<='Product Ratings'!$E$8,H21>='Product Ratings'!$D$8),'Product Ratings'!$C$8,IF(H21>='Product Ratings'!$D$9,'Product Ratings'!$C$9))))) -> 2 | S21: =IF(AND(D21<='Product Ratings'!$I$5,D21>='Product Ratings'!$H$5),'Product Ratings'!$F$5,IF(AND(D21<='Product Ratings'!$I$6,D21>='Product Ratings'!$H$6),'Product Ratings'!$F$6,IF(AND(D21<='Product Ratings'!$I$7,I21>='Product Ratings'!$H$7),'Product Ratings'!$F$7,IF(AND(D21<='Product Ratings'!$I$8,D21>='Product Ratings'!$H$8),'Product Ratings'!$F$8,IF(D21>='Product Ratings'!$H$9,'Product Ratings'!$F$9))))) -> 1 | T21: =IF(AND(O21<='Product Ratings'!$M$5,O21>='Product Ratings'!$L$5),'Product Ratings'!$J$5,IF(AND(O21<='Product Ratings'!$M$6,O21>='Product Ratings'!$L$6),'Product Ratings'!$J$6,IF(AND(O21<='Product Ratings'!$M$7,O21>='Product Ratings'!$L$7),'Product Ratings'!$J$7,IF(AND(O21<='Product Ratings'!$M$8,O21>='Product Ratings'!$L$8),'Product Ratings'!$J$8,IF(O21>='Product Ratings'!$L$9,'Product Ratings'!$J$9))))) -> 2 | U21: =IF(AND(N21<='Product Ratings'!$R$5,N21>='Product Ratings'!$Q$5),'Product Ratings'!$O$5,IF(AND(N21<='Product Ratings'!$R$6,N21>='Product Ratings'!$Q$6),'Product Ratings'!$O$6,IF(AND(N21<='Product Ratings'!$R$7,N21>='Product Ratings'!$Q$7),'Product Ratings'!$O$7,IF(AND(N21<='Product Ratings'!$R$8,N21>='Product Ratings'!$Q$8),'Product Ratings'!$O$8,IF(N21>='Product Ratings'!$Q$9,'Product Ratings'!$O$9))))) -> 3 | V21: =IF(AND(P21<='Product Ratings'!$V$5,P21>='Product Ratings'!$U$5),'Product Ratings'!$S$5,IF(AND(P21<='Product Ratings'!$V$6,P21>='Product Ratings'!$U$6),'Product Ratings'!$S$6,IF(AND(P21<='Product Ratings'!$V$7,P21>='Product Ratings'!$U$7),'Product Ratings'!$S$7,IF(AND(P21<='Product Ratings'!$V$8,P21>='Product Ratings'!$U$8),'Product Ratings'!$S$8,IF(P21>='Product Ratings'!$U$9,'Product Ratings'!$S$9))))) -> 3 | W21: =SUM(R21:V21) -> 11
C22: Widget 16 | D22: 4 | E22: 434.78 | F22: =E22-(E22*35%) -> 282.607 | G22: =E22-F22 -> 152.173 | H22: =G22/E22 -> 0.35 | I22: 44370 | J22: 44406 | M22: =if(E22=0,0,E22/D22) -> 108.695 | N22: =datedif(I22,J22,"D") -> 36 | O22: =if(F22=0,0,F22/D22) -> 70.65175 | P22: 0.3 | R22: =IF(AND(H22<='Product Ratings'!$E$5,H22>='Product Ratings'!$D$5),'Product Ratings'!$C$5,IF(AND(H22<='Product Ratings'!$E$6,H22>='Product Ratings'!$D$6),'Product Ratings'!$C$6,IF(AND(H22<='Product Ratings'!$E$7,H22>='Product Ratings'!$D$7),'Product Ratings'!$C$7,IF(AND(H22<='Product Ratings'!$E$8,H22>='Product Ratings'!$D$8),'Product Ratings'!$C$8,IF(H22>='Product Ratings'!$D$9,'Product Ratings'!$C$9))))) -> 2 | S22: =IF(AND(D22<='Product Ratings'!$I$5,D22>='Product Ratings'!$H$5),'Product Ratings'!$F$5,IF(AND(D22<='Product Ratings'!$I$6,D22>='Product Ratings'!$H$6),'Product Ratings'!$F$6,IF(AND(D22<='Product Ratings'!$I$7,I22>='Product Ratings'!$H$7),'Product Ratings'!$F$7,IF(AND(D22<='Product Ratings'!$I$8,D22>='Product Ratings'!$H$8),'Product Ratings'!$F$8,IF(D22>='Product Ratings'!$H$9,'Product Ratings'!$F$9))))) -> 1 | T22: =IF(AND(O22<='Product Ratings'!$M$5,O22>='Product Ratings'!$L$5),'Product Ratings'!$J$5,IF(AND(O22<='Product Ratings'!$M$6,O22>='Product Ratings'!$L$6),'Product Ratings'!$J$6,IF(AND(O22<='Product Ratings'!$M$7,O22>='Product Ratings'!$L$7),'Product Ratings'!$J$7,IF(AND(O22<='Product Ratings'!$M$8,O22>='Product Ratings'!$L$8),'Product Ratings'!$J$8,IF(O22>='Product Ratings'!$L$9,'Product Ratings'!$J$9))))) -> 3 | U22: =IF(AND(N22<='Product Ratings'!$R$5,N22>='Product Ratings'!$Q$5),'Product Ratings'!$O$5,IF(AND(N22<='Product Ratings'!$R$6,N22>='Product Ratings'!$Q$6),'Product Ratings'!$O$6,IF(AND(N22<='Product Ratings'!$R$7,N22>='Product Ratings'!$Q$7),'Product Ratings'!$O$7,IF(AND(N22<='Product Ratings'!$R$8,N22>='Product Ratings'!$Q$8),'Product Ratings'!$O$8,IF(N22>='Product Ratings'!$Q$9,'Product Ratings'!$O$9))))) -> 3 | V22: =IF(AND(P22<='Product Ratings'!$V$5,P22>='Product Ratings'!$U$5),'Product Ratings'!$S$5,IF(AND(P22<='Product Ratings'!$V$6,P22>='Product Ratings'!$U$6),'Product Ratings'!$S$6,IF(AND(P22<='Product Ratings'!$V$7,P22>='Product Ratings'!$U$7),'Product Ratings'!$S$7,IF(AND(P22<='Product Ratings'!$V$8,P22>='Product Ratings'!$U$8),'Product Ratings'!$S$8,IF(P22>='Product Ratings'!$U$9,'Product Ratings'!$S$9))))) -> 3 | W22: =SUM(R22:V22) -> 12
C23: Widget 17 | D23: 5 | E23: 41.39 | F23: =E23-(E23*35%) -> 26.9035 | G23: =E23-F23 -> 14.4865 | H23: =G23/E23 -> 0.35 | I23: 44371 | J23: 44407 | M23: =if(E23=0,0,E23/D23) -> 8.278 | N23: =datedif(I23,J23,"D") -> 36 | O23: =if(F23=0,0,F23/D23) -> 5.3807 | P23: 0.31 | R23: =IF(AND(H23<='Product Ratings'!$E$5,H23>='Product Ratings'!$D$5),'Product Ratings'!$C$5,IF(AND(H23<='Product Ratings'!$E$6,H23>='Product Ratings'!$D$6),'Product Ratings'!$C$6,IF(AND(H23<='Product Ratings'!$E$7,H23>='Product Ratings'!$D$7),'Product Ratings'!$C$7,IF(AND(H23<='Product Ratings'!$E$8,H23>='Product Ratings'!$D$8),'Product Ratings'!$C$8,IF(H23>='Product Ratings'!$D$9,'Product Ratings'!$C$9))))) -> 2 | S23: =IF(AND(D23<='Product Ratings'!$I$5,D23>='Product Ratings'!$H$5),'Product Ratings'!$F$5,IF(AND(D23<='Product Ratings'!$I$6,D23>='Product Ratings'!$H$6),'Product Ratings'!$F$6,IF(AND(D23<='Product Ratings'!$I$7,I23>='Product Ratings'!$H$7),'Product Ratings'!$F$7,IF(AND(D23<='Product Ratings'!$I$8,D23>='Product Ratings'!$H$8),'Product Ratings'!$F$8,IF(D23>='Product Ratings'!$H$9,'Product Ratings'!$F$9))))) -> 1 | T23: =IF(AND(O23<='Product Ratings'!$M$5,O23>='Product Ratings'!$L$5),'Product Ratings'!$J$5,IF(AND(O23<='Product Ratings'!$M$6,O23>='Product Ratings'!$L$6),'Product Ratings'!$J$6,IF(AND(O23<='Product Ratings'!$M$7,O23>='Product Ratings'!$L$7),'Product Ratings'!$J$7,IF(AND(O23<='Product Ratings'!$M$8,O23>='Product Ratings'!$L$8),'Product Ratings'!$J$8,IF(O23>='Product Ratings'!$L$9,'Product Ratings'!$J$9))))) -> 5 | U23: =IF(AND(N23<='Product Ratings'!$R$5,N23>='Product Ratings'!$Q$5),'Product Ratings'!$O$5,IF(AND(N23<='Product Ratings'!$R$6,N23>='Product Ratings'!$Q$6),'Product Ratings'!$O$6,IF(AND(N23<='Product Ratings'!$R$7,N23>='Product Ratings'!$Q$7),'Product Ratings'!$O$7,IF(AND(N23<='Product Ratings'!$R$8,N23>='Product Ratings'!$Q$8),'Product Ratings'!$O$8,IF(N23>='Product Ratings'!$Q$9,'Product Ratings'!$O$9))))) -> 3 | V23: =IF(AND(P23<='Product Ratings'!$V$5,P23>='Product Ratings'!$U$5),'Product Ratings'!$S$5,IF(AND(P23<='Product Ratings'!$V$6,P23>='Product Ratings'!$U$6),'Product Ratings'!$S$6,IF(AND(P23<='Product Ratings'!$V$7,P23>='Product Ratings'!$U$7),'Product Ratings'!$S$7,IF(AND(P23<='Product Ratings'!$V$8,P23>='Product Ratings'!$U$8),'Product Ratings'!$S$8,IF(P23>='Product Ratings'!$U$9,'Product Ratings'!$S$9))))) -> 3 | W23: =SUM(R23:V23) -> 14
C24: Widget 18 | D24: 6 | E24: 260.87 | F24: =E24-(E24*35%) -> 169.5655 | G24: =E24-F24 -> 91.3045 | H24: =G24/E24 -> 0.35 | I24: 44372 | J24: 44408 | M24: =if(E24=0,0,E24/D24) -> 43.478333 | N24: =datedif(I24,J24,"D") -> 36 | O24: =if(F24=0,0,F24/D24) -> 28.260917 | P24: 0.32 | R24: =IF(AND(H24<='Product Ratings'!$E$5,H24>='Product Ratings'!$D$5),'Product Ratings'!$C$5,IF(AND(H24<='Product Ratings'!$E$6,H24>='Product Ratings'!$D$6),'Product Ratings'!$C$6,IF(AND(H24<='Product Ratings'!$E$7,H24>='Product Ratings'!$D$7),'Product Ratings'!$C$7,IF(AND(H24<='Product Ratings'!$E$8,H24>='Product Ratings'!$D$8),'Product Ratings'!$C$8,IF(H24>='Product Ratings'!$D$9,'Product Ratings'!$C$9))))) -> 2 | S24: =IF(AND(D24<='Product Ratings'!$I$5,D24>='Product Ratings'!$H$5),'Product Ratings'!$F$5,IF(AND(D24<='Product Ratings'!$I$6,D24>='Product Ratings'!$H$6),'Product Ratings'!$F$6,IF(AND(D24<='Product Ratings'!$I$7,I24>='Product Ratings'!$H$7),'Product Ratings'!$F$7,IF(AND(D24<='Product Ratings'!$I$8,D24>='Product Ratings'!$H$8),'Product Ratings'!$F$8,IF(D24>='Product Ratings'!$H$9,'Product Ratings'!$F$9))))) -> 2 | T24: =IF(AND(O24<='Product Ratings'!$M$5,O24>='Product Ratings'!$L$5),'Product Ratings'!$J$5,IF(AND(O24<='Product Ratings'!$M$6,O24>='Product Ratings'!$L$6),'Product Ratings'!$J$6,IF(AND(O24<='Product Ratings'!$M$7,O24>='Product Ratings'!$L$7),'Product Ratings'!$J$7,IF(AND(O24<='Product Ratings'!$M$8,O24>='Product Ratings'!$L$8),'Product Ratings'!$J$8,IF(O24>='Product Ratings'!$L$9,'Product Ratings'!$J$9))))) -> 4 | U24: =IF(AND(N24<='Product Ratings'!$R$5,N24>='Product Ratings'!$Q$5),'Product Ratings'!$O$5,IF(AND(N24<='Product Ratings'!$R$6,N24>='Product Ratings'!$Q$6),'Product Ratings'!$O$6,IF(AND(N24<='Product Ratings'!$R$7,N24>='Product Ratings'!$Q$7),'Product Ratings'!$O$7,IF(AND(N24<='Product Ratings'!$R$8,N24>='Product Ratings'!$Q$8),'Product Ratings'!$O$8,IF(N24>='Product Ratings'!$Q$9,'Product Ratings'!$O$9))))) -> 3 | V24: =IF(AND(P24<='Product Ratings'!$V$5,P24>='Product Ratings'!$U$5),'Product Ratings'!$S$5,IF(AND(P24<='Product Ratings'!$V$6,P24>='Product Ratings'!$U$6),'Product Ratings'!$S$6,IF(AND(P24<='Product Ratings'!$V$7,P24>='Product Ratings'!$U$7),'Product Ratings'!$S$7,IF(AND(P24<='Product Ratings'!$V$8,P24>='Product Ratings'!$U$8),'Product Ratings'!$S$8,IF(P24>='Product Ratings'!$U$9,'Product Ratings'!$S$9))))) -> 3 | W24: =SUM(R24:V24) -> 14
C25: Widget 19 | D25: 1 | E25: 25.22 | F25: =E25-(E25*35%) -> 16.393 | G25: =E25-F25 -> 8.827 | H25: =G25/E25 -> 0.35 | I25: 44373 | J25: 44409 | M25: =if(E25=0,0,E25/D25) -> 25.22 | N25: =datedif(I25,J25,"D") -> 36 | O25: =if(F25=0,0,F25/D25) -> 16.393 | P25: 0.33 | R25: =IF(AND(H25<='Product Ratings'!$E$5,H25>='Product Ratings'!$D$5),'Product Ratings'!$C$5,IF(AND(H25<='Product Ratings'!$E$6,H25>='Product Ratings'!$D$6),'Product Ratings'!$C$6,IF(AND(H25<='Product Ratings'!$E$7,H25>='Product Ratings'!$D$7),'Product Ratings'!$C$7,IF(AND(H25<='Product Ratings'!$E$8,H25>='Product Ratings'!$D$8),'Product Ratings'!$C$8,IF(H25>='Product Ratings'!$D$9,'Product Ratings'!$C$9))))) -> 2 | S25: =IF(AND(D25<='Product Ratings'!$I$5,D25>='Product Ratings'!$H$5),'Product Ratings'!$F$5,IF(AND(D25<='Product Ratings'!$I$6,D25>='Product Ratings'!$H$6),'Product Ratings'!$F$6,IF(AND(D25<='Product Ratings'!$I$7,I25>='Product Ratings'!$H$7),'Product Ratings'!$F$7,IF(AND(D25<='Product Ratings'!$I$8,D25>='Product Ratings'!$H$8),'Product Ratings'!$F$8,IF(D25>='Product Ratings'!$H$9,'Product Ratings'!$F$9))))) -> 1 | T25: =IF(AND(O25<='Product Ratings'!$M$5,O25>='Product Ratings'!$L$5),'Product Ratings'!$J$5,IF(AND(O25<='Product Ratings'!$M$6,O25>='Product Ratings'!$L$6),'Product Ratings'!$J$6,IF(AND(O25<='Product Ratings'!$M$7,O25>='Product Ratings'!$L$7),'Product Ratings'!$J$7,IF(AND(O25<='Product Ratings'!$M$8,O25>='Product Ratings'!$L$8),'Product Ratings'!$J$8,IF(O25>='Product Ratings'!$L$9,'Product Ratings'!$J$9))))) -> 5 | U25: =IF(AND(N25<='Product Ratings'!$R$5,N25>='Product Ratings'!$Q$5),'Product Ratings'!$O$5,IF(AND(N25<='Product Ratings'!$R$6,N25>='Product Ratings'!$Q$6),'Product Ratings'!$O$6,IF(AND(N25<='Product Ratings'!$R$7,N25>='Product Ratings'!$Q$7),'Product Ratings'!$O$7,IF(AND(N25<='Product Ratings'!$R$8,N25>='Product Ratings'!$Q$8),'Product Ratings'!$O$8,IF(N25>='Product Ratings'!$Q$9,'Product Ratings'!$O$9))))) -> 3 | V25: =IF(AND(P25<='Product Ratings'!$V$5,P25>='Product Ratings'!$U$5),'Product Ratings'!$S$5,IF(AND(P25<='Product Ratings'!$V$6,P25>='Product Ratings'!$U$6),'Product Ratings'!$S$6,IF(AND(P25<='Product Ratings'!$V$7,P25>='Product Ratings'!$U$7),'Product Ratings'!$S$7,IF(AND(P25<='Product Ratings'!$V$8,P25>='Product Ratings'!$U$8),'Product Ratings'!$S$8,IF(P25>='Product Ratings'!$U$9,'Product Ratings'!$S$9))))) -> 3 | W25: =SUM(R25:V25) -> 14
C26: Widget 20 | D26: 2 | E26: 219.74 | F26: =E26-(E26*35%) -> 142.831 | G26: =E26-F26 -> 76.909 | H26: =G26/E26 -> 0.35 | I26: 44374 | J26: 44410 | M26: =if(E26=0,0,E26/D26) -> 109.87 | N26: =datedif(I26,J26,"D") -> 36 | O26: =if(F26=0,0,F26/D26) -> 71.4155 | P26: 0.34 | R26: =IF(AND(H26<='Product Ratings'!$E$5,H26>='Product Ratings'!$D$5),'Product Ratings'!$C$5,IF(AND(H26<='Product Ratings'!$E$6,H26>='Product Ratings'!$D$6),'Product Ratings'!$C$6,IF(AND(H26<='Product Ratings'!$E$7,H26>='Product Ratings'!$D$7),'Product Ratings'!$C$7,IF(AND(H26<='Product Ratings'!$E$8,H26>='Product Ratings'!$D$8),'Product Ratings'!$C$8,IF(H26>='Product Ratings'!$D$9,'Product Ratings'!$C$9))))) -> 2 | S26: =IF(AND(D26<='Product Ratings'!$I$5,D26>='Product Ratings'!$H$5),'Product Ratings'!$F$5,IF(AND(D26<='Product Ratings'!$I$6,D26>='Product Ratings'!$H$6),'Product Ratings'!$F$6,IF(AND(D26<='Product Ratings'!$I$7,I26>='Product Ratings'!$H$7),'Product Ratings'!$F$7,IF(AND(D26<='Product Ratings'!$I$8,D26>='Product Ratings'!$H$8),'Product Ratings'!$F$8,IF(D26>='Product Ratings'!$H$9,'Product Ratings'!$F$9))))) -> 1 | T26: =IF(AND(O26<='Product Ratings'!$M$5,O26>='Product Ratings'!$L$5),'Product Ratings'!$J$5,IF(AND(O26<='Product Ratings'!$M$6,O26>='Product Ratings'!$L$6),'Product Ratings'!$J$6,IF(AND(O26<='Product Ratings'!$M$7,O26>='Product Ratings'!$L$7),'Product Ratings'!$J$7,IF(AND(O26<='Product Ratings'!$M$8,O26>='Product Ratings'!$L$8),'Product Ratings'!$J$8,IF(O26>='Product Ratings'!$L$9,'Product Ratings'!$J$9))))) -> 3 | U26: =IF(AND(N26<='Product Ratings'!$R$5,N26>='Product Ratings'!$Q$5),'Product Ratings'!$O$5,IF(AND(N26<='Product Ratings'!$R$6,N26>='Product Ratings'!$Q$6),'Product Ratings'!$O$6,IF(AND(N26<='Product Ratings'!$R$7,N26>='Product Ratings'!$Q$7),'Product Ratings'!$O$7,IF(AND(N26<='Product Ratings'!$R$8,N26>='Product Ratings'!$Q$8),'Product Ratings'!$O$8,IF(N26>='Product Ratings'!$Q$9,'Product Ratings'!$O$9))))) -> 3 | V26: =IF(AND(P26<='Product Ratings'!$V$5,P26>='Product Ratings'!$U$5),'Product Ratings'!$S$5,IF(AND(P26<='Product Ratings'!$V$6,P26>='Product Ratings'!$U$6),'Product Ratings'!$S$6,IF(AND(P26<='Product Ratings'!$V$7,P26>='Product Ratings'!$U$7),'Product Ratings'!$S$7,IF(AND(P26<='Product Ratings'!$V$8,P26>='Product Ratings'!$U$8),'Product Ratings'!$S$8,IF(P26>='Product Ratings'!$U$9,'Product Ratings'!$S$9))))) -> 4 | W26: =SUM(R26:V26) -> 13
C27: Widget 21 | D27: 3 | E27: 217.39 | F27: =E27-(E27*35%) -> 141.3035 | G27: =E27-F27 -> 76.0865 | H27: =G27/E27 -> 0.35 | I27: 44375 | J27: 44411 | M27: =if(E27=0,0,E27/D27) -> 72.463333 | N27: =datedif(I27,J27,"D") -> 36 | O27: =if(F27=0,0,F27/D27) -> 47.101167 | P27: 0.35 | R27: =IF(AND(H27<='Product Ratings'!$E$5,H27>='Product Ratings'!$D$5),'Product Ratings'!$C$5,IF(AND(H27<='Product Ratings'!$E$6,H27>='Product Ratings'!$D$6),'Product Ratings'!$C$6,IF(AND(H27<='Product Ratings'!$E$7,H27>='Product Ratings'!$D$7),'Product Ratings'!$C$7,IF(AND(H27<='Product Ratings'!$E$8,H27>='Product Ratings'!$D$8),'Product Ratings'!$C$8,IF(H27>='Product Ratings'!$D$9,'Product Ratings'!$C$9))))) -> 2 | S27: =IF(AND(D27<='Product Ratings'!$I$5,D27>='Product Ratings'!$H$5),'Product Ratings'!$F$5,IF(AND(D27<='Product Ratings'!$I$6,D27>='Product Ratings'!$H$6),'Product Ratings'!$F$6,IF(AND(D27<='Product Ratings'!$I$7,I27>='Product Ratings'!$H$7),'Product Ratings'!$F$7,IF(AND(D27<='Product Ratings'!$I$8,D27>='Product Ratings'!$H$8),'Product Ratings'!$F$8,IF(D27>='Product Ratings'!$H$9,'Product Ratings'!$F$9))))) -> 1 | T27: =IF(AND(O27<='Product Ratings'!$M$5,O27>='Product Ratings'!$L$5),'Product Ratings'!$J$5,IF(AND(O27<='Product Ratings'!$M$6,O27>='Product Ratings'!$L$6),'Product Ratings'!$J$6,IF(AND(O27<='Product Ratings'!$M$7,O27>='Product Ratings'!$L$7),'Product Ratings'!$J$7,IF(AND(O27<='Product Ratings'!$M$8,O27>='Product Ratings'!$L$8),'Product Ratings'!$J$8,IF(O27>='Product Ratings'!$L$9,'Product Ratings'!$J$9))))) -> 3 | U27: =IF(AND(N27<='Product Ratings'!$R$5,N27>='Product Ratings'!$Q$5),'Product Ratings'!$O$5,IF(AND(N27<='Product Ratings'!$R$6,N27>='Product Ratings'!$Q$6),'Product Ratings'!$O$6,IF(AND(N27<='Product Ratings'!$R$7,N27>='Product Ratings'!$Q$7),'Product Ratings'!$O$7,IF(AND(N27<='Product Ratings'!$R$8,N27>='Product Ratings'!$Q$8),'Product Ratings'!$O$8,IF(N27>='Product Ratings'!$Q$9,'Product Ratings'!$O$9))))) -> 3 | V27: =IF(AND(P27<='Product Ratings'!$V$5,P27>='Product Ratings'!$U$5),'Product Ratings'!$S$5,IF(AND(P27<='Product Ratings'!$V$6,P27>='Product Ratings'!$U$6),'Product Ratings'!$S$6,IF(AND(P27<='Product Ratings'!$V$7,P27>='Product Ratings'!$U$7),'Product Ratings'!$S$7,IF(AND(P27<='Product Ratings'!$V$8,P27>='Product Ratings'!$U$8),'Product Ratings'!$S$8,IF(P27>='Product Ratings'!$U$9,'Product Ratings'!$S$9))))) -> 4 | W27: =SUM(R27:V27) -> 13
C28: Widget 22 | D28: 4 | E28: 19.13 | F28: =E28-(E28*35%) -> 12.4345 | G28: =E28-F28 -> 6.6955 | H28: =G28/E28 -> 0.35 | I28: 44376 | J28: 44412 | M28: =if(E28=0,0,E28/D28) -> 4.7825 | N28: =datedif(I28,J28,"D") -> 36 | O28: =if(F28=0,0,F28/D28) -> 3.108625 | P28: 0.45 | R28: =IF(AND(H28<='Product Ratings'!$E$5,H28>='Product Ratings'!$D$5),'Product Ratings'!$C$5,IF(AND(H28<='Product Ratings'!$E$6,H28>='Product Ratings'!$D$6),'Product Ratings'!$C$6,IF(AND(H28<='Product Ratings'!$E$7,H28>='Product Ratings'!$D$7),'Product Ratings'!$C$7,IF(AND(H28<='Product Ratings'!$E$8,H28>='Product Ratings'!$D$8),'Product Ratings'!$C$8,IF(H28>='Product Ratings'!$D$9,'Product Ratings'!$C$9))))) -> 2 | S28: =IF(AND(D28<='Product Ratings'!$I$5,D28>='Product Ratings'!$H$5),'Product Ratings'!$F$5,IF(AND(D28<='Product Ratings'!$I$6,D28>='Product Ratings'!$H$6),'Product Ratings'!$F$6,IF(AND(D28<='Product Ratings'!$I$7,I28>='Product Ratings'!$H$7),'Product Ratings'!$F$7,IF(AND(D28<='Product Ratings'!$I$8,D28>='Product Ratings'!$H$8),'Product Ratings'!$F$8,IF(D28>='Product Ratings'!$H$9,'Product Ratings'!$F$9))))) -> 1 | T28: =IF(AND(O28<='Product Ratings'!$M$5,O28>='Product Ratings'!$L$5),'Product Ratings'!$J$5,IF(AND(O28<='Product Ratings'!$M$6,O28>='Product Ratings'!$L$6),'Product Ratings'!$J$6,IF(AND(O28<='Product Ratings'!$M$7,O28>='Product Ratings'!$L$7),'Product Ratings'!$J$7,IF(AND(O28<='Product Ratings'!$M$8,O28>='Product Ratings'!$L$8),'Product Ratings'!$J$8,IF(O28>='Product Ratings'!$L$9,'Product Ratings'!$J$9))))) -> 5 | U28: =IF(AND(N28<='Product Ratings'!$R$5,N28>='Product Ratings'!$Q$5),'Product Ratings'!$O$5,IF(AND(N28<='Product Ratings'!$R$6,N28>='Product Ratings'!$Q$6),'Product Ratings'!$O$6,IF(AND(N28<='Product Ratings'!$R$7,N28>='Product Ratings'!$Q$7),'Product Ratings'!$O$7,IF(AND(N28<='Product Ratings'!$R$8,N28>='Product Ratings'!$Q$8),'Product Ratings'!$O$8,IF(N28>='Product Ratings'!$Q$9,'Product Ratings'!$O$9))))) -> 3 | V28: =IF(AND(P28<='Product Ratings'!$V$5,P28>='Product Ratings'!$U$5),'Product Ratings'!$S$5,IF(AND(P28<='Product Ratings'!$V$6,P28>='Product Ratings'!$U$6),'Product Ratings'!$S$6,IF(AND(P28<='Product Ratings'!$V$7,P28>='Product Ratings'!$U$7),'Product Ratings'!$S$7,IF(AND(P28<='Product Ratings'!$V$8,P28>='Product Ratings'!$U$8),'Product Ratings'!$S$8,IF(P28>='Product Ratings'!$U$9,'Product Ratings'!$S$9))))) -> 4 | W28: =SUM(R28:V28) -> 15
C29: Widget 23 | D29: 5 | E29: 173.91 | F29: =E29-(E29*35%) -> 113.0415 | G29: =E29-F29 -> 60.8685 | H29: =G29/E29 -> 0.35 | I29: 44377 | J29: 44413 | M29: =if(E29=0,0,E29/D29) -> 34.782 | N29: =datedif(I29,J29,"D") -> 36 | O29: =if(F29=0,0,F29/D29) -> 22.6083 | P29: 0.46 | R29: =IF(AND(H29<='Product Ratings'!$E$5,H29>='Product Ratings'!$D$5),'Product Ratings'!$C$5,IF(AND(H29<='Product Ratings'!$E$6,H29>='Product Ratings'!$D$6),'Product Ratings'!$C$6,IF(AND(H29<='Product Ratings'!$E$7,H29>='Product Ratings'!$D$7),'Product Ratings'!$C$7,IF(AND(H29<='Product Ratings'!$E$8,H29>='Product Ratings'!$D$8),'Product Ratings'!$C$8,IF(H29>='Product Ratings'!$D$9,'Product Ratings'!$C$9))))) -> 2 | S29: =IF(AND(D29<='Product Ratings'!$I$5,D29>='Product Ratings'!$H$5),'Product Ratings'!$F$5,IF(AND(D29<='Product Ratings'!$I$6,D29>='Product Ratings'!$H$6),'Product Ratings'!$F$6,IF(AND(D29<='Product Ratings'!$I$7,I29>='Product Ratings'!$H$7),'Product Ratings'!$F$7,IF(AND(D29<='Product Ratings'!$I$8,D29>='Product Ratings'!$H$8),'Product Ratings'!$F$8,IF(D29>='Product Ratings'!$H$9,'Product Ratings'!$F$9))))) -> 1 | T29: =IF(AND(O29<='Product Ratings'!$M$5,O29>='Product Ratings'!$L$5),'Product Ratings'!$J$5,IF(AND(O29<='Product Ratings'!$M$6,O29>='Product Ratings'!$L$6),'Product Ratings'!$J$6,IF(AND(O29<='Product Ratings'!$M$7,O29>='Product Ratings'!$L$7),'Product Ratings'!$J$7,IF(AND(O29<='Product Ratings'!$M$8,O29>='Product Ratings'!$L$8),'Product Ratings'!$J$8,IF(O29>='Product Ratings'!$L$9,'Product Ratings'!$J$9))))) -> 5 | U29: =IF(AND(N29<='Product Ratings'!$R$5,N29>='Product Ratings'!$Q$5),'Product Ratings'!$O$5,IF(AND(N29<='Product Ratings'!$R$6,N29>='Product Ratings'!$Q$6),'Product Ratings'!$O$6,IF(AND(N29<='Product Ratings'!$R$7,N29>='Product Ratings'!$Q$7),'Product Ratings'!$O$7,IF(AND(N29<='Product Ratings'!$R$8,N29>='Product Ratings'!$Q$8),'Product Ratings'!$O$8,IF(N29>='Product Ratings'!$Q$9,'Product Ratings'!$O$9))))) -> 3 | V29: =IF(AND(P29<='Product Ratings'!$V$5,P29>='Product Ratings'!$U$5),'Product Ratings'!$S$5,IF(AND(P29<='Product Ratings'!$V$6,P29>='Product Ratings'!$U$6),'Product Ratings'!$S$6,IF(AND(P29<='Product Ratings'!$V$7,P29>='Product Ratings'!$U$7),'Product Ratings'!$S$7,IF(AND(P29<='Product Ratings'!$V$8,P29>='Product Ratings'!$U$8),'Product Ratings'!$S$8,IF(P29>='Product Ratings'!$U$9,'Product Ratings'!$S$9))))) -> 4 | W29: =SUM(R29:V29) -> 15
