Workbook

Sheet Supplier 1 Inputs
F3: Total Days Elapsed From Order to Retail | K3: =F6+K5+F13 -> 154 | L3: =F6+L5+F13 -> 149 | M3: =F6+M5+F13 -> 144
U4: Stock Turn Days | W4: Shipment % | AO4: Yes | AP4: =K6 -> Sea | AQ4: =W5 -> SkyRockets
H5: Refrigerated Surcharge | J5: Container Size | K5: 25 | L5: 20 | M5: 15 | N5: Total Shipping Days | W5: SkyRockets | X5: Steady Eddy | Y5: Slow Burn | AO5: No | AP5: =L6 -> Air | AQ5: =X5 -> Steady Eddy
D6: Manufacture Days | F6: 120 | K6: Sea | L6: Air | M6: Express | AP6: =M6 -> Express | AQ6: =Y5 -> Slow Burn
D7: Order Deposit % | F7: 0.6 | H7: 2500 | J7: 10 ft | K7: 3500 | L7: 5000 | M7: 6500 | U7: 30 | W7: 0.4 | X7: 0.2 | Y7: 0.1
D8: Interest Cover % | F8: 0.06 | H8: 4000 | J8: 20 ft | K8: 8000 | L8: 10000 | M8: 11500 | U8: 60 | W8: 0.25 | X8: 0.3 | Y8: 0.3
D9: Currency Movement % | F9: 0.1 | H9: 6000 | J9: 40 ft | K9: 12000 | L9: 14000 | M9: 15500 | U9: 90 | W9: 0.2 | X9: 0.2 | Y9: 0.4
D10: Order Balance Due Days | F10: 91 | U10: 120 | W10: 0.15 | X10: 0.3 | Y10: 0.2
H12: Deposit Pmts | J12: =J54 -> 64585.8 | K12: =K54 -> 23379.6 | L12: =L54 -> 56586.6 | M12: =M54 -> 33959.4 | N12: =N54 -> 47503.8 | O12: =O54 -> 60406.2 | P12: =P54 -> 17821.8 | Q12: =Q54 -> 17206.2 | ... U12: =U54 -> 8024.4 | W12: =100%-sum(W7:W10) -> 0 | X12: =100%-sum(X7:X10) -> 0 | Y12: =100%-sum(Y7:Y10) -> 0
D13: Pre-Retail Prep Days | F13: 9 | H13: Balance Pmts | J13: =J75 -> 0 | K13: =K75 -> 0 | L13: =L75 -> 0 | M13: =M75 -> 44798.625 | N13: =N75 -> 16216.783 | O13: =O75 -> 39250.142 | P13: =P75 -> 23555.246 | Q13: =Q75 -> 32950.043 | ... U13: =U75 -> 32683.273 | W13: Up to | X13: Up to | Y13: Up to | AA13: =U4 -> Stock Turn Days
H15: Total Import Pmts | J15: =sum(J12:J13) -> 64585.8 | K15: =sum(K12:K13) -> 23379.6 | L15: =sum(L12:L13) -> 56586.6 | M15: =sum(M12:M13) -> 78758.025 | N15: =sum(N12:N13) -> 63720.583 | O15: =sum(O12:O13) -> 99656.342 | P15: =sum(P12:P13) -> 41377.046 | Q15: =sum(Q12:Q13) -> 50156.243 | ... U15: =sum(U12:U13) -> 40707.673 | W15: =U8 -> 60 | X15: =U9 -> 90 | Y15: =U10 -> 120
H17: Projected Sales
D19: Stock Items | F19: Unit Cost | H19: Item Popularity | J19: Jan | K19: Feb | L19: Mar | M19: Apr | N19: May | O19: Jun | P19: Jul | Q19: Aug | R19: Sep | S19: Oct | T19: Nov | U19: Dec | W19: New Stock Retail Markup % | X19: Std Retail Markup % | Y19: Runout Stock Markup % | AA19: New Stock Retail Price | AB19: Std Retail Price | AC19: Runout Stock Price
D21: Stock 1 | F21: 145 | H21: SkyRockets | J21: 34 | K21: 12 | L21: 35 | M21: 24 | N21: 12 | O21: 46 | P21: 14 | Q21: 12 | R21: 36 | S21: 4 | T21: 2 | U21: 16 | W21: 1.85 | X21: 1.52 | Y21: 1.22 | AA21: =(F21*W21)+F21 -> 413.25 | AB21: =(F21*X21)+F21 -> 365.4 | AC21: =(F21*Y21)+F21 -> 321.9
D22: Stock 2 | F22: 146 | H22: Steady Eddy | J22: 33 | K22: 14 | L22: 35 | M22: 23 | N22: 14 | O22: 45 | P22: 13 | R22: 25 | S22: 3 | U22: 15 | W22: 1.85 | X22: 1.52 | Y22: 1.22 | AA22: =(F22*W22)+F22 -> 416.1 | AB22: =(F22*X22)+F22 -> 367.92 | AC22: =(F22*Y22)+F22 -> 324.12
D23: Stock 3 | F23: 147 | H23: Slow Burn | J23: 35 | L23: 34 | N23: 16 | O23: 44 | P23: 15 | S23: 5 | W23: 1.85 | X23: 1.52 | Y23: 1.22 | AA23: =(F23*W23)+F23 -> 418.95 | AB23: =(F23*X23)+F23 -> 370.44 | AC23: =(F23*Y23)+F23 -> 326.34
D24: Stock 4 | F24: 148 | H24: Steady Eddy | J24: 38 | L24: 39 | N24: 18 | O24: 49 | S24: 8 | T24: 18 | W24: 1.85 | X24: 1.52 | Y24: 1.22 | AA24: =(F24*W24)+F24 -> 421.8 | AB24: =(F24*X24)+F24 -> 372.96 | AC24: =(F24*Y24)+F24 -> 328.56
D25: Stock 5 | F25: 149 | H25: SkyRockets | J25: 36 | L25: 38 | M25: 26 | N25: 11 | O25: 48 | Q25: 11 | R25: 28 | S25: 6 | T25: 17 | W25: 1.85 | X25: 1.52 | Y25: 1.22 | AA25: =(F25*W25)+F25 -> 424.65 | AB25: =(F25*X25)+F25 -> 375.48 | AC25: =(F25*Y25)+F25 -> 330.78
D26: Stock 6 | F26: 150 | H26: Slow Burn | J26: 35 | K26: 13 | M26: 25 | O26: 47 | Q26: 13 | R26: 37 | T26: 13 | U26: 17 | W26: 1.85 | X26: 1.52 | Y26: 1.22 | AA26: =(F26*W26)+F26 -> 427.5 | AB26: =(F26*X26)+F26 -> 378 | AC26: =(F26*Y26)+F26 -> 333
D27: Stock 7 | F27: 151 | H27: SkyRockets | J27: 34 | K27: 15 | M27: 24 | Q27: 15 | R27: 33 | T27: 15 | U27: 3 | W27: 1.85 | X27: 1.52 | Y27: 1.22 | AA27: =(F27*W27)+F27 -> 430.35 | AB27: =(F27*X27)+F27 -> 380.52 | AC27: =(F27*Y27)+F27 -> 335.22
D28: Stock 8 | F28: 152 | H28: SkyRockets | J28: 37 | K28: 17 | M28: 27 | N28: 37 | Q28: 17 | S28: 27 | T28: 17 | U28: 5 | W28: 1.85 | X28: 1.52 | Y28: 1.22 | AA28: =(F28*W28)+F28 -> 433.2 | AB28: =(F28*X28)+F28 -> 383.04 | AC28: =(F28*Y28)+F28 -> 337.44
D29: Stock 9 | F29: 153 | H29: Steady Eddy | J29: 34 | K29: 12 | L29: 37 | M29: 24 | N29: 32 | Q29: 12 | S29: 24 | T29: 12 | U29: 7 | W29: 1.85 | X29: 1.52 | Y29: 1.22 | AA29: =(F29*W29)+F29 -> 436.05 | AB29: =(F29*X29)+F29 -> 385.56 | AC29: =(F29*Y29)+F29 -> 339.66
D30: Stock 10 | F30: 154 | H30: Steady Eddy | J30: 33 | K30: 14 | L30: 31 | M30: 23 | N30: 34 | O30: 31 | Q30: 14 | R30: 41 | S30: 23 | U30: 1 | W30: 1.85 | X30: 1.52 | Y30: 1.22 | AA30: =(F30*W30)+F30 -> 438.9 | AB30: =(F30*X30)+F30 -> 388.08 | AC30: =(F30*Y30)+F30 -> 341.88
D31: Stock 11 | F31: 155 | H31: Steady Eddy | J31: 35 | K31: 16 | L31: 35 | N31: 36 | O31: 35 | P31: 15 | Q31: 16 | R31: 55 | S31: 25 | U31: 5 | W31: 1.85 | X31: 1.52 | Y31: 1.22 | AA31: =(F31*W31)+F31 -> 441.75 | AB31: =(F31*X31)+F31 -> 390.6 | AC31: =(F31*Y31)+F31 -> 344.1
D32: Stock 12 | F32: 156 | H32: Steady Eddy | J32: 38 | K32: 18 | L32: 39 | N32: 38 | O32: 39 | P32: 18 | Q32: 18 | R32: 69 | S32: 28 | T32: 18 | W32: 1.85 | X32: 1.52 | Y32: 1.22 | AA32: =(F32*W32)+F32 -> 444.6 | AB32: =(F32*X32)+F32 -> 393.12 | AC32: =(F32*Y32)+F32 -> 346.32
D33: Stock 13 | F33: 157 | H33: Steady Eddy | J33: 36 | K33: 13 | L33: 38 | N33: 33 | O33: 38 | P33: 16 | Q33: 13 | S33: 26 | T33: 13 | W33: 1.85 | X33: 1.52 | Y33: 1.22 | AA33: =(F33*W33)+F33 -> 447.45 | AB33: =(F33*X33)+F33 -> 395.64 | AC33: =(F33*Y33)+F33 -> 348.54
D34: Stock 14 | F34: 158 | H34: SkyRockets | J34: 35 | K34: 15 | L34: 35 | M34: 25 | P34: 15 | T34: 15 | W34: 1.85 | X34: 1.52 | Y34: 1.22 | AA34: =(F34*W34)+F34 -> 450.3 | AB34: =(F34*X34)+F34 -> 398.16 | AC34: =(F34*Y34)+F34 -> 350.76
D35: Stock 15 | F35: 159 | H35: SkyRockets | J35: 34 | K35: 17 | L35: 32 | M35: 24 | P35: 14 | R35: 42 | T35: 17 | W35: 1.85 | X35: 1.52 | Y35: 1.22 | AA35: =(F35*W35)+F35 -> 453.15 | AB35: =(F35*X35)+F35 -> 400.68 | AC35: =(F35*Y35)+F35 -> 352.98
D36: Stock 16 | F36: 160 | H36: SkyRockets | J36: 37 | K36: 19 | L36: 36 | M36: 27 | N36: 49 | O36: 46 | P36: 17 | R36: 36 | T36: 19 | W36: 1.85 | X36: 1.52 | Y36: 1.22 | AA36: =(F36*W36)+F36 -> 456 | AB36: =(F36*X36)+F36 -> 403.2 | AC36: =(F36*Y36)+F36 -> 355.2
D37: Stock 17 | F37: 161 | H37: Slow Burn | J37: 36 | K37: 11 | L37: 35 | M37: 26 | N37: 41 | O37: 45 | P37: 16 | R37: 25 | S37: 6 | T37: 11 | W37: 1.85 | X37: 1.52 | Y37: 1.22 | AA37: =(F37*W37)+F37 -> 458.85 | AB37: =(F37*X37)+F37 -> 405.72 | AC37: =(F37*Y37)+F37 -> 357.42
D38: Stock 18 | F38: 162 | H38: Slow Burn | J38: 32 | K38: 12 | L38: 34 | M38: 22 | N38: 42 | O38: 44 | P38: 12 | Q38: 12 | R38: 24 | S38: 2 | T38: 12 | U38: 4 | W38: 1.85 | X38: 1.52 | Y38: 1.22 | AA38: =(F38*W38)+F38 -> 461.7 | AB38: =(F38*X38)+F38 -> 408.24 | AC38: =(F38*Y38)+F38 -> 359.64
D39: Stock 19 | F39: 163 | H39: SkyRockets | J39: 31 | K39: 14 | L39: 37 | M39: 21 | N39: 44 | O39: 47 | P39: 11 | Q39: 14 | R39: 17 | S39: 1 | T39: 14 | U39: 7 | W39: 1.85 | X39: 1.52 | Y39: 1.22 | AA39: =(F39*W39)+F39 -> 464.55 | AB39: =(F39*X39)+F39 -> 410.76 | AC39: =(F39*Y39)+F39 -> 361.86
D40: Stock 20 | F40: 164 | H40: Steady Eddy | J40: 34 | K40: 18 | L40: 38 | M40: 24 | N40: 48 | O40: 48 | P40: 14 | Q40: 18 | R40: 38 | S40: 4 | T40: 18 | U40: 8 | W40: 1.85 | X40: 1.52 | Y40: 1.22 | AA40: =(F40*W40)+F40 -> 467.4 | AB40: =(F40*X40)+F40 -> 413.28 | AC40: =(F40*Y40)+F40 -> 364.08
H42: Refrigerated | J42: Yes | K42: No | L42: Yes | M42: Yes | N42: No | O42: No | P42: No | Q42: Yes | R42: No | S42: No | T42: Yes | U42: No
H43: Container Size | J43: 10 ft | K43: 20 ft | L43: 40 ft | M43: 20 ft | N43: 10 ft | O43: 20 ft | P43: 40 ft | Q43: 10 ft | R43: 10 ft | S43: 20 ft | T43: 40 ft | U43: 20 ft
H44: Shipping Speed | J44: Air | K44: Sea | L44: Express | M44: Express | N44: Sea | O44: Air | P44: Express | Q44: Sea | R44: Air | S44: Express | T44: Sea | U44: Express
H45: # of Containers | J45: 1 | K45: 1.5 | L45: 2 | M45: 1 | N45: 1.5 | O45: 2 | P45: 1 | Q45: 1.25 | R45: 1 | S45: 1 | T45: 1 | U45: 1
H47: Shipping Costs | J47: =J98 -> 0 | K47: =K98 -> 0 | L47: =L98 -> 0 | M47: =M98 -> 7500 | N47: =N98 -> 12000 | O47: =O98 -> 43000 | P47: =P98 -> 11500 | Q47: =Q98 -> 5250 | ... U47: =U98 -> 7500
D50: Stock/ Manufacture Pmts
F51: =sum(J51:U51) -> 4469 | H51: Total Units | J51: =sum(J21:J40) -> 697 | K51: =sum(K21:K40) -> 250 | L51: =sum(L21:L40) -> 608 | M51: =sum(M21:M40) -> 365 | N51: =sum(N21:N40) -> 505 | O51: =sum(O21:O40) -> 652 | P51: =sum(P21:P40) -> 190 | Q51: =sum(Q21:Q40) -> 185 | ... U51: =sum(U21:U40) -> 88
...

Sheet Supplier 2 Inputs
F3: Total Days Elapsed From Order to Retail | K3: =F6+K5+F13 -> 154 | L3: =F6+L5+F13 -> 149 | M3: =F6+M5+F13 -> 144
U4: Stock Turn Days | W4: Shipment % | AO4: Yes | AP4: =K6 -> Sea | AQ4: =W5 -> SkyRockets
H5: Refrigerated Surcharge | J5: Container Size | K5: 25 | L5: 20 | M5: 15 | N5: Total Shipping Days | W5: SkyRockets | X5: Steady Eddy | Y5: Slow Burn | AO5: No | AP5: =L6 -> Air | AQ5: =X5 -> Steady Eddy
D6: Manufacture Days | F6: 120 | K6: Sea | L6: Air | M6: Express | AP6: =M6 -> Express | AQ6: =Y5 -> Slow Burn
D7: Order Deposit % | F7: 0.6 | H7: 2500 | J7: 10 ft | K7: 3500 | L7: 5000 | M7: 6500 | U7: 30 | W7: 0.4 | X7: 0.2 | Y7: 0.1
D8: Interest Cover % | F8: 0.06 | H8: 4000 | J8: 20 ft | K8: 8000 | L8: 10000 | M8: 11500 | U8: 60 | W8: 0.25 | X8: 0.3 | Y8: 0.3
D9: Currency Movement % | F9: 0.1 | H9: 6000 | J9: 40 ft | K9: 12000 | L9: 14000 | M9: 15500 | U9: 90 | W9: 0.2 | X9: 0.2 | Y9: 0.4
D10: Order Balance Due Days | F10: 91 | U10: 120 | W10: 0.15 | X10: 0.3 | Y10: 0.2
H12: Deposit Pmts | J12: =J54 -> 64585.8 | K12: =K54 -> 23379.6 | L12: =L54 -> 56586.6 | M12: =M54 -> 33959.4 | N12: =N54 -> 47503.8 | O12: =O54 -> 60406.2 | P12: =P54 -> 17821.8 | Q12: =Q54 -> 17206.2 | ... U12: =U54 -> 8024.4 | W12: =100%-sum(W7:W10) -> 0 | X12: =100%-sum(X7:X10) -> 0 | Y12: =100%-sum(Y7:Y10) -> 0
D13: Pre-Retail Prep Days | F13: 9 | H13: Balance Pmts | J13: =J75 -> 0 | K13: =K75 -> 0 | L13: =L75 -> 0 | M13: =M75 -> 44798.625 | N13: =N75 -> 16216.783 | O13: =O75 -> 39250.142 | P13: =P75 -> 23555.246 | Q13: =Q75 -> 32950.043 | ... U13: =U75 -> 32683.273 | W13: Up to | X13: Up to | Y13: Up to | AA13: =U4 -> Stock Turn Days
H15: Total Import Pmts | J15: =sum(J12:J13) -> 64585.8 | K15: =sum(K12:K13) -> 23379.6 | L15: =sum(L12:L13) -> 56586.6 | M15: =sum(M12:M13) -> 78758.025 | N15: =sum(N12:N13) -> 63720.583 | O15: =sum(O12:O13) -> 99656.342 | P15: =sum(P12:P13) -> 41377.046 | Q15: =sum(Q12:Q13) -> 50156.243 | ... U15: =sum(U12:U13) -> 40707.673 | W15: =U8 -> 60 | X15: =U9 -> 90 | Y15: =U10 -> 120
H17: Projected Sales
D19: Stock Items | F19: Unit Cost | H19: Item Popularity | J19: ='Supplier 1 Inputs'!J19 -> Jan | K19: ='Supplier 1 Inputs'!K19 -> Feb | L19: ='Supplier 1 Inputs'!L19 -> Mar | M19: ='Supplier 1 Inputs'!M19 -> Apr | N19: ='Supplier 1 Inputs'!N19 -> May | O19: ='Supplier 1 Inputs'!O19 -> Jun | P19: ='Supplier 1 Inputs'!P19 -> Jul | Q19: ='Supplier 1 Inputs'!Q19 -> Aug | ... U19: ='Supplier 1 Inputs'!U19 -> Dec | W19: New Stock Retail Markup % | X19: Std Retail Markup % | Y19: Runout Stock Markup % | AA19: New Stock Retail Price | AB19: Std Retail Price | AC19: Runout Stock Price
D21: Stock 1 | F21: 145 | H21: SkyRockets | J21: 34 | K21: 12 | L21: 35 | M21: 24 | N21: 12 | O21: 46 | P21: 14 | Q21: 12 | R21: 36 | S21: 4 | T21: 2 | U21: 16 | W21: 1.85 | X21: 1.52 | Y21: 1.22 | AA21: =(F21*W21)+F21 -> 413.25 | AB21: =(F21*X21)+F21 -> 365.4 | AC21: =(F21*Y21)+F21 -> 321.9
D22: Stock 2 | F22: 146 | H22: Steady Eddy | J22: 33 | K22: 14 | L22: 35 | M22: 23 | N22: 14 | O22: 45 | P22: 13 | R22: 25 | S22: 3 | U22: 15 | W22: 1.85 | X22: 1.52 | Y22: 1.22 | AA22: =(F22*W22)+F22 -> 416.1 | AB22: =(F22*X22)+F22 -> 367.92 | AC22: =(F22*Y22)+F22 -> 324.12
D23: Stock 3 | F23: 147 | H23: Slow Burn | J23: 35 | L23: 34 | N23: 16 | O23: 44 | P23: 15 | S23: 5 | W23: 1.85 | X23: 1.52 | Y23: 1.22 | AA23: =(F23*W23)+F23 -> 418.95 | AB23: =(F23*X23)+F23 -> 370.44 | AC23: =(F23*Y23)+F23 -> 326.34
D24: Stock 4 | F24: 148 | H24: Steady Eddy | J24: 38 | L24: 39 | N24: 18 | O24: 49 | S24: 8 | T24: 18 | W24: 1.85 | X24: 1.52 | Y24: 1.22 | AA24: =(F24*W24)+F24 -> 421.8 | AB24: =(F24*X24)+F24 -> 372.96 | AC24: =(F24*Y24)+F24 -> 328.56
D25: Stock 5 | F25: 149 | H25: SkyRockets | J25: 36 | L25: 38 | M25: 26 | N25: 11 | O25: 48 | Q25: 11 | R25: 28 | S25: 6 | T25: 17 | W25: 1.85 | X25: 1.52 | Y25: 1.22 | AA25: =(F25*W25)+F25 -> 424.65 | AB25: =(F25*X25)+F25 -> 375.48 | AC25: =(F25*Y25)+F25 -> 330.78
D26: Stock 6 | F26: 150 | H26: Slow Burn | J26: 35 | K26: 13 | M26: 25 | O26: 47 | Q26: 13 | R26: 37 | T26: 13 | U26: 17 | W26: 1.85 | X26: 1.52 | Y26: 1.22 | AA26: =(F26*W26)+F26 -> 427.5 | AB26: =(F26*X26)+F26 -> 378 | AC26: =(F26*Y26)+F26 -> 333
D27: Stock 7 | F27: 151 | H27: SkyRockets | J27: 34 | K27: 15 | M27: 24 | Q27: 15 | R27: 33 | T27: 15 | U27: 3 | W27: 1.85 | X27: 1.52 | Y27: 1.22 | AA27: =(F27*W27)+F27 -> 430.35 | AB27: =(F27*X27)+F27 -> 380.52 | AC27: =(F27*Y27)+F27 -> 335.22
D28: Stock 8 | F28: 152 | H28: SkyRockets | J28: 37 | K28: 17 | M28: 27 | N28: 37 | Q28: 17 | S28: 27 | T28: 17 | U28: 5 | W28: 1.85 | X28: 1.52 | Y28: 1.22 | AA28: =(F28*W28)+F28 -> 433.2 | AB28: =(F28*X28)+F28 -> 383.04 | AC28: =(F28*Y28)+F28 -> 337.44
D29: Stock 9 | F29: 153 | H29: Steady Eddy | J29: 34 | K29: 12 | L29: 37 | M29: 24 | N29: 32 | Q29: 12 | S29: 24 | T29: 12 | U29: 7 | W29: 1.85 | X29: 1.52 | Y29: 1.22 | AA29: =(F29*W29)+F29 -> 436.05 | AB29: =(F29*X29)+F29 -> 385.56 | AC29: =(F29*Y29)+F29 -> 339.66
D30: Stock 10 | F30: 154 | H30: Steady Eddy | J30: 33 | K30: 14 | L30: 31 | M30: 23 | N30: 34 | O30: 31 | Q30: 14 | R30: 41 | S30: 23 | U30: 1 | W30: 1.85 | X30: 1.52 | Y30: 1.22 | AA30: =(F30*W30)+F30 -> 438.9 | AB30: =(F30*X30)+F30 -> 388.08 | AC30: =(F30*Y30)+F30 -> 341.88
D31: Stock 11 | F31: 155 | H31: Steady Eddy | J31: 35 | K31: 16 | L31: 35 | N31: 36 | O31: 35 | P31: 15 | Q31: 16 | R31: 55 | S31: 25 | U31: 5 | W31: 1.85 | X31: 1.52 | Y31: 1.22 | AA31: =(F31*W31)+F31 -> 441.75 | AB31: =(F31*X31)+F31 -> 390.6 | AC31: =(F31*Y31)+F31 -> 344.1
D32: Stock 12 | F32: 156 | H32: Steady Eddy | J32: 38 | K32: 18 | L32: 39 | N32: 38 | O32: 39 | P32: 18 | Q32: 18 | R32: 69 | S32: 28 | T32: 18 | W32: 1.85 | X32: 1.52 | Y32: 1.22 | AA32: =(F32*W32)+F32 -> 444.6 | AB32: =(F32*X32)+F32 -> 393.12 | AC32: =(F32*Y32)+F32 -> 346.32
D33: Stock 13 | F33: 157 | H33: Steady Eddy | J33: 36 | K33: 13 | L33: 38 | N33: 33 | O33: 38 | P33: 16 | Q33: 13 | S33: 26 | T33: 13 | W33: 1.85 | X33: 1.52 | Y33: 1.22 | AA33: =(F33*W33)+F33 -> 447.45 | AB33: =(F33*X33)+F33 -> 395.64 | AC33: =(F33*Y33)+F33 -> 348.54
D34: Stock 14 | F34: 158 | H34: SkyRockets | J34: 35 | K34: 15 | L34: 35 | M34: 25 | P34: 15 | T34: 15 | W34: 1.85 | X34: 1.52 | Y34: 1.22 | AA34: =(F34*W34)+F34 -> 450.3 | AB34: =(F34*X34)+F34 -> 398.16 | AC34: =(F34*Y34)+F34 -> 350.76
D35: Stock 15 | F35: 159 | H35: SkyRockets | J35: 34 | K35: 17 | L35: 32 | M35: 24 | P35: 14 | R35: 42 | T35: 17 | W35: 1.85 | X35: 1.52 | Y35: 1.22 | AA35: =(F35*W35)+F35 -> 453.15 | AB35: =(F35*X35)+F35 -> 400.68 | AC35: =(F35*Y35)+F35 -> 352.98
D36: Stock 16 | F36: 160 | H36: SkyRockets | J36: 37 | K36: 19 | L36: 36 | M36: 27 | N36: 49 | O36: 46 | P36: 17 | R36: 36 | T36: 19 | W36: 1.85 | X36: 1.52 | Y36: 1.22 | AA36: =(F36*W36)+F36 -> 456 | AB36: =(F36*X36)+F36 -> 403.2 | AC36: =(F36*Y36)+F36 -> 355.2
D37: Stock 17 | F37: 161 | H37: Slow Burn | J37: 36 | K37: 11 | L37: 35 | M37: 26 | N37: 41 | O37: 45 | P37: 16 | R37: 25 | S37: 6 | T37: 11 | W37: 1.85 | X37: 1.52 | Y37: 1.22 | AA37: =(F37*W37)+F37 -> 458.85 | AB37: =(F37*X37)+F37 -> 405.72 | AC37: =(F37*Y37)+F37 -> 357.42
D38: Stock 18 | F38: 162 | H38: Slow Burn | J38: 32 | K38: 12 | L38: 34 | M38: 22 | N38: 42 | O38: 44 | P38: 12 | Q38: 12 | R38: 24 | S38: 2 | T38: 12 | U38: 4 | W38: 1.85 | X38: 1.52 | Y38: 1.22 | AA38: =(F38*W38)+F38 -> 461.7 | AB38: =(F38*X38)+F38 -> 408.24 | AC38: =(F38*Y38)+F38 -> 359.64
D39: Stock 19 | F39: 163 | H39: SkyRockets | J39: 31 | K39: 14 | L39: 37 | M39: 21 | N39: 44 | O39: 47 | P39: 11 | Q39: 14 | R39: 17 | S39: 1 | T39: 14 | U39: 7 | W39: 1.85 | X39: 1.52 | Y39: 1.22 | AA39: =(F39*W39)+F39 -> 464.55 | AB39: =(F39*X39)+F39 -> 410.76 | AC39: =(F39*Y39)+F39 -> 361.86
D40: Stock 20 | F40: 164 | H40: Steady Eddy | J40: 34 | K40: 18 | L40: 38 | M40: 24 | N40: 48 | O40: 48 | P40: 14 | Q40: 18 | R40: 38 | S40: 4 | T40: 18 | U40: 8 | W40: 1.85 | X40: 1.52 | Y40: 1.22 | AA40: =(F40*W40)+F40 -> 467.4 | AB40: =(F40*X40)+F40 -> 413.28 | AC40: =(F40*Y40)+F40 -> 364.08
H42: Refrigerated | J42: Yes | K42: No | L42: Yes | M42: Yes | N42: No | O42: No | P42: No | Q42: Yes | R42: No | S42: No | T42: Yes | U42: No
H43: Container Size | J43: 10 ft | K43: 20 ft | L43: 40 ft | M43: 20 ft | N43: 10 ft | O43: 20 ft | P43: 40 ft | Q43: 10 ft | R43: 10 ft | S43: 20 ft | T43: 40 ft | U43: 20 ft
H44: Shipping Speed | J44: Air | K44: Sea | L44: Express | M44: Express | N44: Sea | O44: Air | P44: Express | Q44: Sea | R44: Air | S44: Express | T44: Sea | U44: Express
H45: # of Containers | J45: 1 | K45: 1.5 | L45: 2 | M45: 1 | N45: 1.5 | O45: 2 | P45: 1 | Q45: 1.25 | R45: 1 | S45: 1 | T45: 1 | U45: 1
H47: Shipping Costs | J47: =J98 -> 0 | K47: =K98 -> 0 | L47: =L98 -> 0 | M47: =M98 -> 7500 | N47: =N98 -> 12000 | O47: =O98 -> 43000 | P47: =P98 -> 11500 | Q47: =Q98 -> 5250 | ... U47: =U98 -> 7500
D50: Stock/ Manufacture Pmts
F51: =sum(J51:U51) -> 4469 | H51: Total Units | J51: =sum(J21:J40) -> 697 | K51: =sum(K21:K40) -> 250 | L51: =sum(L21:L40) -> 608 | M51: =sum(M21:M40) -> 365 | N51: =sum(N21:N40) -> 505 | O51: =sum(O21:O40) -> 652 | P51: =sum(P21:P40) -> 190 | Q51: =sum(Q21:Q40) -> 185 | ... U51: =sum(U21:U40) -> 88
...

Sheet Copy of Supplier 2 Inputs
F3: Total Days Elapsed From Order to Retail | K3: =F6+K5+F13 -> 154 | L3: =F6+L5+F13 -> 149 | M3: =F6+M5+F13 -> 144
U4: Stock Turn Days | W4: Shipment % | AO4: Yes | AP4: =K6 -> Sea | AQ4: =W5 -> SkyRockets
H5: Refrigerated Surcharge | J5: Container Size | K5: 25 | L5: 20 | M5: 15 | N5: Total Shipping Days | W5: SkyRockets | X5: Steady Eddy | Y5: Slow Burn | AO5: No | AP5: =L6 -> Air | AQ5: =X5 -> Steady Eddy
D6: Manufacture Days | F6: 120 | K6: Sea | L6: Air | M6: Express | AP6: =M6 -> Express | AQ6: =Y5 -> Slow Burn
D7: Order Deposit % | F7: 0.6 | H7: 2500 | J7: 10 ft | K7: 3500 | L7: 5000 | M7: 6500 | U7: 30 | W7: 0.4 | X7: 0.2 | Y7: 0.1
D8: Interest Cover % | F8: 0.06 | H8: 4000 | J8: 20 ft | K8: 8000 | L8: 10000 | M8: 11500 | U8: 60 | W8: 0.25 | X8: 0.3 | Y8: 0.3
D9: Currency Movement % | F9: 0.1 | H9: 6000 | J9: 40 ft | K9: 12000 | L9: 14000 | M9: 15500 | U9: 90 | W9: 0.2 | X9: 0.2 | Y9: 0.4
D10: Order Balance Due Days | F10: 91 | U10: 120 | W10: 0.15 | X10: 0.3 | Y10: 0.2
H12: Deposit Pmts | J12: =J54 -> 64585.8 | K12: =K54 -> 23379.6 | L12: =L54 -> 56586.6 | M12: =M54 -> 33959.4 | N12: =N54 -> 47503.8 | O12: =O54 -> 60406.2 | P12: =P54 -> 17821.8 | Q12: =Q54 -> 17206.2 | ... U12: =U54 -> 8024.4 | W12: =100%-sum(W7:W10) -> 0 | X12: =100%-sum(X7:X10) -> 0 | Y12: =100%-sum(Y7:Y10) -> 0
D13: Pre-Retail Prep Days | F13: 9 | H13: Balance Pmts | J13: =J75 -> 0 | K13: =K75 -> 0 | L13: =L75 -> 0 | M13: =M75 -> 44798.625 | N13: =N75 -> 16216.783 | O13: =O75 -> 39250.142 | P13: =P75 -> 23555.246 | Q13: =Q75 -> 32950.043 | ... U13: =U75 -> 32683.273 | W13: Up to | X13: Up to | Y13: Up to | AA13: =U4 -> Stock Turn Days
H15: Total Import Pmts | J15: =sum(J12:J13) -> 64585.8 | K15: =sum(K12:K13) -> 23379.6 | L15: =sum(L12:L13) -> 56586.6 | M15: =sum(M12:M13) -> 78758.025 | N15: =sum(N12:N13) -> 63720.583 | O15: =sum(O12:O13) -> 99656.342 | P15: =sum(P12:P13) -> 41377.046 | Q15: =sum(Q12:Q13) -> 50156.243 | ... U15: =sum(U12:U13) -> 40707.673 | W15: =U8 -> 60 | X15: =U9 -> 90 | Y15: =U10 -> 120
H17: Projected Sales
D19: Stock Items | F19: Unit Cost | H19: Item Popularity | J19: ='Supplier 1 Inputs'!J19 -> Jan | K19: ='Supplier 1 Inputs'!K19 -> Feb | L19: ='Supplier 1 Inputs'!L19 -> Mar | M19: ='Supplier 1 Inputs'!M19 -> Apr | N19: ='Supplier 1 Inputs'!N19 -> May | O19: ='Supplier 1 Inputs'!O19 -> Jun | P19: ='Supplier 1 Inputs'!P19 -> Jul | Q19: ='Supplier 1 Inputs'!Q19 -> Aug | ... U19: ='Supplier 1 Inputs'!U19 -> Dec | W19: New Stock Retail Markup % | X19: Std Retail Markup % | Y19: Runout Stock Markup % | AA19: New Stock Retail Price | AB19: Std Retail Price | AC19: Runout Stock Price
D21: Stock 1 | F21: 145 | H21: SkyRockets | J21: 34 | K21: 12 | L21: 35 | M21: 24 | N21: 12 | O21: 46 | P21: 14 | Q21: 12 | R21: 36 | S21: 4 | T21: 2 | U21: 16 | W21: 1.85 | X21: 1.52 | Y21: 1.22 | AA21: =(F21*W21)+F21 -> 413.25 | AB21: =(F21*X21)+F21 -> 365.4 | AC21: =(F21*Y21)+F21 -> 321.9
D22: Stock 2 | F22: 146 | H22: Steady Eddy | J22: 33 | K22: 14 | L22: 35 | M22: 23 | N22: 14 | O22: 45 | P22: 13 | R22: 25 | S22: 3 | U22: 15 | W22: 1.85 | X22: 1.52 | Y22: 1.22 | AA22: =(F22*W22)+F22 -> 416.1 | AB22: =(F22*X22)+F22 -> 367.92 | AC22: =(F22*Y22)+F22 -> 324.12
D23: Stock 3 | F23: 147 | H23: Slow Burn | J23: 35 | L23: 34 | N23: 16 | O23: 44 | P23: 15 | S23: 5 | W23: 1.85 | X23: 1.52 | Y23: 1.22 | AA23: =(F23*W23)+F23 -> 418.95 | AB23: =(F23*X23)+F23 -> 370.44 | AC23: =(F23*Y23)+F23 -> 326.34
D24: Stock 4 | F24: 148 | H24: Steady Eddy | J24: 38 | L24: 39 | N24: 18 | O24: 49 | S24: 8 | T24: 18 | W24: 1.85 | X24: 1.52 | Y24: 1.22 | AA24: =(F24*W24)+F24 -> 421.8 | AB24: =(F24*X24)+F24 -> 372.96 | AC24: =(F24*Y24)+F24 -> 328.56
D25: Stock 5 | F25: 149 | H25: SkyRockets | J25: 36 | L25: 38 | M25: 26 | N25: 11 | O25: 48 | Q25: 11 | R25: 28 | S25: 6 | T25: 17 | W25: 1.85 | X25: 1.52 | Y25: 1.22 | AA25: =(F25*W25)+F25 -> 424.65 | AB25: =(F25*X25)+F25 -> 375.48 | AC25: =(F25*Y25)+F25 -> 330.78
D26: Stock 6 | F26: 150 | H26: Slow Burn | J26: 35 | K26: 13 | M26: 25 | O26: 47 | Q26: 13 | R26: 37 | T26: 13 | U26: 17 | W26: 1.85 | X26: 1.52 | Y26: 1.22 | AA26: =(F26*W26)+F26 -> 427.5 | AB26: =(F26*X26)+F26 -> 378 | AC26: =(F26*Y26)+F26 -> 333
D27: Stock 7 | F27: 151 | H27: SkyRockets | J27: 34 | K27: 15 | M27: 24 | Q27: 15 | R27: 33 | T27: 15 | U27: 3 | W27: 1.85 | X27: 1.52 | Y27: 1.22 | AA27: =(F27*W27)+F27 -> 430.35 | AB27: =(F27*X27)+F27 -> 380.52 | AC27: =(F27*Y27)+F27 -> 335.22
D28: Stock 8 | F28: 152 | H28: SkyRockets | J28: 37 | K28: 17 | M28: 27 | N28: 37 | Q28: 17 | S28: 27 | T28: 17 | U28: 5 | W28: 1.85 | X28: 1.52 | Y28: 1.22 | AA28: =(F28*W28)+F28 -> 433.2 | AB28: =(F28*X28)+F28 -> 383.04 | AC28: =(F28*Y28)+F28 -> 337.44
D29: Stock 9 | F29: 153 | H29: Steady Eddy | J29: 34 | K29: 12 | L29: 37 | M29: 24 | N29: 32 | Q29: 12 | S29: 24 | T29: 12 | U29: 7 | W29: 1.85 | X29: 1.52 | Y29: 1.22 | AA29: =(F29*W29)+F29 -> 436.05 | AB29: =(F29*X29)+F29 -> 385.56 | AC29: =(F29*Y29)+F29 -> 339.66
D30: Stock 10 | F30: 154 | H30: Steady Eddy | J30: 33 | K30: 14 | L30: 31 | M30: 23 | N30: 34 | O30: 31 | Q30: 14 | R30: 41 | S30: 23 | U30: 1 | W30: 1.85 | X30: 1.52 | Y30: 1.22 | AA30: =(F30*W30)+F30 -> 438.9 | AB30: =(F30*X30)+F30 -> 388.08 | AC30: =(F30*Y30)+F30 -> 341.88
D31: Stock 11 | F31: 155 | H31: Steady Eddy | J31: 35 | K31: 16 | L31: 35 | N31: 36 | O31: 35 | P31: 15 | Q31: 16 | R31: 55 | S31: 25 | U31: 5 | W31: 1.85 | X31: 1.52 | Y31: 1.22 | AA31: =(F31*W31)+F31 -> 441.75 | AB31: =(F31*X31)+F31 -> 390.6 | AC31: =(F31*Y31)+F31 -> 344.1
D32: Stock 12 | F32: 156 | H32: Steady Eddy | J32: 38 | K32: 18 | L32: 39 | N32: 38 | O32: 39 | P32: 18 | Q32: 18 | R32: 69 | S32: 28 | T32: 18 | W32: 1.85 | X32: 1.52 | Y32: 1.22 | AA32: =(F32*W32)+F32 -> 444.6 | AB32: =(F32*X32)+F32 -> 393.12 | AC32: =(F32*Y32)+F32 -> 346.32
D33: Stock 13 | F33: 157 | H33: Steady Eddy | J33: 36 | K33: 13 | L33: 38 | N33: 33 | O33: 38 | P33: 16 | Q33: 13 | S33: 26 | T33: 13 | W33: 1.85 | X33: 1.52 | Y33: 1.22 | AA33: =(F33*W33)+F33 -> 447.45 | AB33: =(F33*X33)+F33 -> 395.64 | AC33: =(F33*Y33)+F33 -> 348.54
D34: Stock 14 | F34: 158 | H34: SkyRockets | J34: 35 | K34: 15 | L34: 35 | M34: 25 | P34: 15 | T34: 15 | W34: 1.85 | X34: 1.52 | Y34: 1.22 | AA34: =(F34*W34)+F34 -> 450.3 | AB34: =(F34*X34)+F34 -> 398.16 | AC34: =(F34*Y34)+F34 -> 350.76
D35: Stock 15 | F35: 159 | H35: SkyRockets | J35: 34 | K35: 17 | L35: 32 | M35: 24 | P35: 14 | R35: 42 | T35: 17 | W35: 1.85 | X35: 1.52 | Y35: 1.22 | AA35: =(F35*W35)+F35 -> 453.15 | AB35: =(F35*X35)+F35 -> 400.68 | AC35: =(F35*Y35)+F35 -> 352.98
D36: Stock 16 | F36: 160 | H36: SkyRockets | J36: 37 | K36: 19 | L36: 36 | M36: 27 | N36: 49 | O36: 46 | P36: 17 | R36: 36 | T36: 19 | W36: 1.85 | X36: 1.52 | Y36: 1.22 | AA36: =(F36*W36)+F36 -> 456 | AB36: =(F36*X36)+F36 -> 403.2 | AC36: =(F36*Y36)+F36 -> 355.2
D37: Stock 17 | F37: 161 | H37: Slow Burn | J37: 36 | K37: 11 | L37: 35 | M37: 26 | N37: 41 | O37: 45 | P37: 16 | R37: 25 | S37: 6 | T37: 11 | W37: 1.85 | X37: 1.52 | Y37: 1.22 | AA37: =(F37*W37)+F37 -> 458.85 | AB37: =(F37*X37)+F37 -> 405.72 | AC37: =(F37*Y37)+F37 -> 357.42
D38: Stock 18 | F38: 162 | H38: Slow Burn | J38: 32 | K38: 12 | L38: 34 | M38: 22 | N38: 42 | O38: 44 | P38: 12 | Q38: 12 | R38: 24 | S38: 2 | T38: 12 | U38: 4 | W38: 1.85 | X38: 1.52 | Y38: 1.22 | AA38: =(F38*W38)+F38 -> 461.7 | AB38: =(F38*X38)+F38 -> 408.24 | AC38: =(F38*Y38)+F38 -> 359.64
D39: Stock 19 | F39: 163 | H39: SkyRockets | J39: 31 | K39: 14 | L39: 37 | M39: 21 | N39: 44 | O39: 47 | P39: 11 | Q39: 14 | R39: 17 | S39: 1 | T39: 14 | U39: 7 | W39: 1.85 | X39: 1.52 | Y39: 1.22 | AA39: =(F39*W39)+F39 -> 464.55 | AB39: =(F39*X39)+F39 -> 410.76 | AC39: =(F39*Y39)+F39 -> 361.86
D40: Stock 20 | F40: 164 | H40: Steady Eddy | J40: 34 | K40: 18 | L40: 38 | M40: 24 | N40: 48 | O40: 48 | P40: 14 | Q40: 18 | R40: 38 | S40: 4 | T40: 18 | U40: 8 | W40: 1.85 | X40: 1.52 | Y40: 1.22 | AA40: =(F40*W40)+F40 -> 467.4 | AB40: =(F40*X40)+F40 -> 413.28 | AC40: =(F40*Y40)+F40 -> 364.08
H42: Refrigerated | J42: Yes | K42: No | L42: Yes | M42: Yes | N42: No | O42: No | P42: No | Q42: Yes | R42: No | S42: No | T42: Yes | U42: No
H43: Container Size | J43: 10 ft | K43: 20 ft | L43: 40 ft | M43: 20 ft | N43: 10 ft | O43: 20 ft | P43: 40 ft | Q43: 10 ft | R43: 10 ft | S43: 20 ft | T43: 40 ft | U43: 20 ft
H44: Shipping Speed | J44: Air | K44: Sea | L44: Express | M44: Express | N44: Sea | O44: Air | P44: Express | Q44: Sea | R44: Air | S44: Express | T44: Sea | U44: Express
H45: # of Containers | J45: 1 | K45: 1.5 | L45: 2 | M45: 1 | N45: 1.5 | O45: 2 | P45: 1 | Q45: 1.25 | R45: 1 | S45: 1 | T45: 1 | U45: 1
H47: Shipping Costs | J47: =J98 -> 0 | K47: =K98 -> 0 | L47: =L98 -> 0 | M47: =M98 -> 7500 | N47: =N98 -> 12000 | O47: =O98 -> 43000 | P47: =P98 -> 11500 | Q47: =Q98 -> 5250 | ... U47: =U98 -> 7500
D50: Stock/ Manufacture Pmts
F51: =sum(J51:U51) -> 4469 | H51: Total Units | J51: =sum(J21:J40) -> 697 | K51: =sum(K21:K40) -> 250 | L51: =sum(L21:L40) -> 608 | M51: =sum(M21:M40) -> 365 | N51: =sum(N21:N40) -> 505 | O51: =sum(O21:O40) -> 652 | P51: =sum(P21:P40) -> 190 | Q51: =sum(Q21:Q40) -> 185 | ... U51: =sum(U21:U40) -> 88
...

Sheet Index Tables
M2: ='Copy of Supplier 2 Inputs'!W5 -> SkyRockets | N2: ='Copy of Supplier 2 Inputs'!X5 -> Steady Eddy | O2: ='Copy of Supplier 2 Inputs'!Y5 -> Slow Burn
L3: ='Copy of Supplier 2 Inputs'!U7 -> 30 | M3: ='Copy of Supplier 2 Inputs'!W7 -> 0.4 | N3: ='Copy of Supplier 2 Inputs'!X7 -> 0.2 | O3: ='Copy of Supplier 2 Inputs'!Y7 -> 0.1 | P3: =100%-sum(M3:O3) -> 0.3
L4: ='Copy of Supplier 2 Inputs'!U8 -> 60 | M4: ='Copy of Supplier 2 Inputs'!W8 -> 0.25 | N4: ='Copy of Supplier 2 Inputs'!X8 -> 0.3 | O4: ='Copy of Supplier 2 Inputs'!Y8 -> 0.3 | P4: =100%-sum(M4:O4) -> 0.15
L5: ='Copy of Supplier 2 Inputs'!U9 -> 90 | M5: ='Copy of Supplier 2 Inputs'!W9 -> 0.2 | N5: ='Copy of Supplier 2 Inputs'!X9 -> 0.2 | O5: ='Copy of Supplier 2 Inputs'!Y9 -> 0.4 | P5: =100%-sum(M5:O5) -> 0.2
L6: ='Copy of Supplier 2 Inputs'!U10 -> 120 | M6: ='Copy of Supplier 2 Inputs'!W10 -> 0.15 | N6: ='Copy of Supplier 2 Inputs'!X10 -> 0.3 | O6: ='Copy of Supplier 2 Inputs'!Y10 -> 0.2 | P6: =100%-sum(M6:O6) -> 0.35
L7: 150 | M7: 0.2 | N7: 0.4 | O7: 0.4 | P7: =100%-sum(M7:O7) -> 0
L8: 180 | M8: 0.4 | N8: 0.3 | O8: 0.3 | P8: =100%-sum(M8:O8) -> 0
L9: 180+ | M9: 0.15 | N9: 0.55 | O9: 0.3 | P9: =100%-sum(M9:O9) -> 0
D13: 30 | E13: 60 | F13: 90 | G13: 120 | H13: 150 | I13: 180 | J13: 210 | K13: 240 | L13: 270 | M13: 300 | N13: 330 | O13: 360 | P13: 390

Sheet Financial Projections
D4: Seasonal Times | F4: Off Peak | G4: Peak | H4: Peak | I4: Normal | J4: Normal | K4: Off Peak | L4: Off Peak | M4: Normal | N4: Peak | O4: Normal | P4: Peak | Q4: Peak
D5: list at bottom
D6: Wage Costs | F6: 20000 | G6: 20000 | H6: 20000 | I6: 20000 | J6: 20000 | K6: 20000 | L6: 20000 | M6: 20000 | N6: 20000 | O6: 20000 | P6: 20000 | Q6: 20000
F8: ='Supplier 1 Inputs'!J279 -> Jan | G8: ='Supplier 1 Inputs'!K279 -> Feb | H8: ='Supplier 1 Inputs'!L279 -> Mar | I8: ='Supplier 1 Inputs'!M279 -> Apr | J8: ='Supplier 1 Inputs'!N279 -> May | K8: ='Supplier 1 Inputs'!O279 -> Jun | L8: ='Supplier 1 Inputs'!P279 -> Jul | M8: ='Supplier 1 Inputs'!Q279 -> Aug | ... AB8: ='Supplier 1 Inputs'!AF279 -> Nov
D10: ='Supplier 1 Inputs'!H12 -> Deposit Pmts | F10: ='Supplier 1 Inputs'!J12+'Supplier 2 Inputs'!J12 -> 129171.6 | G10: ='Supplier 1 Inputs'!K12+'Supplier 2 Inputs'!K12 -> 46759.2 | H10: ='Supplier 1 Inputs'!L12+'Supplier 2 Inputs'!L12 -> 113173.2 | I10: ='Supplier 1 Inputs'!M12+'Supplier 2 Inputs'!M12 -> 67918.8 | J10: ='Supplier 1 Inputs'!N12+'Supplier 2 Inputs'!N12 -> 95007.6 | K10: ='Supplier 1 Inputs'!O12+'Supplier 2 Inputs'!O12 -> 120812.4 | L10: ='Supplier 1 Inputs'!P12+'Supplier 2 Inputs'!P12 -> 35643.6 | M10: ='Supplier 1 Inputs'!Q12+'Supplier 2 Inputs'!Q12 -> 34412.4 | ... Q10: ='Supplier 1 Inputs'!U12+'Supplier 2 Inputs'!U12 -> 16048.8 | AD10: =sum(F10:AB10) -> 831925.2
D12: ='Supplier 1 Inputs'!H13 -> Balance Pmts | F12: ='Supplier 1 Inputs'!J75+'Supplier 2 Inputs'!J75 -> 0 | G12: ='Supplier 1 Inputs'!K75+'Supplier 2 Inputs'!K75 -> 0 | H12: ='Supplier 1 Inputs'!L75+'Supplier 2 Inputs'!L75 -> 0 | I12: ='Supplier 1 Inputs'!M75+'Supplier 2 Inputs'!M75 -> 89597.249 | J12: ='Supplier 1 Inputs'!N75+'Supplier 2 Inputs'!N75 -> 32433.567 | K12: ='Supplier 1 Inputs'!O75+'Supplier 2 Inputs'!O75 -> 78500.285 | L12: ='Supplier 1 Inputs'!P75+'Supplier 2 Inputs'!P75 -> 47110.492 | M12: ='Supplier 1 Inputs'!Q75+'Supplier 2 Inputs'!Q75 -> 65900.086 | ... AB12: ='Supplier 1 Inputs'!AF75+'Supplier 2 Inputs'!AF75 -> 0 | AD12: =sum(F12:AB12) -> 577047.97 | AO12: Stock Costs | AP12: =AD10+AD12 -> 1408973.2
AO13: Shipping Costs | AP13: =AD14 -> 335250
D14: ='Supplier 1 Inputs'!H47 -> Shipping Costs | F14: ='Supplier 1 Inputs'!J98+'Supplier 2 Inputs'!J98 -> 0 | G14: ='Supplier 1 Inputs'!K98+'Supplier 2 Inputs'!K98 -> 0 | H14: ='Supplier 1 Inputs'!L98+'Supplier 2 Inputs'!L98 -> 0 | I14: ='Supplier 1 Inputs'!M98+'Supplier 2 Inputs'!M98 -> 15000 | J14: ='Supplier 1 Inputs'!N98+'Supplier 2 Inputs'!N98 -> 24000 | K14: ='Supplier 1 Inputs'!O98+'Supplier 2 Inputs'!O98 -> 86000 | L14: ='Supplier 1 Inputs'!P98+'Supplier 2 Inputs'!P98 -> 23000 | M14: ='Supplier 1 Inputs'!Q98+'Supplier 2 Inputs'!Q98 -> 10500 | ... AB14: ='Supplier 1 Inputs'!AF98+'Supplier 2 Inputs'!AF98 -> 0 | AD14: =sum(F14:AB14) -> 335250
D16: Total Payments | F16: =sum(F10:F14) -> 129171.6 | G16: =sum(G10:G14) -> 46759.2 | H16: =sum(H10:H14) -> 113173.2 | I16: =sum(I10:I14) -> 172516.05 | J16: =sum(J10:J14) -> 151441.17 | K16: =sum(K10:K14) -> 285312.68 | L16: =sum(L10:L14) -> 105754.09 | M16: =sum(M10:M14) -> 110812.49 | ... AB16: =sum(AB10:AB14) -> 0 | AD16: =sum(F16:AB16) -> 1744223.2
AO17: Total Sales | AP17: =AD18 -> 3595739.2
D18: Projected Revenue | F18: ='Supplier 1 Inputs'!J281+'Supplier 2 Inputs'!J281 -> 0 | G18: ='Supplier 1 Inputs'!K281+'Supplier 2 Inputs'!K281 -> 0 | H18: ='Supplier 1 Inputs'!L281+'Supplier 2 Inputs'!L281 -> 0 | I18: ='Supplier 1 Inputs'!M281+'Supplier 2 Inputs'!M281 -> 0 | J18: ='Supplier 1 Inputs'!N281+'Supplier 2 Inputs'!N281 -> 86041.5 | K18: ='Supplier 1 Inputs'!O281+'Supplier 2 Inputs'!O281 -> 184069.53 | L18: ='Supplier 1 Inputs'!P281+'Supplier 2 Inputs'!P281 -> 284287.09 | M18: ='Supplier 1 Inputs'!Q281+'Supplier 2 Inputs'!Q281 -> 383249.95 | ... AB18: ='Supplier 1 Inputs'!AF281+'Supplier 2 Inputs'!AF281 -> 0 | AD18: =sum(F18:AB18) -> 3595739.2 | AO18: Total Costs | AP18: =AP12+AP13 -> 1744223.2 | AQ18: =AP18/AP17 -> 0.48508056
AP19: =AP17-AP18 -> 1851516
D20: Import Related Mth Cash Movement
F21: =F18-(F16+F6) -> -149171.6 | G21: =G18-(G16+G6) -> -66759.2 | H21: =H18-(H16+H6) -> -133173.2 | I21: =I18-(I16+I6) -> -192516.05 | J21: =J18-(J16+J6) -> -85399.667 | K21: =K18-(K16+K6) -> -121243.15 | L21: =L18-(L16+L6) -> 158533 | M21: =M18-(M16+M6) -> 252437.47 | ... AB21: =AB18-(AB16+AB6) -> 0
D23: Opening Balance | F23: 1 | G23: =F25 -> -149170.6 | H23: =G25 -> -215929.8 | I23: =H25 -> -349103 | J23: =I25 -> -541619.05 | K23: =J25 -> -627018.72 | L23: =K25 -> -748261.87 | M23: =L25 -> -589728.87 | N23: =M25 -> -337291.4 | ... AB23: =AA25 -> 1611517
D25: Closing Balance | F25: =F21+F23 -> -149170.6 | G25: =G23+G21 -> -215929.8 | H25: =H23+H21 -> -349103 | I25: =I23+I21 -> -541619.05 | J25: =J23+J21 -> -627018.72 | K25: =K23+K21 -> -748261.87 | L25: =L23+L21 -> -589728.87 | M25: =M23+M21 -> -337291.4 | N25: =N23+N21 -> -271689.87 | ... AB25: =AB23+AB21 -> 1611517
N28: Total Sales | Q28: =AP17 -> 3595739.2 | U28: =sum(F6:Q6) -> 240000 | X28: Wages
N31: (Product Costs) | Q31: =AP18 -> 1744223.2
N32: Total Costs | Q32: =AP18+U28 -> 1984223.2 | U32: =Q28-Q32 -> 1611516 | X32: Gross Product Margin
N37: Product Costs as a % of Sales | Q37: =AQ18 -> 0.48508056 | U37: =U28/Q28 -> 0.066745664 | X37: Wages as a % of Sales
D54: Off Peak
D55: Peak
D56: Normal
