Workbook

Sheet Assumptions
Z3: =Z14/Z6 -> 0.88690784
D4: Collection of debtors | F4: Make sure you gain client involvement for these inputs
M5: ='Budget Figures'!D6 -> 44287 | N5: ='Budget Figures'!E6 -> 44317 | O5: ='Budget Figures'!F6 -> 44348 | P5: ='Budget Figures'!G6 -> 44378 | Q5: ='Budget Figures'!H6 -> 44409 | R5: ='Budget Figures'!I6 -> 44440 | S5: ='Budget Figures'!J6 -> 44470 | T5: ='Budget Figures'!K6 -> 44501 | ... X5: ='Budget Figures'!O6 -> 44621
D6: Enter collection percentages | K6: Sales | M6: ='Budget Figures'!D9 -> 25000 | N6: ='Budget Figures'!E9 -> 35000 | O6: ='Budget Figures'!F9 -> 45000 | P6: ='Budget Figures'!G9 -> 15000 | Q6: ='Budget Figures'!H9 -> 25000 | R6: ='Budget Figures'!I9 -> 30000 | S6: ='Budget Figures'!J9 -> 12500 | T6: ='Budget Figures'!K9 -> 25000 | ... X6: ='Budget Figures'!O9 -> 35800 | Z6: =sum(M6:X6) -> 348300
D8: Debtors/Cash collected in the same month as sale | F8: 0.2 | K8: Current Month | L8: =F8 -> 0.2 | M8: =M6*$L$8 -> 5000 | N8: =N6*$L$8 -> 7000 | O8: =O6*$L$8 -> 9000 | P8: =P6*$L$8 -> 3000 | Q8: =Q6*$L$8 -> 5000 | R8: =R6*$L$8 -> 6000 | S8: =S6*$L$8 -> 2500 | T8: =T6*$L$8 -> 5000 | ... X8: =X6*$L$8 -> 7160 | Z8: =sum(M8:X8) -> 69660
D9: Debtors collected in the first month following sale | F9: 0.45 | K9: 1st Month Following | L9: =F9 -> 0.45 | N9: =M6*$L$9 -> 11250 | O9: =N6*$L$9 -> 15750 | P9: =O6*$L$9 -> 20250 | Q9: =P6*$L$9 -> 6750 | R9: =Q6*$L$9 -> 11250 | S9: =R6*$L$9 -> 13500 | T9: =S6*$L$9 -> 5625 | U9: =T6*$L$9 -> 11250 | ... X9: =W6*$L$9 -> 11250 | Z9: =sum(M9:X9) -> 140625
D10: Debtors collected in the second month following sale | F10: 0.3 | K10: 2nd Month Following | L10: =F10 -> 0.3 | O10: =M6*$L$10 -> 7500 | P10: =N6*$L$10 -> 10500 | Q10: =O6*$L$10 -> 13500 | R10: =P6*$L$10 -> 4500 | S10: =Q6*$L$10 -> 7500 | T10: =R6*$L$10 -> 9000 | U10: =S6*$L$10 -> 3750 | V10: =T6*$L$10 -> 7500 | ... X10: =V6*$L$10 -> 12000 | Z10: =sum(M10:X10) -> 86250
D11: Debtors collected in the third month following sale | F11: 0.05 | K11: 3rd Month Following | L11: =F11 -> 0.05 | P11: =M6*$L$11 -> 1250 | Q11: =N6*$L$11 -> 1750 | R11: =O6*$L$11 -> 2250 | S11: =P6*$L$11 -> 750 | T11: =Q6*$L$11 -> 1250 | U11: =R6*$L$11 -> 1500 | V11: =S6*$L$11 -> 625 | W11: =T6*$L$11 -> 1250 | X11: =U6*$L$11 -> 1750 | Z11: =sum(M11:X11) -> 12375
D12: Debtors collected in the fourth month following sale | K12: 4th Month Following | L12: =F12 | Q12: =M6*L12 -> 0 | R12: =N6*M12 -> 0 | S12: =O6*N12 -> 0 | T12: =P6*O12 -> 0 | U12: =Q6*P12 -> 0 | V12: =R6*Q12 -> 0 | W12: =S6*R12 -> 0 | X12: =T6*S12 -> 0 | Z12: =sum(M12:X12) -> 0
G13: =100%-sum(F8:F12) -> 0 | H13: balance
L14: =SUM(L8:L13) -> 1 | M14: =SUM(M8:M12) -> 5000 | N14: =SUM(N8:N12) -> 18250 | O14: =SUM(O8:O12) -> 32250 | P14: =SUM(P8:P12) -> 35000 | Q14: =SUM(Q8:Q12) -> 27000 | R14: =SUM(R8:R12) -> 24000 | S14: =SUM(S8:S12) -> 24250 | T14: =SUM(T8:T12) -> 20875 | ... X14: =SUM(X8:X12) -> 32160 | Z14: =SUM(Z8:Z13) -> 308910
Z18: =Z29/Z21 -> 0.91888151
D19: Payment of inventory purchases, creditors' | F19: Make sure you gain client involvement for these inputs
M20: =M5 -> 44287 | N20: =N5 -> 44317 | O20: =O5 -> 44348 | P20: =P5 -> 44378 | Q20: =Q5 -> 44409 | R20: =R5 -> 44440 | S20: =S5 -> 44470 | T20: =T5 -> 44501 | ... X20: =X5 -> 44621
D21: Enter payment percentages for inventory purchases | K21: Material/Product Purchases | M21: ='Budget Figures'!D20 -> 13000 | N21: ='Budget Figures'!E20 -> 15000 | O21: ='Budget Figures'!F20 -> 18000 | P21: ='Budget Figures'!G20 -> 12000 | Q21: ='Budget Figures'!H20 -> 20000 | R21: ='Budget Figures'!I20 -> 15000 | S21: ='Budget Figures'!J20 -> 5600 | T21: ='Budget Figures'!K20 -> 12000 | ... X21: ='Budget Figures'!O20 -> 20000 | Z21: =sum(M21:X21) -> 180600
D23: Creditors paid in the same month as invoice | F23: 0.3 | K23: Current Month | L23: =F23 -> 0.3 | M23: =M21*$L$23 -> 3900 | N23: =N21*$L$23 -> 4500 | O23: =O21*$L$23 -> 5400 | P23: =P21*$L$23 -> 3600 | Q23: =Q21*$L$23 -> 6000 | R23: =R21*$L$23 -> 4500 | S23: =S21*$L$23 -> 1680 | T23: =T21*$L$23 -> 3600 | ... X23: =X21*$L$23 -> 6000 | Z23: =sum(M23:X23) -> 54180
D24: Creditors paid in the first month following invoice | F24: 0.65 | K24: 1st Month Following | L24: =F24 -> 0.65 | N24: =M21*$L$24 -> 8450 | O24: =N21*$L$24 -> 9750 | P24: =O21*$L$24 -> 11700 | Q24: =P21*$L$24 -> 7800 | R24: =Q21*$L$24 -> 13000 | S24: =R21*$L$24 -> 9750 | T24: =S21*$L$24 -> 3640 | U24: =T21*$L$24 -> 7800 | ... X24: =W21*$L$24 -> 8450 | Z24: =sum(M24:X24) -> 104390
D25: Creditors paid in the second month following invoice | F25: 0.05 | K25: 2nd Month Following | L25: =F25 -> 0.05 | O25: =M21*$L$25 -> 650 | P25: =N21*$L$25 -> 750 | Q25: =O21*$L$25 -> 900 | R25: =P21*$L$25 -> 600 | S25: =Q21*$L$25 -> 1000 | T25: =R21*$L$25 -> 750 | U25: =S21*$L$25 -> 280 | V25: =T21*$L$25 -> 600 | ... X25: =V21*$L$25 -> 1100 | Z25: =sum(M25:X25) -> 7380
D26: Creditors paid in the third month following invoice | K26: 3rd Month Following | L26: =F26 | P26: =M21*$L$26 -> 0 | Q26: =N21*$L$26 -> 0 | R26: =O21*$L$26 -> 0 | S26: =P21*$L$26 -> 0 | T26: =Q21*$L$26 -> 0 | U26: =R21*$L$26 -> 0 | V26: =S21*$L$26 -> 0 | W26: =T21*$L$26 -> 0 | X26: =U21*$L$26 -> 0 | Z26: =sum(M26:X26) -> 0
D27: Creditors paid in the fourth month following invoice | K27: 4th Month Following | L27: =F27 | Q27: =M21*$L$27 -> 0 | R27: =N21*$L$27 -> 0 | S27: =O21*$L$27 -> 0 | T27: =P21*$L$27 -> 0 | U27: =Q21*$L$27 -> 0 | V27: =R21*$L$27 -> 0 | W27: =S21*$L$27 -> 0 | X27: =T21*$L$27 -> 0 | Z27: =sum(M27:X27) -> 0
G28: =100%-sum(F23:F27) -> 0 | H28: balance
L29: =SUM(L23:L28) -> 1 | M29: =SUM(M23:M27) -> 3900 | N29: =SUM(N23:N27) -> 12950 | O29: =SUM(O23:O27) -> 15800 | P29: =SUM(P23:P27) -> 16050 | Q29: =SUM(Q23:Q27) -> 14700 | R29: =SUM(R23:R27) -> 18100 | S29: =SUM(S23:S27) -> 12430 | T29: =SUM(T23:T27) -> 7990 | ... X29: =SUM(X23:X27) -> 15550 | Z29: =SUM(Z23:Z28) -> 165950
C32: Use the clear cell area below to add your own calculations regarding purchases and sales or, use an industry specific revenue model available in Advisor-e.
D34: Goods & Sales Tax % | F34: 0.15

Sheet Budget Figures
C3: FORECAST MONTHLY CASHFLOW: | U3: Goods & Sales Tax % | V3: =Assumptions!F34 -> 0.15
D6: 44287 | E6: 44317 | F6: 44348 | G6: 44378 | H6: 44409 | I6: 44440 | J6: 44470 | K6: 44501 | L6: 44531 | M6: 44562 | N6: 44593 | O6: 44621 | Q6: Year to Date
C7: DEPOSITS
C9: Sales | D9: 25000 | E9: 35000 | F9: 45000 | G9: 15000 | H9: 25000 | I9: 30000 | J9: 12500 | K9: 25000 | L9: 35000 | M9: 40000 | N9: 25000 | O9: 35800 | Q9: =SUM(D9:O9) -> 348300
C10: Tax Rebates | Q10: =SUM(D10:O10) -> 0
C11: Interest Received | Q11: =SUM(D11:O11) -> 0
C12: Capital Introduced | Q12: =SUM(D12:O12) -> 0
C13: Other | Q13: =SUM(D13:O13) -> 0
C14: Non GST Related Sales | D14: 250 | E14: 250 | F14: 250 | G14: 250 | H14: 250 | I14: 250 | J14: 250 | K14: 250 | L14: 250 | M14: 250 | N14: 250 | O14: 250 | Q14: =SUM(D14:O14) -> 3000
C16: SUBTOTAL DEPOSITS RECEIVED: | D16: =Assumptions!M14+D10+D11+D12+D13+D14 -> 5250 | E16: =Assumptions!N14+E10+E11+E12+E13+E14 -> 18500 | F16: =Assumptions!O14+F10+F11+F12+F13+F14 -> 32500 | G16: =Assumptions!P14+G10+G11+G12+G13+G14 -> 35250 | H16: =Assumptions!Q14+H10+H11+H12+H13+H14 -> 27250 | I16: =Assumptions!R14+I10+I11+I12+I13+I14 -> 24250 | J16: =Assumptions!S14+J10+J11+J12+J13+J14 -> 24500 | K16: =Assumptions!T14+K10+K11+K12+K13+K14 -> 21125 | ... O16: =Assumptions!X14+O10+O11+O12+O13+O14 -> 32410 | Q16: =SUM(D16:O16) -> 311910
C18: VARIABLE (JOB RELATED) COSTS
C20: Material/Product Purchases | D20: 13000 | E20: 15000 | F20: 18000 | G20: 12000 | H20: 20000 | I20: 15000 | J20: 5600 | K20: 12000 | L20: 15000 | M20: 22000 | N20: 13000 | O20: 20000 | Q20: =SUM(D20:O20) -> 180600
C22: PAYMENTS MADE | D22: =Assumptions!M29 -> 3900 | E22: =Assumptions!N29 -> 12950 | F22: =Assumptions!O29 -> 15800 | G22: =Assumptions!P29 -> 16050 | H22: =Assumptions!Q29 -> 14700 | I22: =Assumptions!R29 -> 18100 | J22: =Assumptions!S29 -> 12430 | K22: =Assumptions!T29 -> 7990 | ... O22: =Assumptions!X29 -> 15550 | Q22: =SUM(D22:O22) -> 165950
C24: GROSS PROFIT | D24: =D16-D22 -> 1350 | E24: =E16-E22 -> 5550 | F24: =F16-F22 -> 16700 | G24: =G16-G22 -> 19200 | H24: =H16-H22 -> 12550 | I24: =I16-I22 -> 6150 | J24: =J16-J22 -> 12070 | K24: =K16-K22 -> 13135 | ... O24: =O16-O22 -> 16860 | Q24: =SUM(D24:O24) -> 145960
C26: EXPENSES
C28: Car | D28: 500 | E28: 500 | F28: 500 | G28: 500 | H28: 500 | I28: 500 | J28: 500 | K28: 500 | L28: 500 | M28: 500 | N28: 500 | O28: 500 | Q28: =SUM(D28:O28) -> 6000
C29: Bank Fees | Q29: =SUM(D29:O29) -> 0
C30: Credit Card Charges | Q30: =SUM(D30:O30) -> 0
C31: Computer ( Hardware & Software) | Q31: =SUM(D31:O31) -> 0
C32: Entertainment | D32: 150 | E32: 150 | F32: 150 | G32: 150 | H32: 150 | I32: 150 | J32: 150 | K32: 150 | L32: 150 | M32: 150 | N32: 150 | O32: 150 | Q32: =SUM(D32:O32) -> 1800
C33: General Expenses | Q33: =SUM(D33:O33) -> 0
C34: Printing | Q34: =SUM(D34:O34) -> 0
C35: Stationary & Supplies | Q35: =SUM(D35:O35) -> 0
C36: Vehicle Leases | D36: 1000 | E36: 1000 | F36: 1000 | G36: 1000 | H36: 1000 | I36: 1000 | J36: 1000 | K36: 1000 | L36: 1000 | M36: 1000 | N36: 1000 | O36: 1000 | Q36: =SUM(D36:O36) -> 12000
C37: Telephone, Tolls & E-Mail | Q37: =SUM(D37:O37) -> 0
C38: Cell Phone | Q38: =SUM(D38:O38) -> 0
C39: Travelling & Accomodation | Q39: =SUM(D39:O39) -> 0
C40: Insurance | Q40: =SUM(D40:O40) -> 0
C41: Accounting | D41: 600 | E41: 600 | F41: 600 | G41: 600 | H41: 600 | I41: 600 | J41: 600 | K41: 600 | L41: 600 | M41: 600 | N41: 600 | O41: 600 | Q41: =SUM(D41:O41) -> 7200
C42: Provision for Taxation | Q42: =SUM(D42:O42) -> 0
C43: Fringe Benefit Tax | Q43: =SUM(D43:O43) -> 0
C44: Legal | Q44: =SUM(D44:O44) -> 0
C45: Low Cost Assets | Q45: =SUM(D45:O45) -> 0
C46: Plant & Equipment | Q46: =SUM(D46:O46) -> 0
C47: Drawings | Q47: =SUM(D47:O47) -> 0
C48: Principle Loan Repayments | D48: 500 | E48: 500 | F48: 500 | G48: 500 | H48: 500 | I48: 500 | J48: 500 | K48: 500 | L48: 500 | M48: 500 | N48: 500 | O48: 500 | Q48: =SUM(D48:O48) -> 6000
C49: Other 1 | Q49: =SUM(D49:O49) -> 0
C50: Other 2 | Q50: =SUM(D50:O50) -> 0
C51: Other 3 | Q51: =SUM(D51:O51) -> 0
C52: Other 4 | Q52: =SUM(D52:O52) -> 0
...

Sheet Actual Figures
C3: FORECAST MONTHLY CASHFLOW: | U3: Goods & Sales Tax % | V3: =Assumptions!F34 -> 0.15
D6: ='Budget Figures'!D6 -> 44287 | E6: ='Budget Figures'!E6 -> 44317 | F6: ='Budget Figures'!F6 -> 44348 | G6: ='Budget Figures'!G6 -> 44378 | H6: ='Budget Figures'!H6 -> 44409 | I6: ='Budget Figures'!I6 -> 44440 | J6: ='Budget Figures'!J6 -> 44470 | K6: ='Budget Figures'!K6 -> 44501 | ... O6: ='Budget Figures'!O6 -> 44621 | Q6: Year to Date
C7: DEPOSITS
C9: Sales | D9: 25000 | E9: 35000 | F9: 45000 | G9: 15000 | H9: 25000 | I9: 30000 | J9: 12500 | K9: 25000 | L9: 35000 | M9: 40000 | N9: 25000 | O9: 35800 | Q9: =SUM(D9:O9) -> 348300
C10: Tax Rebates | Q10: =SUM(D10:O10) -> 0
C11: Interest Received | Q11: =SUM(D11:O11) -> 0
C12: Capital Introduced | Q12: =SUM(D12:O12) -> 0
C13: Other | Q13: =SUM(D13:O13) -> 0
C14: Non GST Related Sales | D14: 250 | E14: 250 | F14: 250 | G14: 250 | H14: 250 | I14: 250 | J14: 250 | K14: 250 | L14: 250 | M14: 250 | N14: 250 | O14: 250 | Q14: =SUM(D14:O14) -> 3000
C16: SUBTOTAL DEPOSITS RECEIVED: | D16: =sum(D9:D14) -> 25250 | E16: =sum(E9:E14) -> 35250 | F16: =sum(F9:F14) -> 45250 | G16: =sum(G9:G14) -> 15250 | H16: =sum(H9:H14) -> 25250 | I16: =sum(I9:I14) -> 30250 | J16: =sum(J9:J14) -> 12750 | K16: =sum(K9:K14) -> 25250 | ... O16: =sum(O9:O14) -> 36050 | Q16: =SUM(D16:O16) -> 351300
C18: VARIABLE (JOB RELATED) COSTS
C20: Material/Product Purchases | D20: 13000 | E20: 15000 | F20: 18000 | G20: 12000 | H20: 20000 | I20: 15000 | J20: 5600 | K20: 12000 | L20: 15000 | M20: 22000 | N20: 13000 | O20: 20000 | Q20: =SUM(D20:O20) -> 180600
C22: PAYMENTS MADE | D22: =D20 -> 13000 | E22: =E20 -> 15000 | F22: =F20 -> 18000 | G22: =G20 -> 12000 | H22: =H20 -> 20000 | I22: =I20 -> 15000 | J22: =J20 -> 5600 | K22: =K20 -> 12000 | ... O22: =O20 -> 20000 | Q22: =SUM(D22:O22) -> 180600
C24: GROSS PROFIT | D24: =D16-D22 -> 12250 | E24: =E16-E22 -> 20250 | F24: =F16-F22 -> 27250 | G24: =G16-G22 -> 3250 | H24: =H16-H22 -> 5250 | I24: =I16-I22 -> 15250 | J24: =J16-J22 -> 7150 | K24: =K16-K22 -> 13250 | ... O24: =O16-O22 -> 16050 | Q24: =SUM(D24:O24) -> 170700
C26: EXPENSES
C28: Car | D28: 500 | E28: 750 | F28: 500 | G28: 500 | H28: 1500 | I28: 500 | J28: 500 | K28: 500 | L28: 850 | M28: 500 | N28: 500 | O28: 500 | Q28: =SUM(D28:O28) -> 7600
C29: Bank Fees | Q29: =SUM(D29:O29) -> 0
C30: Credit Card Charges | Q30: =SUM(D30:O30) -> 0
C31: Computer ( Hardware & Software) | Q31: =SUM(D31:O31) -> 0
C32: Entertainment | D32: 150 | E32: 300 | F32: 150 | G32: 150 | H32: 250 | I32: 150 | J32: 150 | K32: 150 | L32: 450 | M32: 150 | N32: 150 | O32: 150 | Q32: =SUM(D32:O32) -> 2350
C33: General Expenses | Q33: =SUM(D33:O33) -> 0
C34: Printing | Q34: =SUM(D34:O34) -> 0
C35: Stationary & Supplies | Q35: =SUM(D35:O35) -> 0
C36: Vehicle Leases | D36: 1000 | E36: 1000 | F36: 1000 | G36: 1000 | H36: 1000 | I36: 1000 | J36: 1000 | K36: 1000 | L36: 1000 | M36: 1000 | N36: 1000 | O36: 1000 | Q36: =SUM(D36:O36) -> 12000
C37: Telephone, Tolls & E-Mail | Q37: =SUM(D37:O37) -> 0
C38: Cell Phone | Q38: =SUM(D38:O38) -> 0
C39: Travelling & Accomodation | Q39: =SUM(D39:O39) -> 0
C40: Insurance | Q40: =SUM(D40:O40) -> 0
C41: Accounting | D41: 600 | E41: 600 | F41: 600 | G41: 600 | H41: 600 | I41: 600 | J41: 600 | K41: 600 | L41: 600 | M41: 600 | N41: 600 | O41: 600 | Q41: =SUM(D41:O41) -> 7200
C42: Provision for Taxation | Q42: =SUM(D42:O42) -> 0
C43: Fringe Benefit Tax | Q43: =SUM(D43:O43) -> 0
C44: Legal | Q44: =SUM(D44:O44) -> 0
C45: Low Cost Assets | Q45: =SUM(D45:O45) -> 0
C46: Plant & Equipment | Q46: =SUM(D46:O46) -> 0
C47: Drawings | Q47: =SUM(D47:O47) -> 0
C48: Principle Loan Repayments | D48: 500 | E48: 500 | F48: 750 | G48: 500 | H48: 500 | I48: 1000 | J48: 500 | K48: 500 | L48: 500 | M48: 500 | N48: 500 | O48: 500 | Q48: =SUM(D48:O48) -> 6750
C49: Other 1 | Q49: =SUM(D49:O49) -> 0
C50: Other 2 | Q50: =SUM(D50:O50) -> 0
C51: Other 3 | Q51: =SUM(D51:O51) -> 0
C52: Other 4 | Q52: =SUM(D52:O52) -> 0
...

Sheet Cashflow Variances
C3: FORECAST MONTHLY CASHFLOW: | U3: Goods & Sales Tax % | V3: =Assumptions!F34 -> 0.15
D6: ='Budget Figures'!D6 -> 44287 | E6: ='Budget Figures'!E6 -> 44317 | F6: ='Budget Figures'!F6 -> 44348 | G6: ='Budget Figures'!G6 -> 44378 | H6: ='Budget Figures'!H6 -> 44409 | I6: ='Budget Figures'!I6 -> 44440 | J6: ='Budget Figures'!J6 -> 44470 | K6: ='Budget Figures'!K6 -> 44501 | ... O6: ='Budget Figures'!O6 -> 44621 | Q6: Year to Date
C7: DEPOSITS
C9: Sales | D9: =IF('Actual Figures'!D9<>"",'Actual Figures'!D9-'Budget Figures'!D9,"") -> 0 | E9: =IF('Actual Figures'!E9<>"",'Actual Figures'!E9-'Budget Figures'!E9,"") -> 0 | F9: =IF('Actual Figures'!F9<>"",'Actual Figures'!F9-'Budget Figures'!F9,"") -> 0 | G9: =IF('Actual Figures'!G9<>"",'Actual Figures'!G9-'Budget Figures'!G9,"") -> 0 | H9: =IF('Actual Figures'!H9<>"",'Actual Figures'!H9-'Budget Figures'!H9,"") -> 0 | I9: =IF('Actual Figures'!I9<>"",'Actual Figures'!I9-'Budget Figures'!I9,"") -> 0 | J9: =IF('Actual Figures'!J9<>"",'Actual Figures'!J9-'Budget Figures'!J9,"") -> 0 | K9: =IF('Actual Figures'!K9<>"",'Actual Figures'!K9-'Budget Figures'!K9,"") -> 0 | ... O9: =IF('Actual Figures'!O9<>"",'Actual Figures'!O9-'Budget Figures'!O9,"") -> 0 | Q9: =SUM(D9:O9) -> 0
C10: Tax Rebates | D10: =IF('Actual Figures'!D10<>"",'Actual Figures'!D10-'Budget Figures'!D10,"") | E10: =IF('Actual Figures'!E10<>"",'Actual Figures'!E10-'Budget Figures'!E10,"") | F10: =IF('Actual Figures'!F10<>"",'Actual Figures'!F10-'Budget Figures'!F10,"") | G10: =IF('Actual Figures'!G10<>"",'Actual Figures'!G10-'Budget Figures'!G10,"") | H10: =IF('Actual Figures'!H10<>"",'Actual Figures'!H10-'Budget Figures'!H10,"") | I10: =IF('Actual Figures'!I10<>"",'Actual Figures'!I10-'Budget Figures'!I10,"") | J10: =IF('Actual Figures'!J10<>"",'Actual Figures'!J10-'Budget Figures'!J10,"") | K10: =IF('Actual Figures'!K10<>"",'Actual Figures'!K10-'Budget Figures'!K10,"") | ... O10: =IF('Actual Figures'!O10<>"",'Actual Figures'!O10-'Budget Figures'!O10,"") | Q10: =SUM(D10:O10) -> 0
C11: Interest Received | D11: =IF('Actual Figures'!D11<>"",'Actual Figures'!D11-'Budget Figures'!D11,"") | E11: =IF('Actual Figures'!E11<>"",'Actual Figures'!E11-'Budget Figures'!E11,"") | F11: =IF('Actual Figures'!F11<>"",'Actual Figures'!F11-'Budget Figures'!F11,"") | G11: =IF('Actual Figures'!G11<>"",'Actual Figures'!G11-'Budget Figures'!G11,"") | H11: =IF('Actual Figures'!H11<>"",'Actual Figures'!H11-'Budget Figures'!H11,"") | I11: =IF('Actual Figures'!I11<>"",'Actual Figures'!I11-'Budget Figures'!I11,"") | J11: =IF('Actual Figures'!J11<>"",'Actual Figures'!J11-'Budget Figures'!J11,"") | K11: =IF('Actual Figures'!K11<>"",'Actual Figures'!K11-'Budget Figures'!K11,"") | ... O11: =IF('Actual Figures'!O11<>"",'Actual Figures'!O11-'Budget Figures'!O11,"") | Q11: =SUM(D11:O11) -> 0
C12: Capital Introduced | D12: =IF('Actual Figures'!D12<>"",'Actual Figures'!D12-'Budget Figures'!D12,"") | E12: =IF('Actual Figures'!E12<>"",'Actual Figures'!E12-'Budget Figures'!E12,"") | F12: =IF('Actual Figures'!F12<>"",'Actual Figures'!F12-'Budget Figures'!F12,"") | G12: =IF('Actual Figures'!G12<>"",'Actual Figures'!G12-'Budget Figures'!G12,"") | H12: =IF('Actual Figures'!H12<>"",'Actual Figures'!H12-'Budget Figures'!H12,"") | I12: =IF('Actual Figures'!I12<>"",'Actual Figures'!I12-'Budget Figures'!I12,"") | J12: =IF('Actual Figures'!J12<>"",'Actual Figures'!J12-'Budget Figures'!J12,"") | K12: =IF('Actual Figures'!K12<>"",'Actual Figures'!K12-'Budget Figures'!K12,"") | ... O12: =IF('Actual Figures'!O12<>"",'Actual Figures'!O12-'Budget Figures'!O12,"") | Q12: =SUM(D12:O12) -> 0
C13: Other | D13: =IF('Actual Figures'!D13<>"",'Actual Figures'!D13-'Budget Figures'!D13,"") | E13: =IF('Actual Figures'!E13<>"",'Actual Figures'!E13-'Budget Figures'!E13,"") | F13: =IF('Actual Figures'!F13<>"",'Actual Figures'!F13-'Budget Figures'!F13,"") | G13: =IF('Actual Figures'!G13<>"",'Actual Figures'!G13-'Budget Figures'!G13,"") | H13: =IF('Actual Figures'!H13<>"",'Actual Figures'!H13-'Budget Figures'!H13,"") | I13: =IF('Actual Figures'!I13<>"",'Actual Figures'!I13-'Budget Figures'!I13,"") | J13: =IF('Actual Figures'!J13<>"",'Actual Figures'!J13-'Budget Figures'!J13,"") | K13: =IF('Actual Figures'!K13<>"",'Actual Figures'!K13-'Budget Figures'!K13,"") | ... O13: =IF('Actual Figures'!O13<>"",'Actual Figures'!O13-'Budget Figures'!O13,"") | Q13: =SUM(D13:O13) -> 0
C14: Non GST Related Sales | D14: =IF('Actual Figures'!D14<>"",'Actual Figures'!D14-'Budget Figures'!D14,"") -> 0 | E14: =IF('Actual Figures'!E14<>"",'Actual Figures'!E14-'Budget Figures'!E14,"") -> 0 | F14: =IF('Actual Figures'!F14<>"",'Actual Figures'!F14-'Budget Figures'!F14,"") -> 0 | G14: =IF('Actual Figures'!G14<>"",'Actual Figures'!G14-'Budget Figures'!G14,"") -> 0 | H14: =IF('Actual Figures'!H14<>"",'Actual Figures'!H14-'Budget Figures'!H14,"") -> 0 | I14: =IF('Actual Figures'!I14<>"",'Actual Figures'!I14-'Budget Figures'!I14,"") -> 0 | J14: =IF('Actual Figures'!J14<>"",'Actual Figures'!J14-'Budget Figures'!J14,"") -> 0 | K14: =IF('Actual Figures'!K14<>"",'Actual Figures'!K14-'Budget Figures'!K14,"") -> 0 | ... O14: =IF('Actual Figures'!O14<>"",'Actual Figures'!O14-'Budget Figures'!O14,"") -> 0 | Q14: =SUM(D14:O14) -> 0
C16: SUBTOTAL DEPOSITS RECEIVED: | D16: =IF('Actual Figures'!D16<>"",'Actual Figures'!D16-'Budget Figures'!D16,"") -> 20000 | E16: =IF('Actual Figures'!E16<>"",'Actual Figures'!E16-'Budget Figures'!E16,"") -> 16750 | F16: =IF('Actual Figures'!F16<>"",'Actual Figures'!F16-'Budget Figures'!F16,"") -> 12750 | G16: =IF('Actual Figures'!G16<>"",'Actual Figures'!G16-'Budget Figures'!G16,"") -> -20000 | H16: =IF('Actual Figures'!H16<>"",'Actual Figures'!H16-'Budget Figures'!H16,"") -> -2000 | I16: =IF('Actual Figures'!I16<>"",'Actual Figures'!I16-'Budget Figures'!I16,"") -> 6000 | J16: =IF('Actual Figures'!J16<>"",'Actual Figures'!J16-'Budget Figures'!J16,"") -> -11750 | K16: =IF('Actual Figures'!K16<>"",'Actual Figures'!K16-'Budget Figures'!K16,"") -> 4125 | ... O16: =IF('Actual Figures'!O16<>"",'Actual Figures'!O16-'Budget Figures'!O16,"") -> 3640 | Q16: =SUM(D16:O16) -> 39390
C18: VARIABLE (JOB RELATED) COSTS
C20: Material/Product Purchases | D20: =IF('Actual Figures'!D20<>"",'Actual Figures'!D20-'Budget Figures'!D20,"") -> 0 | E20: =IF('Actual Figures'!E20<>"",'Actual Figures'!E20-'Budget Figures'!E20,"") -> 0 | F20: =IF('Actual Figures'!F20<>"",'Actual Figures'!F20-'Budget Figures'!F20,"") -> 0 | G20: =IF('Actual Figures'!G20<>"",'Actual Figures'!G20-'Budget Figures'!G20,"") -> 0 | H20: =IF('Actual Figures'!H20<>"",'Actual Figures'!H20-'Budget Figures'!H20,"") -> 0 | I20: =IF('Actual Figures'!I20<>"",'Actual Figures'!I20-'Budget Figures'!I20,"") -> 0 | J20: =IF('Actual Figures'!J20<>"",'Actual Figures'!J20-'Budget Figures'!J20,"") -> 0 | K20: =IF('Actual Figures'!K20<>"",'Actual Figures'!K20-'Budget Figures'!K20,"") -> 0 | ... O20: =IF('Actual Figures'!O20<>"",'Actual Figures'!O20-'Budget Figures'!O20,"") -> 0 | Q20: =SUM(D20:O20) -> 0
C22: PAYMENTS MADE | D22: =IF('Actual Figures'!D22<>"",'Actual Figures'!D22-'Budget Figures'!D22,"") -> 9100 | E22: =IF('Actual Figures'!E22<>"",'Actual Figures'!E22-'Budget Figures'!E22,"") -> 2050 | F22: =IF('Actual Figures'!F22<>"",'Actual Figures'!F22-'Budget Figures'!F22,"") -> 2200 | G22: =IF('Actual Figures'!G22<>"",'Actual Figures'!G22-'Budget Figures'!G22,"") -> -4050 | H22: =IF('Actual Figures'!H22<>"",'Actual Figures'!H22-'Budget Figures'!H22,"") -> 5300 | I22: =IF('Actual Figures'!I22<>"",'Actual Figures'!I22-'Budget Figures'!I22,"") -> -3100 | J22: =IF('Actual Figures'!J22<>"",'Actual Figures'!J22-'Budget Figures'!J22,"") -> -6830 | K22: =IF('Actual Figures'!K22<>"",'Actual Figures'!K22-'Budget Figures'!K22,"") -> 4010 | ... O22: =IF('Actual Figures'!O22<>"",'Actual Figures'!O22-'Budget Figures'!O22,"") -> 4450 | Q22: =SUM(D22:O22) -> 14650
C24: GROSS PROFIT | D24: =D16-D22 -> 10900 | E24: =E16-E22 -> 14700 | F24: =F16-F22 -> 10550 | G24: =G16-G22 -> -15950 | H24: =H16-H22 -> -7300 | I24: =I16-I22 -> 9100 | J24: =J16-J22 -> -4920 | K24: =K16-K22 -> 115 | ... O24: =O16-O22 -> -810 | Q24: =SUM(D24:O24) -> 24740
C26: EXPENSES
C28: Car | D28: =IF('Actual Figures'!D28<>"",'Actual Figures'!D28-'Budget Figures'!D28,"") -> 0 | E28: =IF('Actual Figures'!E28<>"",'Actual Figures'!E28-'Budget Figures'!E28,"") -> 250 | F28: =IF('Actual Figures'!F28<>"",'Actual Figures'!F28-'Budget Figures'!F28,"") -> 0 | G28: =IF('Actual Figures'!G28<>"",'Actual Figures'!G28-'Budget Figures'!G28,"") -> 0 | H28: =IF('Actual Figures'!H28<>"",'Actual Figures'!H28-'Budget Figures'!H28,"") -> 1000 | I28: =IF('Actual Figures'!I28<>"",'Actual Figures'!I28-'Budget Figures'!I28,"") -> 0 | J28: =IF('Actual Figures'!J28<>"",'Actual Figures'!J28-'Budget Figures'!J28,"") -> 0 | K28: =IF('Actual Figures'!K28<>"",'Actual Figures'!K28-'Budget Figures'!K28,"") -> 0 | ... O28: =IF('Actual Figures'!O28<>"",'Actual Figures'!O28-'Budget Figures'!O28,"") -> 0 | Q28: =SUM(D28:O28) -> 1600
C29: Bank Fees | D29: =IF('Actual Figures'!D29<>"",'Actual Figures'!D29-'Budget Figures'!D29,"") | E29: =IF('Actual Figures'!E29<>"",'Actual Figures'!E29-'Budget Figures'!E29,"") | F29: =IF('Actual Figures'!F29<>"",'Actual Figures'!F29-'Budget Figures'!F29,"") | G29: =IF('Actual Figures'!G29<>"",'Actual Figures'!G29-'Budget Figures'!G29,"") | H29: =IF('Actual Figures'!H29<>"",'Actual Figures'!H29-'Budget Figures'!H29,"") | I29: =IF('Actual Figures'!I29<>"",'Actual Figures'!I29-'Budget Figures'!I29,"") | J29: =IF('Actual Figures'!J29<>"",'Actual Figures'!J29-'Budget Figures'!J29,"") | K29: =IF('Actual Figures'!K29<>"",'Actual Figures'!K29-'Budget Figures'!K29,"") | ... O29: =IF('Actual Figures'!O29<>"",'Actual Figures'!O29-'Budget Figures'!O29,"") | Q29: =SUM(D29:O29) -> 0
C30: Credit Card Charges | D30: =IF('Actual Figures'!D30<>"",'Actual Figures'!D30-'Budget Figures'!D30,"") | E30: =IF('Actual Figures'!E30<>"",'Actual Figures'!E30-'Budget Figures'!E30,"") | F30: =IF('Actual Figures'!F30<>"",'Actual Figures'!F30-'Budget Figures'!F30,"") | G30: =IF('Actual Figures'!G30<>"",'Actual Figures'!G30-'Budget Figures'!G30,"") | H30: =IF('Actual Figures'!H30<>"",'Actual Figures'!H30-'Budget Figures'!H30,"") | I30: =IF('Actual Figures'!I30<>"",'Actual Figures'!I30-'Budget Figures'!I30,"") | J30: =IF('Actual Figures'!J30<>"",'Actual Figures'!J30-'Budget Figures'!J30,"") | K30: =IF('Actual Figures'!K30<>"",'Actual Figures'!K30-'Budget Figures'!K30,"") | ... O30: =IF('Actual Figures'!O30<>"",'Actual Figures'!O30-'Budget Figures'!O30,"") | Q30: =SUM(D30:O30) -> 0
C31: Computer ( Hardware & Software) | D31: =IF('Actual Figures'!D31<>"",'Actual Figures'!D31-'Budget Figures'!D31,"") | E31: =IF('Actual Figures'!E31<>"",'Actual Figures'!E31-'Budget Figures'!E31,"") | F31: =IF('Actual Figures'!F31<>"",'Actual Figures'!F31-'Budget Figures'!F31,"") | G31: =IF('Actual Figures'!G31<>"",'Actual Figures'!G31-'Budget Figures'!G31,"") | H31: =IF('Actual Figures'!H31<>"",'Actual Figures'!H31-'Budget Figures'!H31,"") | I31: =IF('Actual Figures'!I31<>"",'Actual Figures'!I31-'Budget Figures'!I31,"") | J31: =IF('Actual Figures'!J31<>"",'Actual Figures'!J31-'Budget Figures'!J31,"") | K31: =IF('Actual Figures'!K31<>"",'Actual Figures'!K31-'Budget Figures'!K31,"") | ... O31: =IF('Actual Figures'!O31<>"",'Actual Figures'!O31-'Budget Figures'!O31,"") | Q31: =SUM(D31:O31) -> 0
C32: Entertainment | D32: =IF('Actual Figures'!D32<>"",'Actual Figures'!D32-'Budget Figures'!D32,"") -> 0 | E32: =IF('Actual Figures'!E32<>"",'Actual Figures'!E32-'Budget Figures'!E32,"") -> 150 | F32: =IF('Actual Figures'!F32<>"",'Actual Figures'!F32-'Budget Figures'!F32,"") -> 0 | G32: =IF('Actual Figures'!G32<>"",'Actual Figures'!G32-'Budget Figures'!G32,"") -> 0 | H32: =IF('Actual Figures'!H32<>"",'Actual Figures'!H32-'Budget Figures'!H32,"") -> 100 | I32: =IF('Actual Figures'!I32<>"",'Actual Figures'!I32-'Budget Figures'!I32,"") -> 0 | J32: =IF('Actual Figures'!J32<>"",'Actual Figures'!J32-'Budget Figures'!J32,"") -> 0 | K32: =IF('Actual Figures'!K32<>"",'Actual Figures'!K32-'Budget Figures'!K32,"") -> 0 | ... O32: =IF('Actual Figures'!O32<>"",'Actual Figures'!O32-'Budget Figures'!O32,"") -> 0 | Q32: =SUM(D32:O32) -> 550
C33: General Expenses | D33: =IF('Actual Figures'!D33<>"",'Actual Figures'!D33-'Budget Figures'!D33,"") | E33: =IF('Actual Figures'!E33<>"",'Actual Figures'!E33-'Budget Figures'!E33,"") | F33: =IF('Actual Figures'!F33<>"",'Actual Figures'!F33-'Budget Figures'!F33,"") | G33: =IF('Actual Figures'!G33<>"",'Actual Figures'!G33-'Budget Figures'!G33,"") | H33: =IF('Actual Figures'!H33<>"",'Actual Figures'!H33-'Budget Figures'!H33,"") | I33: =IF('Actual Figures'!I33<>"",'Actual Figures'!I33-'Budget Figures'!I33,"") | J33: =IF('Actual Figures'!J33<>"",'Actual Figures'!J33-'Budget Figures'!J33,"") | K33: =IF('Actual Figures'!K33<>"",'Actual Figures'!K33-'Budget Figures'!K33,"") | ... O33: =IF('Actual Figures'!O33<>"",'Actual Figures'!O33-'Budget Figures'!O33,"") | Q33: =SUM(D33:O33) -> 0
C34: Printing | D34: =IF('Actual Figures'!D34<>"",'Actual Figures'!D34-'Budget Figures'!D34,"") | E34: =IF('Actual Figures'!E34<>"",'Actual Figures'!E34-'Budget Figures'!E34,"") | F34: =IF('Actual Figures'!F34<>"",'Actual Figures'!F34-'Budget Figures'!F34,"") | G34: =IF('Actual Figures'!G34<>"",'Actual Figures'!G34-'Budget Figures'!G34,"") | H34: =IF('Actual Figures'!H34<>"",'Actual Figures'!H34-'Budget Figures'!H34,"") | I34: =IF('Actual Figures'!I34<>"",'Actual Figures'!I34-'Budget Figures'!I34,"") | J34: =IF('Actual Figures'!J34<>"",'Actual Figures'!J34-'Budget Figures'!J34,"") | K34: =IF('Actual Figures'!K34<>"",'Actual Figures'!K34-'Budget Figures'!K34,"") | ... O34: =IF('Actual Figures'!O34<>"",'Actual Figures'!O34-'Budget Figures'!O34,"") | Q34: =SUM(D34:O34) -> 0
C35: Stationary & Supplies | D35: =IF('Actual Figures'!D35<>"",'Actual Figures'!D35-'Budget Figures'!D35,"") | E35: =IF('Actual Figures'!E35<>"",'Actual Figures'!E35-'Budget Figures'!E35,"") | F35: =IF('Actual Figures'!F35<>"",'Actual Figures'!F35-'Budget Figures'!F35,"") | G35: =IF('Actual Figures'!G35<>"",'Actual Figures'!G35-'Budget Figures'!G35,"") | H35: =IF('Actual Figures'!H35<>"",'Actual Figures'!H35-'Budget Figures'!H35,"") | I35: =IF('Actual Figures'!I35<>"",'Actual Figures'!I35-'Budget Figures'!I35,"") | J35: =IF('Actual Figures'!J35<>"",'Actual Figures'!J35-'Budget Figures'!J35,"") | K35: =IF('Actual Figures'!K35<>"",'Actual Figures'!K35-'Budget Figures'!K35,"") | ... O35: =IF('Actual Figures'!O35<>"",'Actual Figures'!O35-'Budget Figures'!O35,"") | Q35: =SUM(D35:O35) -> 0
C36: Vehicle Leases | D36: =IF('Actual Figures'!D36<>"",'Actual Figures'!D36-'Budget Figures'!D36,"") -> 0 | E36: =IF('Actual Figures'!E36<>"",'Actual Figures'!E36-'Budget Figures'!E36,"") -> 0 | F36: =IF('Actual Figures'!F36<>"",'Actual Figures'!F36-'Budget Figures'!F36,"") -> 0 | G36: =IF('Actual Figures'!G36<>"",'Actual Figures'!G36-'Budget Figures'!G36,"") -> 0 | H36: =IF('Actual Figures'!H36<>"",'Actual Figures'!H36-'Budget Figures'!H36,"") -> 0 | I36: =IF('Actual Figures'!I36<>"",'Actual Figures'!I36-'Budget Figures'!I36,"") -> 0 | J36: =IF('Actual Figures'!J36<>"",'Actual Figures'!J36-'Budget Figures'!J36,"") -> 0 | K36: =IF('Actual Figures'!K36<>"",'Actual Figures'!K36-'Budget Figures'!K36,"") -> 0 | ... O36: =IF('Actual Figures'!O36<>"",'Actual Figures'!O36-'Budget Figures'!O36,"") -> 0 | Q36: =SUM(D36:O36) -> 0
C37: Telephone, Tolls & E-Mail | D37: =IF('Actual Figures'!D37<>"",'Actual Figures'!D37-'Budget Figures'!D37,"") | E37: =IF('Actual Figures'!E37<>"",'Actual Figures'!E37-'Budget Figures'!E37,"") | F37: =IF('Actual Figures'!F37<>"",'Actual Figures'!F37-'Budget Figures'!F37,"") | G37: =IF('Actual Figures'!G37<>"",'Actual Figures'!G37-'Budget Figures'!G37,"") | H37: =IF('Actual Figures'!H37<>"",'Actual Figures'!H37-'Budget Figures'!H37,"") | I37: =IF('Actual Figures'!I37<>"",'Actual Figures'!I37-'Budget Figures'!I37,"") | J37: =IF('Actual Figures'!J37<>"",'Actual Figures'!J37-'Budget Figures'!J37,"") | K37: =IF('Actual Figures'!K37<>"",'Actual Figures'!K37-'Budget Figures'!K37,"") | ... O37: =IF('Actual Figures'!O37<>"",'Actual Figures'!O37-'Budget Figures'!O37,"") | Q37: =SUM(D37:O37) -> 0
C38: Cell Phone | D38: =IF('Actual Figures'!D38<>"",'Actual Figures'!D38-'Budget Figures'!D38,"") | E38: =IF('Actual Figures'!E38<>"",'Actual Figures'!E38-'Budget Figures'!E38,"") | F38: =IF('Actual Figures'!F38<>"",'Actual Figures'!F38-'Budget Figures'!F38,"") | G38: =IF('Actual Figures'!G38<>"",'Actual Figures'!G38-'Budget Figures'!G38,"") | H38: =IF('Actual Figures'!H38<>"",'Actual Figures'!H38-'Budget Figures'!H38,"") | I38: =IF('Actual Figures'!I38<>"",'Actual Figures'!I38-'Budget Figures'!I38,"") | J38: =IF('Actual Figures'!J38<>"",'Actual Figures'!J38-'Budget Figures'!J38,"") | K38: =IF('Actual Figures'!K38<>"",'Actual Figures'!K38-'Budget Figures'!K38,"") | ... O38: =IF('Actual Figures'!O38<>"",'Actual Figures'!O38-'Budget Figures'!O38,"") | Q38: =SUM(D38:O38) -> 0
C39: Travelling & Accomodation | D39: =IF('Actual Figures'!D39<>"",'Actual Figures'!D39-'Budget Figures'!D39,"") | E39: =IF('Actual Figures'!E39<>"",'Actual Figures'!E39-'Budget Figures'!E39,"") | F39: =IF('Actual Figures'!F39<>"",'Actual Figures'!F39-'Budget Figures'!F39,"") | G39: =IF('Actual Figures'!G39<>"",'Actual Figures'!G39-'Budget Figures'!G39,"") | H39: =IF('Actual Figures'!H39<>"",'Actual Figures'!H39-'Budget Figures'!H39,"") | I39: =IF('Actual Figures'!I39<>"",'Actual Figures'!I39-'Budget Figures'!I39,"") | J39: =IF('Actual Figures'!J39<>"",'Actual Figures'!J39-'Budget Figures'!J39,"") | K39: =IF('Actual Figures'!K39<>"",'Actual Figures'!K39-'Budget Figures'!K39,"") | ... O39: =IF('Actual Figures'!O39<>"",'Actual Figures'!O39-'Budget Figures'!O39,"") | Q39: =SUM(D39:O39) -> 0
... C54: Other 6 | D54: =IF('Actual Figures'!D54<>"",'Actual Figures'!D54-'Budget Figures'!D54,"") | E54: =IF('Actual Figures'!E54<>"",'Actual Figures'!E54-'Budget Figures'!E54,"") | F54: =IF('Actual Figures'!F54<>"",'Actual Figures'!F54-'Budget Figures'!F54,"") | G54: =IF('Actual Figures'!G54<>"",'Actual Figures'!G54-'Budget Figures'!G54,"") | H54: =IF('Actual Figures'!H54<>"",'Actual Figures'!H54-'Budget Figures'!H54,"") | I54: =IF('Actual Figures'!I54<>"",'Actual Figures'!I54-'Budget Figures'!I54,"") | J54: =IF('Actual Figures'!J54<>"",'Actual Figures'!J54-'Budget Figures'!J54,"") | K54: =IF('Actual Figures'!K54<>"",'Actual Figures'!K54-'Budget Figures'!K54,"") | ... O54: =IF('Actual Figures'!O54<>"",'Actual Figures'!O54-'Budget Figures'!O54,"") | Q54: =SUM(D54:O54) -> 0
C56: NON GST RELATED WITHDRAWALS
C58: Wages | D58: =IF('Actual Figures'!D58<>"",'Actual Figures'!D58-'Budget Figures'!D58,"") -> 0 | E58: =IF('Actual Figures'!E58<>"",'Actual Figures'!E58-'Budget Figures'!E58,"") -> 0 | F58: =IF('Actual Figures'!F58<>"",'Actual Figures'!F58-'Budget Figures'!F58,"") -> 0 | G58: =IF('Actual Figures'!G58<>"",'Actual Figures'!G58-'Budget Figures'!G58,"") -> 0 | H58: =IF('Actual Figures'!H58<>"",'Actual Figures'!H58-'Budget Figures'!H58,"") -> 0 | I58: =IF('Actual Figures'!I58<>"",'Actual Figures'!I58-'Budget Figures'!I58,"") -> 0 | J58: =IF('Actual Figures'!J58<>"",'Actual Figures'!J58-'Budget Figures'!J58,"") -> 0 | K58: =IF('Actual Figures'!K58<>"",'Actual Figures'!K58-'Budget Figures'!K58,"") -> 0 | ... O58: =IF('Actual Figures'!O58<>"",'Actual Figures'!O58-'Budget Figures'!O58,"") -> 0 | Q58: =SUM(D58:O58) -> 0
C59: Interest Only Loan Payments | D59: =IF('Actual Figures'!D59<>"",'Actual Figures'!D59-'Budget Figures'!D59,"") -> 0 | E59: =IF('Actual Figures'!E59<>"",'Actual Figures'!E59-'Budget Figures'!E59,"") -> 0 | F59: =IF('Actual Figures'!F59<>"",'Actual Figures'!F59-'Budget Figures'!F59,"") -> 0 | G59: =IF('Actual Figures'!G59<>"",'Actual Figures'!G59-'Budget Figures'!G59,"") -> 0 | H59: =IF('Actual Figures'!H59<>"",'Actual Figures'!H59-'Budget Figures'!H59,"") -> 0 | I59: =IF('Actual Figures'!I59<>"",'Actual Figures'!I59-'Budget Figures'!I59,"") -> 0 | J59: =IF('Actual Figures'!J59<>"",'Actual Figures'!J59-'Budget Figures'!J59,"") -> 0 | K59: =IF('Actual Figures'!K59<>"",'Actual Figures'!K59-'Budget Figures'!K59,"") -> 0 | ... O59: =IF('Actual Figures'!O59<>"",'Actual Figures'!O59-'Budget Figures'!O59,"") -> 0 | Q59: =SUM(D59:O59) -> 0
C60: Other 1 | D60: =IF('Actual Figures'!D60<>"",'Actual Figures'!D60-'Budget Figures'!D60,"") | E60: =IF('Actual Figures'!E60<>"",'Actual Figures'!E60-'Budget Figures'!E60,"") | F60: =IF('Actual Figures'!F60<>"",'Actual Figures'!F60-'Budget Figures'!F60,"") | G60: =IF('Actual Figures'!G60<>"",'Actual Figures'!G60-'Budget Figures'!G60,"") | H60: =IF('Actual Figures'!H60<>"",'Actual Figures'!H60-'Budget Figures'!H60,"") | I60: =IF('Actual Figures'!I60<>"",'Actual Figures'!I60-'Budget Figures'!I60,"") | J60: =IF('Actual Figures'!J60<>"",'Actual Figures'!J60-'Budget Figures'!J60,"") | K60: =IF('Actual Figures'!K60<>"",'Actual Figures'!K60-'Budget Figures'!K60,"") | ... O60: =IF('Actual Figures'!O60<>"",'Actual Figures'!O60-'Budget Figures'!O60,"") | Q60: =SUM(D60:O60) -> 0
C61: Other 2 | D61: =IF('Actual Figures'!D61<>"",'Actual Figures'!D61-'Budget Figures'!D61,"") | E61: =IF('Actual Figures'!E61<>"",'Actual Figures'!E61-'Budget Figures'!E61,"") | F61: =IF('Actual Figures'!F61<>"",'Actual Figures'!F61-'Budget Figures'!F61,"") | G61: =IF('Actual Figures'!G61<>"",'Actual Figures'!G61-'Budget Figures'!G61,"") | H61: =IF('Actual Figures'!H61<>"",'Actual Figures'!H61-'Budget Figures'!H61,"") | I61: =IF('Actual Figures'!I61<>"",'Actual Figures'!I61-'Budget Figures'!I61,"") | J61: =IF('Actual Figures'!J61<>"",'Actual Figures'!J61-'Budget Figures'!J61,"") | K61: =IF('Actual Figures'!K61<>"",'Actual Figures'!K61-'Budget Figures'!K61,"") | ... O61: =IF('Actual Figures'!O61<>"",'Actual Figures'!O61-'Budget Figures'!O61,"") | Q61: =SUM(D61:O61) -> 0
C62: Other 3 | D62: =IF('Actual Figures'!D62<>"",'Actual Figures'!D62-'Budget Figures'!D62,"") | E62: =IF('Actual Figures'!E62<>"",'Actual Figures'!E62-'Budget Figures'!E62,"") | F62: =IF('Actual Figures'!F62<>"",'Actual Figures'!F62-'Budget Figures'!F62,"") | G62: =IF('Actual Figures'!G62<>"",'Actual Figures'!G62-'Budget Figures'!G62,"") | H62: =IF('Actual Figures'!H62<>"",'Actual Figures'!H62-'Budget Figures'!H62,"") | I62: =IF('Actual Figures'!I62<>"",'Actual Figures'!I62-'Budget Figures'!I62,"") | J62: =IF('Actual Figures'!J62<>"",'Actual Figures'!J62-'Budget Figures'!J62,"") | K62: =IF('Actual Figures'!K62<>"",'Actual Figures'!K62-'Budget Figures'!K62,"") | ... O62: =IF('Actual Figures'!O62<>"",'Actual Figures'!O62-'Budget Figures'!O62,"") | Q62: =SUM(D62:O62) -> 0
C64: SUBTOTAL WITHDRAWALS: | D64: =IF('Actual Figures'!D64<>"",'Actual Figures'!D64-'Budget Figures'!D64,"") -> 0 | E64: =IF('Actual Figures'!E64<>"",'Actual Figures'!E64-'Budget Figures'!E64,"") -> 400 | F64: =IF('Actual Figures'!F64<>"",'Actual Figures'!F64-'Budget Figures'!F64,"") -> 250 | G64: =IF('Actual Figures'!G64<>"",'Actual Figures'!G64-'Budget Figures'!G64,"") -> 0 | H64: =IF('Actual Figures'!H64<>"",'Actual Figures'!H64-'Budget Figures'!H64,"") -> 1100 | I64: =IF('Actual Figures'!I64<>"",'Actual Figures'!I64-'Budget Figures'!I64,"") -> 500 | J64: =IF('Actual Figures'!J64<>"",'Actual Figures'!J64-'Budget Figures'!J64,"") -> 0 | K64: =IF('Actual Figures'!K64<>"",'Actual Figures'!K64-'Budget Figures'!K64,"") -> 0 | ... O64: =IF('Actual Figures'!O64<>"",'Actual Figures'!O64-'Budget Figures'!O64,"") -> 0 | Q64: =SUM(D64:O64) -> 2900
C66: GST Related Deposits | D66: =IF('Actual Figures'!D66<>"",'Actual Figures'!D66-'Budget Figures'!D66,"") -> 20000 | E66: =IF('Actual Figures'!E66<>"",'Actual Figures'!E66-'Budget Figures'!E66,"") -> 16750 | F66: =IF('Actual Figures'!F66<>"",'Actual Figures'!F66-'Budget Figures'!F66,"") -> 12750 | G66: =IF('Actual Figures'!G66<>"",'Actual Figures'!G66-'Budget Figures'!G66,"") -> -20000 | H66: =IF('Actual Figures'!H66<>"",'Actual Figures'!H66-'Budget Figures'!H66,"") -> -2000 | I66: =IF('Actual Figures'!I66<>"",'Actual Figures'!I66-'Budget Figures'!I66,"") -> 6000 | J66: =IF('Actual Figures'!J66<>"",'Actual Figures'!J66-'Budget Figures'!J66,"") -> -11750 | K66: =IF('Actual Figures'!K66<>"",'Actual Figures'!K66-'Budget Figures'!K66,"") -> 4125 | ... O66: =IF('Actual Figures'!O66<>"",'Actual Figures'!O66-'Budget Figures'!O66,"") -> 3640
C67: GST Related Withdrawals | D67: =IF('Actual Figures'!D67<>"",'Actual Figures'!D67-'Budget Figures'!D67,"") -> 9100 | E67: =IF('Actual Figures'!E67<>"",'Actual Figures'!E67-'Budget Figures'!E67,"") -> 2450 | F67: =IF('Actual Figures'!F67<>"",'Actual Figures'!F67-'Budget Figures'!F67,"") -> 2450 | G67: =IF('Actual Figures'!G67<>"",'Actual Figures'!G67-'Budget Figures'!G67,"") -> -4050 | H67: =IF('Actual Figures'!H67<>"",'Actual Figures'!H67-'Budget Figures'!H67,"") -> 6400 | I67: =IF('Actual Figures'!I67<>"",'Actual Figures'!I67-'Budget Figures'!I67,"") -> -2600 | J67: =IF('Actual Figures'!J67<>"",'Actual Figures'!J67-'Budget Figures'!J67,"") -> -6830 | K67: =IF('Actual Figures'!K67<>"",'Actual Figures'!K67-'Budget Figures'!K67,"") -> 4010 | ... O67: =IF('Actual Figures'!O67<>"",'Actual Figures'!O67-'Budget Figures'!O67,"") -> 4450
C69: GST MOVEMENTS
C70: Input (Expense Related) | D70: =IF('Actual Figures'!D70<>"",'Actual Figures'!D70-'Budget Figures'!D70,"") -> 1186.9565 | E70: =IF('Actual Figures'!E70<>"",'Actual Figures'!E70-'Budget Figures'!E70,"") -> 319.56522 | F70: =IF('Actual Figures'!F70<>"",'Actual Figures'!F70-'Budget Figures'!F70,"") -> 319.56522 | G70: =IF('Actual Figures'!G70<>"",'Actual Figures'!G70-'Budget Figures'!G70,"") -> -528.26087 | H70: =IF('Actual Figures'!H70<>"",'Actual Figures'!H70-'Budget Figures'!H70,"") -> 834.78261 | I70: =IF('Actual Figures'!I70<>"",'Actual Figures'!I70-'Budget Figures'!I70,"") -> -339.13043 | J70: =IF('Actual Figures'!J70<>"",'Actual Figures'!J70-'Budget Figures'!J70,"") -> -890.86957 | K70: =IF('Actual Figures'!K70<>"",'Actual Figures'!K70-'Budget Figures'!K70,"") -> 523.04348 | ... O70: =IF('Actual Figures'!O70<>"",'Actual Figures'!O70-'Budget Figures'!O70,"") -> 580.43478 | Q70: =SUM(D70:O70) -> 2289.1304
C71: Output (Income Related) | D71: =IF('Actual Figures'!D71<>"",'Actual Figures'!D71-'Budget Figures'!D71,"") -> 2608.6957 | E71: =IF('Actual Figures'!E71<>"",'Actual Figures'!E71-'Budget Figures'!E71,"") -> 2184.7826 | F71: =IF('Actual Figures'!F71<>"",'Actual Figures'!F71-'Budget Figures'!F71,"") -> 1663.0435 | G71: =IF('Actual Figures'!G71<>"",'Actual Figures'!G71-'Budget Figures'!G71,"") -> -2608.6957 | H71: =IF('Actual Figures'!H71<>"",'Actual Figures'!H71-'Budget Figures'!H71,"") -> -260.86957 | I71: =IF('Actual Figures'!I71<>"",'Actual Figures'!I71-'Budget Figures'!I71,"") -> 782.6087 | J71: =IF('Actual Figures'!J71<>"",'Actual Figures'!J71-'Budget Figures'!J71,"") -> -1532.6087 | K71: =IF('Actual Figures'!K71<>"",'Actual Figures'!K71-'Budget Figures'!K71,"") -> 538.04348 | ... O71: =IF('Actual Figures'!O71<>"",'Actual Figures'!O71-'Budget Figures'!O71,"") -> 474.78261 | Q71: =SUM(D71:O71) -> 5137.8261
...

Sheet Reports
E64: ='Budget Figures'!D6 -> 44287 | F64: ='Budget Figures'!E6 -> 44317 | G64: ='Budget Figures'!F6 -> 44348 | H64: ='Budget Figures'!G6 -> 44378 | I64: ='Budget Figures'!H6 -> 44409 | J64: ='Budget Figures'!I6 -> 44440 | K64: ='Budget Figures'!J6 -> 44470 | L64: ='Budget Figures'!K6 -> 44501 | ... P64: ='Budget Figures'!O6 -> 44621
D65: Budget Revenue | E65: ='Budget Figures'!D16 -> 5250 | F65: ='Budget Figures'!E16 -> 18500 | G65: ='Budget Figures'!F16 -> 32500 | H65: ='Budget Figures'!G16 -> 35250 | I65: ='Budget Figures'!H16 -> 27250 | J65: ='Budget Figures'!I16 -> 24250 | K65: ='Budget Figures'!J16 -> 24500 | L65: ='Budget Figures'!K16 -> 21125 | ... P65: ='Budget Figures'!O16 -> 32410
D66: Actual Revenue | E66: ='Actual Figures'!D16 -> 25250 | F66: ='Actual Figures'!E16 -> 35250 | G66: ='Actual Figures'!F16 -> 45250 | H66: ='Actual Figures'!G16 -> 15250 | I66: ='Actual Figures'!H16 -> 25250 | J66: ='Actual Figures'!I16 -> 30250 | K66: ='Actual Figures'!J16 -> 12750 | L66: ='Actual Figures'!K16 -> 25250 | ... P66: ='Actual Figures'!O16 -> 36050
E70: =E64 -> 44287 | F70: =F64 -> 44317 | G70: =G64 -> 44348 | H70: =H64 -> 44378 | I70: =I64 -> 44409 | J70: =J64 -> 44440 | K70: =K64 -> 44470 | L70: =L64 -> 44501 | ... P70: =P64 -> 44621
D71: Budget Expenses | E71: ='Budget Figures'!D64+'Budget Figures'!D22 -> 21400 | F71: ='Budget Figures'!E64+'Budget Figures'!E22 -> 30450 | G71: ='Budget Figures'!F64+'Budget Figures'!F22 -> 33300 | H71: ='Budget Figures'!G64+'Budget Figures'!G22 -> 33550 | I71: ='Budget Figures'!H64+'Budget Figures'!H22 -> 32200 | J71: ='Budget Figures'!I64+'Budget Figures'!I22 -> 35600 | K71: ='Budget Figures'!J64+'Budget Figures'!J22 -> 29930 | L71: ='Budget Figures'!K64+'Budget Figures'!K22 -> 25490 | ... P71: ='Budget Figures'!O64+'Budget Figures'!O22 -> 33050
D72: Actual Expenses | E72: ='Actual Figures'!D22+'Actual Figures'!D64 -> 30500 | F72: ='Actual Figures'!E22+'Actual Figures'!E64 -> 32900 | G72: ='Actual Figures'!F22+'Actual Figures'!F64 -> 35750 | H72: ='Actual Figures'!G22+'Actual Figures'!G64 -> 29500 | I72: ='Actual Figures'!H22+'Actual Figures'!H64 -> 38600 | J72: ='Actual Figures'!I22+'Actual Figures'!I64 -> 33000 | K72: ='Actual Figures'!J22+'Actual Figures'!J64 -> 23100 | L72: ='Actual Figures'!K22+'Actual Figures'!K64 -> 29500 | ... P72: ='Actual Figures'!O22+'Actual Figures'!O64 -> 37500
