Workbook

Sheet Report
F4: Sales Ranges Breakdown
C5: $ Range | J5: Transactions | K5: Sales Value | L5: Sales Margin
D6: 1 | F6: 1 | H6: 250 | J6: =Sheet1!D17 -> 13 | K6: =Sheet1!E16 -> 2369 | L6: =Sheet1!D16 -> 1129
D7: 2 | F7: =H6+1 -> 251 | H7: 500 | J7: =Sheet1!F17 -> 7 | K7: =Sheet1!G16 -> 2534 | L7: =Sheet1!F16 -> 1309
D8: 3 | F8: =H7+1 -> 501 | H8: 1000 | J8: =Sheet1!H17 -> 36 | K8: =Sheet1!I16 -> 27630 | L8: =Sheet1!H16 -> 14326
D9: 4 | F9: =H8+1 -> 1001 | H9: 1500 | J9: =Sheet1!J17 -> 13 | K9: =Sheet1!K16 -> 17550 | L9: =Sheet1!J16 -> 8107
D10: 5 | F10: =H9+1 -> 1501 | H10: 2500 | J10: =Sheet1!L17 -> 40 | K10: =Sheet1!M16 -> 83000 | L10: =Sheet1!L16 -> 42305
D11: 6 | F11: =H10+1 -> 2501 | H11: 5000 | J11: =Sheet1!N17 -> 25 | K11: =Sheet1!O16 -> 86700 | L11: =Sheet1!N16 -> 41007
D12: 7 | F12: =H11+1 -> 5001 | H12: 7500 | J12: =Sheet1!P17 -> 3 | K12: =Sheet1!Q16 -> 18100 | L12: =Sheet1!P16 -> 7223
D13: 8 | F13: =H12+1 -> 7501 | H13: 10000 | J13: =Sheet1!R17 -> 2 | K13: =Sheet1!S16 -> 16550 | L13: =Sheet1!R16 -> 6483
D14: 9 | F14: =H13+1 -> 10001 | H14: 15000 | J14: =Sheet1!T17 -> 0 | K14: =Sheet1!U16 -> 0 | L14: =Sheet1!T16 -> 0
D15: 10 | F15: Greater than | H15: =H14+1 -> 15001 | J15: =Sheet1!V17 -> 1 | K15: =Sheet1!W16 -> 15250 | L15: =Sheet1!V16 -> 8400
E17: Total | J17: =SUM(J6:J15) -> 140 | K17: =SUM(K6:K15) -> 269683 | L17: =SUM(L6:L15) -> 130289
F20: Total # of Sales | J20: ='Sales Data Input'!E14 -> 140
F21: Average Sale Margin | J21: =L17/J17 -> 930.63571 | K21: =L17/K17 -> 0.48311907
F22: Average Sale Value | J22: =K17/J17 -> 1926.3071

Sheet Pie Graph Options

Sheet Other Chart Options

Sheet Sales Data Input
B1: Brands | C1: Products | D1: =D16 -> Product Category | I1: Region | J1: Sales Person
A2: 1 | B2: Smith | C2: Coco | D2: Full Auto | I2: Auckland | J2: Billy
A3: 2 | B3: Jones | C3: Zoco | D3: Semi Auto | I3: Christchurch | J3: Bobby
A4: 3 | B4: Wessen | C4: Mofo | D4: Double Barrel | I4: Wellington | J4: Betty
A5: 4 | B5: Apple | C5: Bojo | D5: Single Barrel | I5: Hamilton | J5: Barry
A6: 5 | B6: Honda | C6: Lodo | D6: Extra Shiny | I6: Tauranga | J6: Mary
A7: 6 | B7: Seiko | C7: Rodo | D7: Low Sheen | I7: Rotorua | J7: Marg
A8: 7 | B8: Shimano | C8: Podo | D8: Wet | I8: Nelson | J8: Mavis
A9: 8 | B9: Samsung | C9: Hodo | D9: Dry | I9: Dunedin | J9: Steve
A10: 9 | B10: Dulux | C10: Dodo | D10: Hard | I10: Invercargill | J10: Sue
A11: 10 | B11: Toyota | C11: Sodo | D11: Soft | I11: Kaitaia | J11: Shaun
E13: =SUM(E18:E518) -> 269683 | F13: =SUM(F18:F518) -> 139394 | G13: =SUM(G18:G518) -> 130289 | H13: =if(E13=0,0,(E13-F13)/E13) -> 0.48311907
E14: =countif(E18:E508,">=1") -> 140
B16: Product Brand | C16: Product Name | D16: Product Category | E16: Sales Revenue | F16: Product Cost | G16: Margin $ | H16: Margin % | I16: Region | J16: Sales Person
B18: Smith | C18: Coco | D18: Full Auto | E18: 15250 | F18: 6850 | G18: =E18-F18 -> 8400 | H18: =if(E18=0,0,(E18-F18)/E18) -> 0.55081967 | I18: Auckland | J18: Billy
B19: Smith | C19: Zoco | D19: Semi Auto | E19: 8750 | F19: 5478 | G19: =E19-F19 -> 3272 | H19: =if(E19=0,0,(E19-F19)/E19) -> 0.37394286 | I19: Auckland | J19: Bobby
B20: Smith | C20: Mofo | D20: Double Barrel | E20: 7800 | F20: 4589 | G20: =E20-F20 -> 3211 | H20: =if(E20=0,0,(E20-F20)/E20) -> 0.41166667 | I20: Auckland | J20: Betty
B21: Smith | C21: Bojo | D21: Single Barrel | E21: 6500 | F21: 3698 | G21: =E21-F21 -> 2802 | H21: =if(E21=0,0,(E21-F21)/E21) -> 0.43107692 | I21: Auckland | J21: Barry
B22: Smith | C22: Lodo | D22: Extra Shiny | E22: 5800 | F22: 4123 | G22: =E22-F22 -> 1677 | H22: =if(E22=0,0,(E22-F22)/E22) -> 0.28913793 | I22: Auckland | J22: Mary
B23: Smith | C23: Rodo | D23: Low Sheen | E23: 5800 | F23: 3056 | G23: =E23-F23 -> 2744 | H23: =if(E23=0,0,(E23-F23)/E23) -> 0.47310345 | I23: Auckland | J23: Marg
B24: Smith | C24: Podo | D24: Wet | E24: 4800 | F24: 2589 | G24: =E24-F24 -> 2211 | H24: =if(E24=0,0,(E24-F24)/E24) -> 0.460625 | I24: Auckland | J24: Mavis
B25: Smith | C25: Hodo | D25: Dry | E25: 4800 | F25: 2547 | G25: =E25-F25 -> 2253 | H25: =if(E25=0,0,(E25-F25)/E25) -> 0.469375 | I25: Auckland | J25: Steve
B26: Jones | C26: Dodo | D26: Hard | E26: 4800 | F26: 2365 | G26: =E26-F26 -> 2435 | H26: =if(E26=0,0,(E26-F26)/E26) -> 0.50729167 | I26: Christchurch | J26: Sue
B27: Jones | C27: Sodo | D27: Soft | E27: 4800 | F27: 3145 | G27: =E27-F27 -> 1655 | H27: =if(E27=0,0,(E27-F27)/E27) -> 0.34479167 | I27: Christchurch | J27: Shaun
B28: Jones | C28: Coco | D28: Soft | E28: 4800 | F28: 2541 | G28: =E28-F28 -> 2259 | H28: =if(E28=0,0,(E28-F28)/E28) -> 0.470625 | I28: Christchurch | J28: Billy
B29: Jones | C29: Zoco | D29: Soft | E29: 3750 | F29: 2589 | G29: =E29-F29 -> 1161 | H29: =if(E29=0,0,(E29-F29)/E29) -> 0.3096 | I29: Christchurch | J29: Bobby
... B41: Apple | C41: Bojo | D41: Extra Shiny | E41: 2850 | F41: 1654 | G41: =E41-F41 -> 1196 | H41: =if(E41=0,0,(E41-F41)/E41) -> 0.41964912 | I41: Hamilton | J41: Barry
B42: =B41 -> Apple | C42: Lodo | D42: Extra Shiny | E42: 2850 | F42: 1458 | G42: =E42-F42 -> 1392 | H42: =if(E42=0,0,(E42-F42)/E42) -> 0.48842105 | I42: Hamilton | J42: Mary
B43: =B42 -> Apple | C43: Rodo | D43: Extra Shiny | E43: 2850 | F43: 1895 | G43: =E43-F43 -> 955 | H43: =if(E43=0,0,(E43-F43)/E43) -> 0.33508772 | I43: Hamilton | J43: Marg
B44: =B43 -> Apple | C44: Podo | D44: Extra Shiny | E44: 2850 | F44: 987 | G44: =E44-F44 -> 1863 | H44: =if(E44=0,0,(E44-F44)/E44) -> 0.65368421 | I44: Hamilton | J44: Mavis
B45: Honda | C45: Hodo | D45: Extra Shiny | E45: 2850 | F45: 1453 | G45: =E45-F45 -> 1397 | H45: =if(E45=0,0,(E45-F45)/E45) -> 0.49017544 | I45: Tauranga | J45: Steve
B46: =B45 -> Honda | C46: Dodo | D46: Wet | E46: 2850 | F46: 985 | G46: =E46-F46 -> 1865 | H46: =if(E46=0,0,(E46-F46)/E46) -> 0.65438596 | I46: Tauranga | J46: Sue
B47: =B46 -> Honda | C47: Sodo | D47: Wet | E47: 2850 | F47: 985 | G47: =E47-F47 -> 1865 | H47: =if(E47=0,0,(E47-F47)/E47) -> 0.65438596 | I47: Tauranga | J47: Shaun
B48: =B47 -> Honda | C48: Coco | D48: Wet | E48: 2850 | F48: 985 | G48: =E48-F48 -> 1865 | H48: =if(E48=0,0,(E48-F48)/E48) -> 0.65438596 | I48: Tauranga | J48: Billy
B49: =B48 -> Honda | C49: Zoco | D49: Wet | E49: 2400 | F49: 985 | G49: =E49-F49 -> 1415 | H49: =if(E49=0,0,(E49-F49)/E49) -> 0.58958333 | I49: Tauranga | J49: Bobby
B50: =B49 -> Honda | C50: Mofo | D50: Wet | E50: 2400 | F50: 985 | G50: =E50-F50 -> 1415 | H50: =if(E50=0,0,(E50-F50)/E50) -> 0.58958333 | I50: Tauranga | J50: Betty
B51: =B50 -> Honda | C51: Bojo | D51: Dry | E51: 2400 | F51: 985 | G51: =E51-F51 -> 1415 | H51: =if(E51=0,0,(E51-F51)/E51) -> 0.58958333 | I51: Tauranga | J51: Barry
B52: =B51 -> Honda | C52: Lodo | D52: Dry | E52: 2400 | F52: 1200 | G52: =E52-F52 -> 1200 | H52: =if(E52=0,0,(E52-F52)/E52) -> 0.5 | I52: Tauranga | J52: Mary
B53: Seiko | C53: Rodo | D53: Dry | E53: 2400 | F53: 1200 | G53: =E53-F53 -> 1200 | H53: =if(E53=0,0,(E53-F53)/E53) -> 0.5 | I53: Tauranga | J53: Marg
B54: =B53 -> Seiko | C54: Podo | D54: Dry | E54: 2400 | F54: 1200 | G54: =E54-F54 -> 1200 | H54: =if(E54=0,0,(E54-F54)/E54) -> 0.5 | I54: Tauranga | J54: Mavis
...

Sheet Sort & Filter
D1: =Subtotal(9,D3:D306) -> 269683 | E1: =Subtotal(9,E3:E306) -> 139394 | F1: =Subtotal(9,F3:F306) -> 130289 | G1: =F1/D1 -> 0.48311907
A2: Product Brand | B2: Product Name | C2: Product Category | D2: Sales Revenue | E2: Product Cost | F2: Margin $ | G2: Margin % | H2: Region | I2: Sales Person
A3: Smith | B3: Bojo | C3: Single Barrel | D3: 6500 | E3: 3698 | F3: =D3-E3 -> 2802 | G3: =if(D3=0,0,(D3-E3)/D3) -> 0.43107692 | H3: Auckland | I3: Barry
A4: Wessen | B4: Bojo | C4: Semi Auto | D4: 3750 | E4: 2145 | F4: =D4-E4 -> 1605 | G4: =if(D4=0,0,(D4-E4)/D4) -> 0.428 | H4: Christchurch | I4: Barry
A5: Apple | B5: Bojo | C5: Extra Shiny | D5: 2850 | E5: 1654 | F5: =D5-E5 -> 1196 | G5: =if(D5=0,0,(D5-E5)/D5) -> 0.41964912 | H5: Hamilton | I5: Barry
A6: =A5 -> Apple | B6: Bojo | C6: Dry | D6: 2400 | E6: 985 | F6: =D6-E6 -> 1415 | G6: =if(D6=0,0,(D6-E6)/D6) -> 0.58958333 | H6: Tauranga | I6: Barry
A7: =A6 -> Apple | B7: Bojo | C7: Soft | D7: 2400 | E7: 1200 | F7: =D7-E7 -> 1200 | G7: =if(D7=0,0,(D7-E7)/D7) -> 0.5 | H7: Rotorua | I7: Barry
A8: =A7 -> Apple | B8: Bojo | C8: Full Auto | D8: 1850 | E8: 987 | F8: =D8-E8 -> 863 | G8: =if(D8=0,0,(D8-E8)/D8) -> 0.46648649 | H8: Dunedin | I8: Barry
A9: =A8 -> Apple | B9: Bojo | C9: Semi Auto | D9: 1850 | E9: 987 | F9: =D9-E9 -> 863 | G9: =if(D9=0,0,(D9-E9)/D9) -> 0.46648649 | H9: Nelson | I9: Barry
A10: =A9 -> Apple | B10: Bojo | C10: Double Barrel | D10: 1350 | E10: 658 | F10: =D10-E10 -> 692 | G10: =if(D10=0,0,(D10-E10)/D10) -> 0.51259259 | H10: Invercargill | I10: Barry
A11: =A10 -> Apple | B11: Bojo | C11: Hard | D11: 1350 | E11: 785 | F11: =D11-E11 -> 565 | G11: =if(D11=0,0,(D11-E11)/D11) -> 0.41851852 | H11: Kaitaia | I11: Barry
A12: =A11 -> Apple | B12: Bojo | C12: Soft | D12: 980 | E12: 547 | F12: =D12-E12 -> 433 | G12: =if(D12=0,0,(D12-E12)/D12) -> 0.44183673 | H12: Rotorua | I12: Barry
A13: =A12 -> Apple | B13: Bojo | C13: Dry | D13: 725 | E13: 325 | F13: =D13-E13 -> 400 | G13: =if(D13=0,0,(D13-E13)/D13) -> 0.55172414 | H13: Auckland | I13: Barry
A14: =A13 -> Apple | B14: Bojo | C14: Full Auto | D14: 545 | E14: 245 | F14: =D14-E14 -> 300 | G14: =if(D14=0,0,(D14-E14)/D14) -> 0.55045872 | H14: Wellington | I14: Barry
A15: =A14 -> Apple | B15: Bojo | C15: Semi Auto | D15: 362 | E15: 175 | F15: =D15-E15 -> 187 | G15: =if(D15=0,0,(D15-E15)/D15) -> 0.51657459 | H15: Hamilton | I15: Barry
A16: =A15 -> Apple | B16: Bojo | C16: Single Barrel | D16: 218 | E16: 105 | F16: =D16-E16 -> 113 | G16: =if(D16=0,0,(D16-E16)/D16) -> 0.51834862 | H16: Hamilton | I16: Barry
A17: Smith | B17: Coco | C17: Full Auto | D17: 15250 | E17: 6850 | F17: =D17-E17 -> 8400 | G17: =if(D17=0,0,(D17-E17)/D17) -> 0.55081967 | H17: Auckland | I17: Billy
A18: Jones | B18: Coco | C18: Soft | D18: 4800 | E18: 2541 | F18: =D18-E18 -> 2259 | G18: =if(D18=0,0,(D18-E18)/D18) -> 0.470625 | H18: Christchurch | I18: Billy
A19: Apple | B19: Coco | C19: Double Barrel | D19: 3200 | E19: 1458 | F19: =D19-E19 -> 1742 | G19: =if(D19=0,0,(D19-E19)/D19) -> 0.544375 | H19: Wellington | I19: Billy
A20: =A19 -> Apple | B20: Coco | C20: Wet | D20: 2850 | E20: 985 | F20: =D20-E20 -> 1865 | G20: =if(D20=0,0,(D20-E20)/D20) -> 0.65438596 | H20: Tauranga | I20: Billy
A21: =A20 -> Apple | B21: Coco | C21: Soft | D21: 2400 | E21: 1200 | F21: =D21-E21 -> 1200 | G21: =if(D21=0,0,(D21-E21)/D21) -> 0.5 | H21: Rotorua | I21: Billy
A22: =A21 -> Apple | B22: Coco | C22: Full Auto | D22: 1850 | E22: 987 | F22: =D22-E22 -> 863 | G22: =if(D22=0,0,(D22-E22)/D22) -> 0.46648649 | H22: Dunedin | I22: Billy
A23: Samsung | B23: Coco | C23: Single Barrel | D23: 1850 | E23: 987 | F23: =D23-E23 -> 863 | G23: =if(D23=0,0,(D23-E23)/D23) -> 0.46648649 | H23: Nelson | I23: Billy
A24: =A23 -> Samsung | B24: Coco | C24: Double Barrel | D24: 1700 | E24: 658 | F24: =D24-E24 -> 1042 | G24: =if(D24=0,0,(D24-E24)/D24) -> 0.61294118 | H24: Dunedin | I24: Billy
A25: =A24 -> Samsung | B25: Coco | C25: Hard | D25: 1350 | E25: 785 | F25: =D25-E25 -> 565 | G25: =if(D25=0,0,(D25-E25)/D25) -> 0.41851852 | H25: Invercargill | I25: Billy
A26: =A25 -> Samsung | B26: Coco | C26: Soft | D26: 980 | E26: 547 | F26: =D26-E26 -> 433 | G26: =if(D26=0,0,(D26-E26)/D26) -> 0.44183673 | H26: Kaitaia | I26: Billy
A27: =A26 -> Samsung | B27: Coco | C27: Dry | D27: 725 | E27: 325 | F27: =D27-E27 -> 400 | G27: =if(D27=0,0,(D27-E27)/D27) -> 0.55172414 | H27: Rotorua | I27: Billy
A28: =A27 -> Samsung | B28: Coco | C28: Full Auto | D28: 650 | E28: 245 | F28: =D28-E28 -> 405 | G28: =if(D28=0,0,(D28-E28)/D28) -> 0.62307692 | H28: Wellington | I28: Billy
A29: =A28 -> Samsung | B29: Coco | C29: Semi Auto | D29: 362 | E29: 175 | F29: =D29-E29 -> 187 | G29: =if(D29=0,0,(D29-E29)/D29) -> 0.51657459 | H29: Hamilton | I29: Billy
A30: =A29 -> Samsung | B30: Coco | C30: Semi Auto | D30: 218 | E30: 105 | F30: =D30-E30 -> 113 | G30: =if(D30=0,0,(D30-E30)/D30) -> 0.51834862 | H30: Hamilton | I30: Billy
A31: Jones | B31: Dodo | C31: Hard | D31: 4800 | E31: 2365 | F31: =D31-E31 -> 2435 | G31: =if(D31=0,0,(D31-E31)/D31) -> 0.50729167 | H31: Christchurch | I31: Sue
A32: Wessen | B32: Dodo | C32: Double Barrel | D32: 3200 | E32: 1542 | F32: =D32-E32 -> 1658 | G32: =if(D32=0,0,(D32-E32)/D32) -> 0.518125 | H32: Wellington | I32: Sue
A33: =A32 -> Wessen | B33: Dodo | C33: Wet | D33: 2850 | E33: 985 | F33: =D33-E33 -> 1865 | G33: =if(D33=0,0,(D33-E33)/D33) -> 0.65438596 | H33: Tauranga | I33: Sue
A34: =A33 -> Wessen | B34: Dodo | C34: Soft | D34: 2400 | E34: 1200 | F34: =D34-E34 -> 1200 | G34: =if(D34=0,0,(D34-E34)/D34) -> 0.5 | H34: Rotorua | I34: Sue
A35: =A34 -> Wessen | B35: Dodo | C35: Single Barrel | D35: 2400 | E35: 1200 | F35: =D35-E35 -> 1200 | G35: =if(D35=0,0,(D35-E35)/D35) -> 0.5 | H35: Nelson | I35: Sue
A36: =A35 -> Wessen | B36: Dodo | C36: Full Auto | D36: 1850 | E36: 987 | F36: =D36-E36 -> 863 | G36: =if(D36=0,0,(D36-E36)/D36) -> 0.46648649 | H36: Dunedin | I36: Sue
A37: Toyota | B37: Dodo | C37: Double Barrel | D37: 1700 | E37: 658 | F37: =D37-E37 -> 1042 | G37: =if(D37=0,0,(D37-E37)/D37) -> 0.61294118 | H37: Dunedin | I37: Sue
A38: =A37 -> Toyota | B38: Dodo | C38: Double Barrel | D38: 1350 | E38: 785 | F38: =D38-E38 -> 565 | G38: =if(D38=0,0,(D38-E38)/D38) -> 0.41851852 | H38: Invercargill | I38: Sue
A39: =A38 -> Toyota | B39: Dodo | C39: Soft | D39: 980 | E39: 547 | F39: =D39-E39 -> 433 | G39: =if(D39=0,0,(D39-E39)/D39) -> 0.44183673 | H39: Kaitaia | I39: Sue
A40: =A39 -> Toyota | B40: Dodo | C40: Dry | D40: 725 | E40: 325 | F40: =D40-E40 -> 400 | G40: =if(D40=0,0,(D40-E40)/D40) -> 0.55172414 | H40: Rotorua | I40: Sue
...

Sheet Sheet1
B3: Category Sales Margin | D3: =sumif('Sales Data Input'!$D$18:$D$529,D6,'Sales Data Input'!$G$18:$G$529) -> 20080 | E3: =sumif('Sales Data Input'!$D$18:$D$529,E6,'Sales Data Input'!$G$18:$G$529) -> 18778 | F3: =sumif('Sales Data Input'!$D$18:$D$529,F6,'Sales Data Input'!$G$18:$G$529) -> 21919 | G3: =sumif('Sales Data Input'!$D$18:$D$529,G6,'Sales Data Input'!$G$18:$G$529) -> 11205 | H3: =sumif('Sales Data Input'!$D$18:$D$529,H6,'Sales Data Input'!$G$18:$G$529) -> 8480 | I3: =sumif('Sales Data Input'!$D$18:$D$529,I6,'Sales Data Input'!$G$18:$G$529) -> 2744 | J3: =sumif('Sales Data Input'!$D$18:$D$529,J6,'Sales Data Input'!$G$18:$G$529) -> 10636 | K3: =sumif('Sales Data Input'!$D$18:$D$529,K6,'Sales Data Input'!$G$18:$G$529) -> 12883 | ... M3: =sumif('Sales Data Input'!$D$18:$D$529,M6,'Sales Data Input'!$G$18:$G$529) -> 16572 | N3: =sum(D3:M3) -> 130289
B4: Category Sales Value | D4: =sumif('Sales Data Input'!$D$18:$D$529,D6,'Sales Data Input'!$E$18:$E$529) -> 37470 | E4: =sumif('Sales Data Input'!$D$18:$D$529,E6,'Sales Data Input'!$E$18:$E$529) -> 43301 | F4: =sumif('Sales Data Input'!$D$18:$D$529,F6,'Sales Data Input'!$E$18:$E$529) -> 43900 | G4: =sumif('Sales Data Input'!$D$18:$D$529,G6,'Sales Data Input'!$E$18:$E$529) -> 23697 | H4: =sumif('Sales Data Input'!$D$18:$D$529,H6,'Sales Data Input'!$E$18:$E$529) -> 20050 | I4: =sumif('Sales Data Input'!$D$18:$D$529,I6,'Sales Data Input'!$E$18:$E$529) -> 5800 | J4: =sumif('Sales Data Input'!$D$18:$D$529,J6,'Sales Data Input'!$E$18:$E$529) -> 18150 | K4: =sumif('Sales Data Input'!$D$18:$D$529,K6,'Sales Data Input'!$E$18:$E$529) -> 24550 | ... M4: =sumif('Sales Data Input'!$D$18:$D$529,M6,'Sales Data Input'!$E$18:$E$529) -> 37295 | N4: =sum(D4:M4) -> 269683
B5: Category Counts | D5: =countif('Sales Data Input'!$D$18:$D$529,D6) -> 20 | E5: =countif('Sales Data Input'!$D$18:$D$529,E6) -> 25 | F5: =countif('Sales Data Input'!$D$18:$D$529,F6) -> 19 | G5: =countif('Sales Data Input'!$D$18:$D$529,G6) -> 17 | H5: =countif('Sales Data Input'!$D$18:$D$529,H6) -> 6 | I5: =countif('Sales Data Input'!$D$18:$D$529,I6) -> 1 | J5: =countif('Sales Data Input'!$D$18:$D$529,J6) -> 6 | K5: =countif('Sales Data Input'!$D$18:$D$529,K6) -> 17 | ... M5: =countif('Sales Data Input'!$D$18:$D$529,M6) -> 19 | N5: =sum(D5:M5) -> 140
B6: ='Sales Data Input'!D1 -> Product Category | D6: ='Sales Data Input'!D2 -> Full Auto | E6: ='Sales Data Input'!D3 -> Semi Auto | F6: ='Sales Data Input'!D4 -> Double Barrel | G6: ='Sales Data Input'!D5 -> Single Barrel | H6: ='Sales Data Input'!D6 -> Extra Shiny | I6: ='Sales Data Input'!D7 -> Low Sheen | J6: ='Sales Data Input'!D8 -> Wet | K6: ='Sales Data Input'!D9 -> Dry | L6: ='Sales Data Input'!D10 -> Hard | M6: ='Sales Data Input'!D11 -> Soft
B7: Product Sales Margin | D7: =sumif('Sales Data Input'!$C$18:$C$529,D10,'Sales Data Input'!$G$18:$G$529) -> 20337 | E7: =sumif('Sales Data Input'!$C$18:$C$529,E10,'Sales Data Input'!$G$18:$G$529) -> 13363 | F7: =sumif('Sales Data Input'!$C$18:$C$529,F10,'Sales Data Input'!$G$18:$G$529) -> 12882 | G7: =sumif('Sales Data Input'!$C$18:$C$529,G10,'Sales Data Input'!$G$18:$G$529) -> 12634 | H7: =sumif('Sales Data Input'!$C$18:$C$529,H10,'Sales Data Input'!$G$18:$G$529) -> 11165 | I7: =sumif('Sales Data Input'!$C$18:$C$529,I10,'Sales Data Input'!$G$18:$G$529) -> 12134 | J7: =sumif('Sales Data Input'!$C$18:$C$529,J10,'Sales Data Input'!$G$18:$G$529) -> 12512 | K7: =sumif('Sales Data Input'!$C$18:$C$529,K10,'Sales Data Input'!$G$18:$G$529) -> 11880 | ... M7: =sumif('Sales Data Input'!$C$18:$C$529,M10,'Sales Data Input'!$G$18:$G$529) -> 10831 | N7: =sum(D7:M7) -> 130289 | P7: Salesperson Sales Margin | R7: =sumif('Sales Data Input'!$J$18:$J$529,R10,'Sales Data Input'!$G$18:$G$529) -> 20337 | S7: =sumif('Sales Data Input'!$J$18:$J$529,S10,'Sales Data Input'!$G$18:$G$529) -> 13363 | T7: =sumif('Sales Data Input'!$J$18:$J$529,T10,'Sales Data Input'!$G$18:$G$529) -> 12882 | U7: =sumif('Sales Data Input'!$J$18:$J$529,U10,'Sales Data Input'!$G$18:$G$529) -> 12634 | V7: =sumif('Sales Data Input'!$J$18:$J$529,V10,'Sales Data Input'!$G$18:$G$529) -> 11165 | W7: =sumif('Sales Data Input'!$J$18:$J$529,W10,'Sales Data Input'!$G$18:$G$529) -> 12134 | X7: =sumif('Sales Data Input'!$J$18:$J$529,X10,'Sales Data Input'!$G$18:$G$529) -> 12512 | Y7: =sumif('Sales Data Input'!$J$18:$J$529,Y10,'Sales Data Input'!$G$18:$G$529) -> 11880 | ... AA7: =sumif('Sales Data Input'!$J$18:$J$529,AA10,'Sales Data Input'!$G$18:$G$529) -> 10831 | AB7: =sum(R7:AA7) -> 130289
B8: Product Sales Value | D8: =sumif('Sales Data Input'!$C$18:$C$529,D10,'Sales Data Input'!$E$18:$E$529) -> 38185 | E8: =sumif('Sales Data Input'!$C$18:$C$529,E10,'Sales Data Input'!$E$18:$E$529) -> 29485 | F8: =sumif('Sales Data Input'!$C$18:$C$529,F10,'Sales Data Input'!$E$18:$E$529) -> 28535 | G8: =sumif('Sales Data Input'!$C$18:$C$529,G10,'Sales Data Input'!$E$18:$E$529) -> 27130 | H8: =sumif('Sales Data Input'!$C$18:$C$529,H10,'Sales Data Input'!$E$18:$E$529) -> 26060 | I8: =sumif('Sales Data Input'!$C$18:$C$529,I10,'Sales Data Input'!$E$18:$E$529) -> 25267 | J8: =sumif('Sales Data Input'!$C$18:$C$529,J10,'Sales Data Input'!$E$18:$E$529) -> 24192 | K8: =sumif('Sales Data Input'!$C$18:$C$529,K10,'Sales Data Input'!$E$18:$E$529) -> 23793 | ... M8: =sumif('Sales Data Input'!$C$18:$C$529,M10,'Sales Data Input'!$E$18:$E$529) -> 23243 | N8: =sum(D8:M8) -> 269683 | P8: Salesperson Sales Value | R8: =sumif('Sales Data Input'!$J$18:$J$529,R10,'Sales Data Input'!$E$18:$E$529) -> 38185 | S8: =sumif('Sales Data Input'!$J$18:$J$529,S10,'Sales Data Input'!$E$18:$E$529) -> 29485 | T8: =sumif('Sales Data Input'!$J$18:$J$529,T10,'Sales Data Input'!$E$18:$E$529) -> 28535 | U8: =sumif('Sales Data Input'!$J$18:$J$529,U10,'Sales Data Input'!$E$18:$E$529) -> 27130 | V8: =sumif('Sales Data Input'!$J$18:$J$529,V10,'Sales Data Input'!$E$18:$E$529) -> 26060 | W8: =sumif('Sales Data Input'!$J$18:$J$529,W10,'Sales Data Input'!$E$18:$E$529) -> 25267 | X8: =sumif('Sales Data Input'!$J$18:$J$529,X10,'Sales Data Input'!$E$18:$E$529) -> 24192 | Y8: =sumif('Sales Data Input'!$J$18:$J$529,Y10,'Sales Data Input'!$E$18:$E$529) -> 23793 | ... AA8: =sumif('Sales Data Input'!$J$18:$J$529,AA10,'Sales Data Input'!$E$18:$E$529) -> 23243 | AB8: =sum(R8:AA8) -> 269683
B9: Product Counts | D9: =countif('Sales Data Input'!$C$18:$C$529,D10) -> 14 | E9: =countif('Sales Data Input'!$C$18:$C$529,E10) -> 14 | F9: =countif('Sales Data Input'!$C$18:$C$529,F10) -> 14 | G9: =countif('Sales Data Input'!$C$18:$C$529,G10) -> 14 | H9: =countif('Sales Data Input'!$C$18:$C$529,H10) -> 14 | I9: =countif('Sales Data Input'!$C$18:$C$529,I10) -> 14 | J9: =countif('Sales Data Input'!$C$18:$C$529,J10) -> 14 | K9: =countif('Sales Data Input'!$C$18:$C$529,K10) -> 14 | ... M9: =countif('Sales Data Input'!$C$18:$C$529,M10) -> 14 | N9: =sum(D9:M9) -> 140 | P9: Sales Counts | R9: =countif('Sales Data Input'!$J$18:$J$529,R10) -> 14 | S9: =countif('Sales Data Input'!$J$18:$J$529,S10) -> 14 | T9: =countif('Sales Data Input'!$J$18:$J$529,T10) -> 14 | U9: =countif('Sales Data Input'!$J$18:$J$529,U10) -> 14 | V9: =countif('Sales Data Input'!$J$18:$J$529,V10) -> 14 | W9: =countif('Sales Data Input'!$J$18:$J$529,W10) -> 14 | X9: =countif('Sales Data Input'!$J$18:$J$529,X10) -> 14 | Y9: =countif('Sales Data Input'!$J$18:$J$529,Y10) -> 14 | ... AA9: =countif('Sales Data Input'!$J$18:$J$529,AA10) -> 14 | AB9: =sum(R9:AA9) -> 140
B10: ='Sales Data Input'!C1 -> Products | D10: ='Sales Data Input'!C2 -> Coco | E10: ='Sales Data Input'!C3 -> Zoco | F10: ='Sales Data Input'!C4 -> Mofo | G10: ='Sales Data Input'!C5 -> Bojo | H10: ='Sales Data Input'!C6 -> Lodo | I10: ='Sales Data Input'!C7 -> Rodo | J10: ='Sales Data Input'!C8 -> Podo | K10: ='Sales Data Input'!C9 -> Hodo | L10: ='Sales Data Input'!C10 -> Dodo | M10: ='Sales Data Input'!C11 -> Sodo | P10: ='Sales Data Input'!J1 -> Sales Person | R10: ='Sales Data Input'!J2 -> Billy | S10: ='Sales Data Input'!J3 -> Bobby | T10: ='Sales Data Input'!J4 -> Betty | U10: ='Sales Data Input'!J5 -> Barry | V10: ='Sales Data Input'!J6 -> Mary | W10: ='Sales Data Input'!J7 -> Marg | X10: ='Sales Data Input'!J8 -> Mavis | Y10: ='Sales Data Input'!J9 -> Steve | Z10: ='Sales Data Input'!J10 -> Sue | AA10: ='Sales Data Input'!J11 -> Shaun
B11: Brand Sales Margin | D11: =sumif('Sales Data Input'!$B$18:$B$529,D14,'Sales Data Input'!$G$18:$G$529) -> 26570 | E11: =sumif('Sales Data Input'!$B$18:$B$529,E14,'Sales Data Input'!$G$18:$G$529) -> 8673 | F11: =sumif('Sales Data Input'!$B$18:$B$529,F14,'Sales Data Input'!$G$18:$G$529) -> 9509 | G11: =sumif('Sales Data Input'!$B$18:$B$529,G14,'Sales Data Input'!$G$18:$G$529) -> 11369 | H11: =sumif('Sales Data Input'!$B$18:$B$529,H14,'Sales Data Input'!$G$18:$G$529) -> 12437 | I11: =sumif('Sales Data Input'!$B$18:$B$529,I14,'Sales Data Input'!$G$18:$G$529) -> 10800 | J11: =sumif('Sales Data Input'!$B$18:$B$529,J14,'Sales Data Input'!$G$18:$G$529) -> 6863 | K11: =sumif('Sales Data Input'!$B$18:$B$529,K14,'Sales Data Input'!$G$18:$G$529) -> 3452 | ... M11: =sumif('Sales Data Input'!$B$18:$B$529,M14,'Sales Data Input'!$G$18:$G$529) -> 27997 | N11: =sum(D11:M11) -> 130289 | P11: Region Sales Margin | R11: =sumif('Sales Data Input'!$I$18:$I$529,R14,'Sales Data Input'!$G$18:$G$529) -> 29390 | S11: =sumif('Sales Data Input'!$I$18:$I$529,S14,'Sales Data Input'!$G$18:$G$529) -> 10278 | T11: =sumif('Sales Data Input'!$I$18:$I$529,T14,'Sales Data Input'!$G$18:$G$529) -> 14178 | U11: =sumif('Sales Data Input'!$I$18:$I$529,U14,'Sales Data Input'!$G$18:$G$529) -> 10672 | V11: =sumif('Sales Data Input'!$I$18:$I$529,V14,'Sales Data Input'!$G$18:$G$529) -> 14837 | W11: =sumif('Sales Data Input'!$I$18:$I$529,W14,'Sales Data Input'!$G$18:$G$529) -> 16132 | X11: =sumif('Sales Data Input'!$I$18:$I$529,X14,'Sales Data Input'!$G$18:$G$529) -> 6715 | Y11: =sumif('Sales Data Input'!$I$18:$I$529,Y14,'Sales Data Input'!$G$18:$G$529) -> 16083 | ... AA11: =sumif('Sales Data Input'!$I$18:$I$529,AA14,'Sales Data Input'!$G$18:$G$529) -> 5592 | AB11: =sum(R11:AA11) -> 130289
B12: Brand Sales Value | D12: =sumif('Sales Data Input'!$B$18:$B$529,D14,'Sales Data Input'!$E$18:$E$529) -> 59500 | E12: =sumif('Sales Data Input'!$B$18:$B$529,E14,'Sales Data Input'!$E$18:$E$529) -> 21900 | F12: =sumif('Sales Data Input'!$B$18:$B$529,F14,'Sales Data Input'!$E$18:$E$529) -> 20300 | G12: =sumif('Sales Data Input'!$B$18:$B$529,G14,'Sales Data Input'!$E$18:$E$529) -> 23500 | H12: =sumif('Sales Data Input'!$B$18:$B$529,H14,'Sales Data Input'!$E$18:$E$529) -> 21000 | I12: =sumif('Sales Data Input'!$B$18:$B$529,I14,'Sales Data Input'!$E$18:$E$529) -> 21600 | J12: =sumif('Sales Data Input'!$B$18:$B$529,J14,'Sales Data Input'!$E$18:$E$529) -> 13850 | K12: =sumif('Sales Data Input'!$B$18:$B$529,K14,'Sales Data Input'!$E$18:$E$529) -> 7400 | ... M12: =sumif('Sales Data Input'!$B$18:$B$529,M14,'Sales Data Input'!$E$18:$E$529) -> 55183 | N12: =sum(D12:M12) -> 269683 | P12: Region Sales Value | R12: =sumif('Sales Data Input'!$I$18:$I$529,R14,'Sales Data Input'!$E$18:$E$529) -> 64275 | S12: =sumif('Sales Data Input'!$I$18:$I$529,S14,'Sales Data Input'!$E$18:$E$529) -> 25650 | T12: =sumif('Sales Data Input'!$I$18:$I$529,T14,'Sales Data Input'!$E$18:$E$529) -> 28715 | U12: =sumif('Sales Data Input'!$I$18:$I$529,U14,'Sales Data Input'!$E$18:$E$529) -> 21160 | V12: =sumif('Sales Data Input'!$I$18:$I$529,V14,'Sales Data Input'!$E$18:$E$529) -> 25800 | W12: =sumif('Sales Data Input'!$I$18:$I$529,W14,'Sales Data Input'!$E$18:$E$529) -> 32270 | X12: =sumif('Sales Data Input'!$I$18:$I$529,X14,'Sales Data Input'!$E$18:$E$529) -> 14050 | Y12: =sumif('Sales Data Input'!$I$18:$I$529,Y14,'Sales Data Input'!$E$18:$E$529) -> 31393 | ... AA12: =sumif('Sales Data Input'!$I$18:$I$529,AA14,'Sales Data Input'!$E$18:$E$529) -> 12870 | AB12: =sum(R12:AA12) -> 269683
B13: Brand Counts | D13: =countif('Sales Data Input'!$B$18:$B$529,D14) -> 8 | E13: =countif('Sales Data Input'!$B$18:$B$529,E14) -> 5 | F13: =countif('Sales Data Input'!$B$18:$B$529,F14) -> 6 | G13: =countif('Sales Data Input'!$B$18:$B$529,G14) -> 8 | H13: =countif('Sales Data Input'!$B$18:$B$529,H14) -> 8 | I13: =countif('Sales Data Input'!$B$18:$B$529,I14) -> 9 | J13: =countif('Sales Data Input'!$B$18:$B$529,J14) -> 6 | K13: =countif('Sales Data Input'!$B$18:$B$529,K14) -> 4 | ... M13: =countif('Sales Data Input'!$B$18:$B$529,M14) -> 72 | N13: =sum(D13:M13) -> 140 | P13: Region Counts | R13: =countif('Sales Data Input'!$I$18:$I$529,R14) -> 15 | S13: =countif('Sales Data Input'!$I$18:$I$529,S14) -> 6 | T13: =countif('Sales Data Input'!$I$18:$I$529,T14) -> 17 | U13: =countif('Sales Data Input'!$I$18:$I$529,U14) -> 20 | V13: =countif('Sales Data Input'!$I$18:$I$529,V14) -> 10 | W13: =countif('Sales Data Input'!$I$18:$I$529,W14) -> 20 | X13: =countif('Sales Data Input'!$I$18:$I$529,X14) -> 7 | Y13: =countif('Sales Data Input'!$I$18:$I$529,Y14) -> 23 | ... AA13: =countif('Sales Data Input'!$I$18:$I$529,AA14) -> 12 | AB13: =sum(R13:AA13) -> 140
B14: ='Sales Data Input'!B1 -> Brands | D14: ='Sales Data Input'!B2 -> Smith | E14: ='Sales Data Input'!B3 -> Jones | F14: ='Sales Data Input'!B4 -> Wessen | G14: ='Sales Data Input'!B5 -> Apple | H14: ='Sales Data Input'!B6 -> Honda | I14: ='Sales Data Input'!B7 -> Seiko | J14: ='Sales Data Input'!B8 -> Shimano | K14: ='Sales Data Input'!B9 -> Samsung | L14: ='Sales Data Input'!B10 -> Dulux | M14: ='Sales Data Input'!B11 -> Toyota | P14: ='Sales Data Input'!I1 -> Region | R14: ='Sales Data Input'!I2 -> Auckland | S14: ='Sales Data Input'!I3 -> Christchurch | T14: ='Sales Data Input'!I4 -> Wellington | U14: ='Sales Data Input'!I5 -> Hamilton | V14: ='Sales Data Input'!I6 -> Tauranga | W14: ='Sales Data Input'!I7 -> Rotorua | X14: ='Sales Data Input'!I8 -> Nelson | Y14: ='Sales Data Input'!I9 -> Dunedin | Z14: ='Sales Data Input'!I10 -> Invercargill | AA14: ='Sales Data Input'!I11 -> Kaitaia
B16: Margin Total | C16: Sales Total | D16: =SUMIFS('Sales Data Input'!$G18:$G535,'Sales Data Input'!$E18:$E535,">="&D19,'Sales Data Input'!$E18:$E535,"<="&E19) -> 1129 | E16: =SUMIFS('Sales Data Input'!$E18:$E535,'Sales Data Input'!$E18:$E535,">="&D19,'Sales Data Input'!$E18:$E535,"<="&E19) -> 2369 | F16: =SUMIFS('Sales Data Input'!$G18:$G535,'Sales Data Input'!$E18:$E535,">="&F19,'Sales Data Input'!$E18:$E535,"<="&G19) -> 1309 | G16: =SUMIFS('Sales Data Input'!$E18:$E535,'Sales Data Input'!$E18:$E535,">="&F19,'Sales Data Input'!$E18:$E535,"<="&G19) -> 2534 | H16: =SUMIFS('Sales Data Input'!$G18:$G535,'Sales Data Input'!$E18:$E535,">="&H19,'Sales Data Input'!$E18:$E535,"<="&I19) -> 14326 | I16: =SUMIFS('Sales Data Input'!$E18:$E535,'Sales Data Input'!$E18:$E535,">="&H19,'Sales Data Input'!$E18:$E535,"<="&I19) -> 27630 | J16: =SUMIFS('Sales Data Input'!$G18:$G535,'Sales Data Input'!$E18:$E535,">="&J19,'Sales Data Input'!$E18:$E535,"<="&K19) -> 8107 | K16: =SUMIFS('Sales Data Input'!$E18:$E535,'Sales Data Input'!$E18:$E535,">="&J19,'Sales Data Input'!$E18:$E535,"<="&K19) -> 17550 | L16: =SUMIFS('Sales Data Input'!$G18:$G535,'Sales Data Input'!$E18:$E535,">="&L19,'Sales Data Input'!$E18:$E535,"<="&M19) -> 42305 | M16: =SUMIFS('Sales Data Input'!$E18:$E535,'Sales Data Input'!$E18:$E535,">="&L19,'Sales Data Input'!$E18:$E535,"<="&M19) -> 83000 | N16: =SUMIFS('Sales Data Input'!$G18:$G535,'Sales Data Input'!$E18:$E535,">="&N19,'Sales Data Input'!$E18:$E535,"<="&O19) -> 41007 | O16: =SUMIFS('Sales Data Input'!$E18:$E535,'Sales Data Input'!$E18:$E535,">="&N19,'Sales Data Input'!$E18:$E535,"<="&O19) -> 86700 | P16: =SUMIFS('Sales Data Input'!$G18:$G535,'Sales Data Input'!$E18:$E535,">="&P19,'Sales Data Input'!$E18:$E535,"<="&Q19) -> 7223 | Q16: =SUMIFS('Sales Data Input'!$E18:$E535,'Sales Data Input'!$E18:$E535,">="&P19,'Sales Data Input'!$E18:$E535,"<="&Q19) -> 18100 | R16: =SUMIFS('Sales Data Input'!$G18:$G535,'Sales Data Input'!$E18:$E535,">="&R19,'Sales Data Input'!$E18:$E535,"<="&S19) -> 6483 | S16: =SUMIFS('Sales Data Input'!$E18:$E535,'Sales Data Input'!$E18:$E535,">="&R19,'Sales Data Input'!$E18:$E535,"<="&S19) -> 16550 | T16: =SUMIFS('Sales Data Input'!$G18:$G535,'Sales Data Input'!$E18:$E535,">="&T19,'Sales Data Input'!$E18:$E535,"<="&U19) -> 0 | U16: =SUMIFS('Sales Data Input'!$E18:$E535,'Sales Data Input'!$E18:$E535,">="&T19,'Sales Data Input'!$E18:$E535,"<="&U19) -> 0 | V16: =SUMIF('Sales Data Input'!$E18:$E535,">="&V19,'Sales Data Input'!$G18:FE535) -> 8400 | W16: =SUMIF('Sales Data Input'!$E18:$E535,">="&V19,'Sales Data Input'!$E18:$E535) -> 15250 | X16: =V16+T16+R16+P16+N16+L16+J16+H16+F16+D16 -> 130289
B17: Sale Transaction Counts | D17: =COUNTIFS('Sales Data Input'!E18:E537,">="&D19,'Sales Data Input'!E18:E537,"<="&E19) -> 13 | F17: =COUNTIFS('Sales Data Input'!E18:E537,">="&F19,'Sales Data Input'!E18:E537,"<="&G19) -> 7 | H17: =COUNTIFS('Sales Data Input'!E18:E537,">="&H19,'Sales Data Input'!E18:E537,"<="&I19) -> 36 | J17: =COUNTIFS('Sales Data Input'!E18:E537,">="&J19,'Sales Data Input'!E18:E537,"<="&K19) -> 13 | L17: =COUNTIFS('Sales Data Input'!E18:E537,">="&L19,'Sales Data Input'!E18:E537,"<"&M19) -> 40 | N17: =COUNTIFS('Sales Data Input'!E18:E537,">"&N19,'Sales Data Input'!E18:E537,"<"&O19) -> 25 | P17: =COUNTIFS('Sales Data Input'!E18:E537,">="&P19,'Sales Data Input'!E18:E537,"<="&Q19) -> 3 | R17: =COUNTIFS('Sales Data Input'!E18:E537,">="&R19,'Sales Data Input'!E18:E537,"<="&S19) -> 2 | T17: =COUNTIFS('Sales Data Input'!E18:E537,">="&T19,'Sales Data Input'!E18:E537,"<="&U19) -> 0 | V17: =COUNTIF('Sales Data Input'!E18:E537,">="&V19) -> 1 | X17: =W16+U16+S16+Q16+O16+M16+K16+I16+G16+E16 -> 269683
D18: Between | F18: Between | H18: Between | J18: Between | L18: Between | N18: Between | P18: Between | R18: Between | T18: Between | V18: Greater than
B19: Sales Ranges | D19: =Report!F6 -> 1 | E19: =Report!H6 -> 250 | F19: =Report!F7 -> 251 | G19: =Report!H7 -> 500 | H19: =Report!F8 -> 501 | I19: =Report!H8 -> 1000 | J19: =Report!F9 -> 1001 | K19: =Report!H9 -> 1500 | L19: =Report!F10 -> 1501 | M19: =Report!H10 -> 2500 | N19: =Report!F11 -> 2501 | O19: =Report!H11 -> 5000 | P19: =Report!F12 -> 5001 | Q19: =Report!H12 -> 7500 | R19: =Report!F13 -> 7501 | S19: =Report!H13 -> 10000 | T19: =Report!F14 -> 10001 | U19: =Report!H14 -> 15000 | V19: =Report!H15 -> 15001
C25: ='Sales Data Input'!B1 -> Brands | D25: Transactions | E25: Sales Value | F25: Sales Margin | H25: ='Sales Data Input'!C1 -> Products | I25: Transactions | J25: Sales Value | K25: Sales Margin | M25: Region | N25: =I25 -> Transactions | O25: =J25 -> Sales Value | P25: =K25 -> Sales Margin | R25: ='Sales Data Input'!J1 -> Sales Person | S25: =N25 -> Transactions | T25: =O25 -> Sales Value | U25: =P25 -> Sales Margin | W25: ='Sales Data Input'!D1 -> Product Category | X25: =S25 -> Transactions | Y25: =T25 -> Sales Value | Z25: =U25 -> Sales Margin
C26: ='Sales Data Input'!B2 -> Smith | D26: =D13 -> 8 | E26: =D12 -> 59500 | F26: =D11 -> 26570 | H26: ='Sales Data Input'!C2 -> Coco | I26: =D9 -> 14 | J26: =D8 -> 38185 | K26: =D7 -> 20337 | M26: ='Sales Data Input'!I2 -> Auckland | N26: =R13 -> 15 | O26: =R12 -> 64275 | P26: =R11 -> 29390 | R26: ='Sales Data Input'!J2 -> Billy | S26: =R9 -> 14 | T26: =R8 -> 38185 | U26: =R7 -> 20337 | W26: ='Sales Data Input'!D2 -> Full Auto | X26: =D5 -> 20 | Y26: =D4 -> 37470 | Z26: =D3 -> 20080
C27: ='Sales Data Input'!B3 -> Jones | D27: =E13 -> 5 | E27: =E12 -> 21900 | F27: =E11 -> 8673 | H27: ='Sales Data Input'!C3 -> Zoco | I27: =E9 -> 14 | J27: =E8 -> 29485 | K27: =E7 -> 13363 | M27: ='Sales Data Input'!I3 -> Christchurch | N27: =S13 -> 6 | O27: =S12 -> 25650 | P27: =S11 -> 10278 | R27: ='Sales Data Input'!J3 -> Bobby | S27: =S9 -> 14 | T27: =S8 -> 29485 | U27: =S7 -> 13363 | W27: ='Sales Data Input'!D3 -> Semi Auto | X27: =E5 -> 25 | Y27: =E4 -> 43301 | Z27: =E3 -> 18778
C28: ='Sales Data Input'!B4 -> Wessen | D28: =F13 -> 6 | E28: =F12 -> 20300 | F28: =F11 -> 9509 | H28: ='Sales Data Input'!C4 -> Mofo | I28: =F9 -> 14 | J28: =F8 -> 28535 | K28: =F7 -> 12882 | M28: ='Sales Data Input'!I4 -> Wellington | N28: =T13 -> 17 | O28: =T12 -> 28715 | P28: =T11 -> 14178 | R28: ='Sales Data Input'!J4 -> Betty | S28: =T9 -> 14 | T28: =T8 -> 28535 | U28: =T7 -> 12882 | W28: ='Sales Data Input'!D4 -> Double Barrel | X28: =F5 -> 19 | Y28: =F4 -> 43900 | Z28: =F3 -> 21919
C29: ='Sales Data Input'!B5 -> Apple | D29: =G13 -> 8 | E29: =G12 -> 23500 | F29: =G11 -> 11369 | H29: ='Sales Data Input'!C5 -> Bojo | I29: =G9 -> 14 | J29: =G8 -> 27130 | K29: =G7 -> 12634 | M29: ='Sales Data Input'!I5 -> Hamilton | N29: =U13 -> 20 | O29: =U12 -> 21160 | P29: =U11 -> 10672 | R29: ='Sales Data Input'!J5 -> Barry | S29: =U9 -> 14 | T29: =U8 -> 27130 | U29: =U7 -> 12634 | W29: ='Sales Data Input'!D5 -> Single Barrel | X29: =G5 -> 17 | Y29: =G4 -> 23697 | Z29: =G3 -> 11205
C30: ='Sales Data Input'!B6 -> Honda | D30: =H13 -> 8 | E30: =H12 -> 21000 | F30: =H11 -> 12437 | H30: ='Sales Data Input'!C6 -> Lodo | I30: =H9 -> 14 | J30: =H8 -> 26060 | K30: =H7 -> 11165 | M30: ='Sales Data Input'!I6 -> Tauranga | N30: =V13 -> 10 | O30: =V12 -> 25800 | P30: =V11 -> 14837 | R30: ='Sales Data Input'!J6 -> Mary | S30: =V9 -> 14 | T30: =V8 -> 26060 | U30: =V7 -> 11165 | W30: ='Sales Data Input'!D6 -> Extra Shiny | X30: =H5 -> 6 | Y30: =H4 -> 20050 | Z30: =H3 -> 8480
C31: ='Sales Data Input'!B7 -> Seiko | D31: =I13 -> 9 | E31: =I12 -> 21600 | F31: =I11 -> 10800 | H31: ='Sales Data Input'!C7 -> Rodo | I31: =I9 -> 14 | J31: =I8 -> 25267 | K31: =I7 -> 12134 | M31: ='Sales Data Input'!I7 -> Rotorua | N31: =W13 -> 20 | O31: =W12 -> 32270 | P31: =W11 -> 16132 | R31: ='Sales Data Input'!J7 -> Marg | S31: =W9 -> 14 | T31: =W8 -> 25267 | U31: =W7 -> 12134 | W31: ='Sales Data Input'!D7 -> Low Sheen | X31: =I5 -> 1 | Y31: =I4 -> 5800 | Z31: =I3 -> 2744
C32: ='Sales Data Input'!B8 -> Shimano | D32: =J13 -> 6 | E32: =J12 -> 13850 | F32: =J11 -> 6863 | H32: ='Sales Data Input'!C8 -> Podo | I32: =J9 -> 14 | J32: =J8 -> 24192 | K32: =J7 -> 12512 | M32: ='Sales Data Input'!I8 -> Nelson | N32: =X13 -> 7 | O32: =X12 -> 14050 | P32: =X11 -> 6715 | R32: ='Sales Data Input'!J8 -> Mavis | S32: =X9 -> 14 | T32: =X8 -> 24192 | U32: =X7 -> 12512 | W32: ='Sales Data Input'!D8 -> Wet | X32: =J5 -> 6 | Y32: =J4 -> 18150 | Z32: =J3 -> 10636
C33: ='Sales Data Input'!B9 -> Samsung | D33: =K13 -> 4 | E33: =K12 -> 7400 | F33: =K11 -> 3452 | H33: ='Sales Data Input'!C9 -> Hodo | I33: =K9 -> 14 | J33: =K8 -> 23793 | K33: =K7 -> 11880 | M33: ='Sales Data Input'!I9 -> Dunedin | N33: =Y13 -> 23 | O33: =Y12 -> 31393 | P33: =Y11 -> 16083 | R33: ='Sales Data Input'!J9 -> Steve | S33: =Y9 -> 14 | T33: =Y8 -> 23793 | U33: =Y7 -> 11880 | W33: ='Sales Data Input'!D9 -> Dry | X33: =K5 -> 17 | Y33: =K4 -> 24550 | Z33: =K3 -> 12883
C34: ='Sales Data Input'!B10 -> Dulux | D34: =L13 -> 14 | E34: =L12 -> 25450 | F34: =L11 -> 12619 | H34: ='Sales Data Input'!C10 -> Dodo | I34: =L9 -> 14 | J34: =L8 -> 23793 | K34: =L7 -> 12551 | M34: ='Sales Data Input'!I10 -> Invercargill | N34: =Z13 -> 10 | O34: =Z12 -> 13500 | P34: =Z11 -> 6412 | R34: ='Sales Data Input'!J10 -> Sue | S34: =Z9 -> 14 | T34: =Z8 -> 23793 | U34: =Z7 -> 12551 | W34: ='Sales Data Input'!D10 -> Hard | X34: =L5 -> 10 | Y34: =L4 -> 15470 | Z34: =L3 -> 6992
C35: ='Sales Data Input'!B11 -> Toyota | D35: =M13 -> 72 | E35: =M12 -> 55183 | F35: =M11 -> 27997 | H35: ='Sales Data Input'!C11 -> Sodo | I35: =M9 -> 14 | J35: =M8 -> 23243 | K35: =M7 -> 10831 | M35: ='Sales Data Input'!I11 -> Kaitaia | N35: =AA13 -> 12 | O35: =AA12 -> 12870 | P35: =AA11 -> 5592 | R35: ='Sales Data Input'!J11 -> Shaun | S35: =Z9 -> 14 | T35: =AA8 -> 23243 | U35: =AA7 -> 10831 | W35: ='Sales Data Input'!D11 -> Soft | X35: =M5 -> 19 | Y35: =M4 -> 37295 | Z35: =M3 -> 16572
D37: =sum(D26:D35) -> 140 | E37: =sum(E26:E35) -> 269683 | F37: =sum(F26:F35) -> 130289 | I37: =sum(I26:I35) -> 140 | J37: =sum(J26:J35) -> 269683 | K37: =sum(K26:K35) -> 130289 | N37: =sum(N26:N35) -> 140 | O37: =sum(O26:O35) -> 269683 | P37: =sum(P26:P35) -> 130289 | S37: =sum(S26:S35) -> 140 | T37: =sum(T26:T35) -> 269683 | U37: =sum(U26:U35) -> 130289 | X37: =sum(X26:X35) -> 140 | Y37: =sum(Y26:Y35) -> 269683 | Z37: =sum(Z26:Z35) -> 130289
C40: =C25 -> Brands | D40: =E25 -> Sales Value | H40: =H25 -> Products | I40: =J25 -> Sales Value | M40: =M25 -> Region | N40: =O25 -> Sales Value | R40: =R25 -> Sales Person | S40: =T25 -> Sales Value | W40: =W25 -> Product Category | X40: =Y25 -> Sales Value
C41: =C26 -> Smith | D41: =E26 -> 59500 | H41: =H26 -> Coco | I41: =J26 -> 38185 | M41: =M26 -> Auckland | N41: =O26 -> 64275 | R41: =R26 -> Billy | S41: =T26 -> 38185 | W41: =W26 -> Full Auto | X41: =Y26 -> 37470
C42: =C27 -> Jones | D42: =E27 -> 21900 | H42: =H27 -> Zoco | I42: =J27 -> 29485 | M42: =M27 -> Christchurch | N42: =O27 -> 25650 | R42: =R27 -> Bobby | S42: =T27 -> 29485 | W42: =W27 -> Semi Auto | X42: =Y27 -> 43301
C43: =C28 -> Wessen | D43: =E28 -> 20300 | H43: =H28 -> Mofo | I43: =J28 -> 28535 | M43: =M28 -> Wellington | N43: =O28 -> 28715 | R43: =R28 -> Betty | S43: =T28 -> 28535 | W43: =W28 -> Double Barrel | X43: =Y28 -> 43900
C44: =C29 -> Apple | D44: =E29 -> 23500 | H44: =H29 -> Bojo | I44: =J29 -> 27130 | M44: =M29 -> Hamilton | N44: =O29 -> 21160 | R44: =R29 -> Barry | S44: =T29 -> 27130 | W44: =W29 -> Single Barrel | X44: =Y29 -> 23697
C45: =C30 -> Honda | D45: =E30 -> 21000 | H45: =H30 -> Lodo | I45: =J30 -> 26060 | M45: =M30 -> Tauranga | N45: =O30 -> 25800 | R45: =R30 -> Mary | S45: =T30 -> 26060 | W45: =W30 -> Extra Shiny | X45: =Y30 -> 20050
C46: =C31 -> Seiko | D46: =E31 -> 21600 | H46: =H31 -> Rodo | I46: =J31 -> 25267 | M46: =M31 -> Rotorua | N46: =O31 -> 32270 | R46: =R31 -> Marg | S46: =T31 -> 25267 | W46: =W31 -> Low Sheen | X46: =Y31 -> 5800
C47: =C32 -> Shimano | D47: =E32 -> 13850 | H47: =H32 -> Podo | I47: =J32 -> 24192 | M47: =M32 -> Nelson | N47: =O32 -> 14050 | R47: =R32 -> Mavis | S47: =T32 -> 24192 | W47: =W32 -> Wet | X47: =Y32 -> 18150
C48: =C33 -> Samsung | D48: =E33 -> 7400 | H48: =H33 -> Hodo | I48: =J33 -> 23793 | M48: =M33 -> Dunedin | N48: =O33 -> 31393 | R48: =R33 -> Steve | S48: =T33 -> 23793 | W48: =W33 -> Dry | X48: =Y33 -> 24550
C49: =C34 -> Dulux | D49: =E34 -> 25450 | H49: =H34 -> Dodo | I49: =J34 -> 23793 | M49: =M34 -> Invercargill | N49: =O34 -> 13500 | R49: =R34 -> Sue | S49: =T34 -> 23793 | W49: =W34 -> Hard | X49: =Y34 -> 15470
C50: =C35 -> Toyota | D50: =E35 -> 55183 | H50: =H35 -> Sodo | I50: =J35 -> 23243 | M50: =M35 -> Kaitaia | N50: =O35 -> 12870 | R50: =R35 -> Shaun | S50: =T35 -> 23243 | W50: =W35 -> Soft | X50: =Y35 -> 37295
C51: =C36 | H51: =H36 | M51: =M36 | R51: =R36 | W51: =W36
...
